Workbook

Sheet Master
B1: 품의코드 | C1: Vendor 코드 | E1: 매출처 | F1: END-USER | G1: 구분 | H1: MA : 청구구분 상품 : PN | I1: 거래내용 | J1: 수량 | K1: 단가 | L1: 공급가액 | M1: 부가세 | N1: 공급가합계 | O1: 매입액 | P1: 매입거래처 | Q1: GP | R1: 입금일 | S1: 영업 담당자 | T1: 비고
A2: . | B2: ='1월'!B3 -> S | D2: ='1월'!D3 -> 45658 | E2: ='1월'!E3 -> 홈닥터 | F2: ='1월'!F3 -> 광명자이 1811호 | G2: ='1월'!G3 -> 건물임대 | H2: ='1월'!H3 -> 임대료 | I2: ='1월'!I3 -> 12월(12.5~25.1.4) 임대료 - 11/24회 | J2: ='1월'!J3 -> 1 | K2: ='1월'!K3 -> 550000 | ... S2: ='1월'!S3 -> 정지우
A3: . | B3: ='1월'!B4 -> IK-22025 | D3: ='1월'!D4 -> 45658 | E3: ='1월'!E4 -> 디에스피 | F3: ='1월'!F4 -> 엘지생활건강 | G3: ='1월'!G4 -> MA | H3: ='1월'!H4 -> 월간-IBM | I3: ='1월'!I4 -> 1월 유지정비료 - 12/12회 | J3: ='1월'!J4 -> 1 | K3: ='1월'!K4 -> 635000 | ... S3: ='1월'!S4 -> 천범석
A4: . | B4: ='1월'!B5 -> SM-23015 | D4: ='1월'!D5 -> 45658 | E4: ='1월'!E5 -> 동원프라스틱 | F4: ='1월'!F5 -> 동원프라스틱 | G4: ='1월'!G5 -> MA | H4: ='1월'!H5 -> 월간 | I4: ='1월'!I5 -> 1월 유지정비료 - 10/13회 | J4: ='1월'!J5 -> 1 | K4: ='1월'!K5 -> 1200000 | ... S4: ='1월'!S5 -> 이예지
A5: . | B5: ='1월'!B6 -> IK-23016 | D5: ='1월'!D6 -> 45658 | E5: ='1월'!E6 -> 케이정보기술 | F5: ='1월'!F6 -> 청주시청 | G5: ='1월'!G6 -> MA | H5: ='1월'!H6 -> 월간-IBM | I5: ='1월'!I6 -> 1월 유지정비료 - 17/36회 | J5: ='1월'!J6 -> 1 | K5: ='1월'!K6 -> 1300000 | ... S5: ='1월'!S6 -> 천범석
A6: . | B6: ='1월'!B7 -> SM-24011 | D6: ='1월'!D7 -> 45658 | E6: ='1월'!E7 -> 가나병원 | G6: ='1월'!G7 -> MA | H6: ='1월'!H7 -> 월간 | I6: ='1월'!I7 -> 1월 유지정비료 - 9/12회 | J6: ='1월'!J7 -> 1 | K6: ='1월'!K7 -> 300000 | L6: ='1월'!L7 -> 300000 | M6: ='1월'!M7 -> 30000 | N6: ='1월'!N7 -> 330000 | ... S6: ='1월'!S7 -> 천범석
A7: . | B7: ='1월'!B8 -> LI-24004 | D7: ='1월'!D8 -> 45658 | E7: ='1월'!E8 -> 한국메탈 | G7: ='1월'!G8 -> MA | H7: ='1월'!H8 -> 월간-IBM | I7: ='1월'!I8 -> 1월 유지정비료 - 9/36회 | J7: ='1월'!J8 -> 1 | K7: ='1월'!K8 -> 507500 | L7: ='1월'!L8 -> 507500 | M7: ='1월'!M8 -> 50750 | N7: ='1월'!N8 -> 558250 | ... S7: ='1월'!S8 -> 천범석
A8: . | B8: ='1월'!B9 -> LI-24005 | C8: ='1월'!C9 -> Z4ACEZ | D8: ='1월'!D9 -> 45658 | E8: ='1월'!E9 -> 해종합건축사사무소 | G8: ='1월'!G9 -> MA | H8: ='1월'!H9 -> 월간-IBM | I8: ='1월'!I9 -> 1월 유지정비료 - 8/12회 | J8: ='1월'!J9 -> 1 | K8: ='1월'!K9 -> 1554500 | L8: ='1월'!L9 -> 1554500 | M8: ='1월'!M9 -> 155450 | N8: ='1월'!N9 -> 1709950 | ... S8: ='1월'!S9 -> 천범석
A9: . | B9: ='1월'!B10 -> SB-24039 | C9: ='1월'!C10 -> ZZGBBZ | D9: ='1월'!D10 -> 45658 | E9: ='1월'!E10 -> 한국디지털방송 | G9: ='1월'!G10 -> MA | H9: ='1월'!H10 -> 월간-레노버 | I9: ='1월'!I10 -> 1월 유지정비료 - 7/12회 | J9: ='1월'!J10 -> 1 | K9: ='1월'!K10 -> 1423000 | L9: ='1월'!L10 -> 1423000 | M9: ='1월'!M10 -> 142300 | N9: ='1월'!N10 -> 1565300 | ... S9: ='1월'!S10 -> 천범석
A10: . | B10: ='1월'!B11 -> IK-24008 | D10: ='1월'!D11 -> 45658 | E10: ='1월'!E11 -> 서비스링크 | F10: ='1월'!F11 -> 세원정공(폴라리스세원) | G10: ='1월'!G11 -> MA | H10: ='1월'!H11 -> 월간-레노버 | I10: ='1월'!I11 -> 1월 유지정비료 - 7/12회 | J10: ='1월'!J11 -> 1 | K10: ='1월'!K11 -> 238000 | ... S10: ='1월'!S11 -> 천범석
A11: . | B11: ='1월'!B12 -> IK-24013 | D11: ='1월'!D12 -> 45658 | E11: ='1월'!E12 -> 레드텍 | F11: ='1월'!F12 -> 대한상공회의소 | G11: ='1월'!G12 -> MA | H11: ='1월'!H12 -> 월간-IBM | I11: ='1월'!I12 -> 1월 유지정비료 - 3/12회 | J11: ='1월'!J12 -> 1 | K11: ='1월'!K12 -> 158400 | ... S11: ='1월'!S12 -> 천범석
A12: . | B12: ='1월'!B13 -> SM-23012 | D12: ='1월'!D13 -> 45658 | E12: ='1월'!E13 -> 택스홈앤아웃 | F12: ='1월'!F13 -> 본사 | G12: ='1월'!G13 -> MA | H12: ='1월'!H13 -> 월간 | I12: ='1월'!I13 -> VPN 서비스 1월임대료 - 1/12회 280,000 + 보안스위치 1월 2대*120,000 | J12: ='1월'!J13 -> 1 | K12: ='1월'!K13 -> 520000 | ... S12: ='1월'!S13 -> 이예지
A13: . | B13: ='1월'!B14 -> SM-23013 | D13: ='1월'!D14 -> 45658 | E13: ='1월'!E14 -> 하이엔드택스 강남지점 | F13: ='1월'!F14 -> 압구정 | G13: ='1월'!G14 -> MA | H13: ='1월'!H14 -> 월간 | I13: ='1월'!I14 -> VPN 서비스/ 1월임대료 - 1/12회 | J13: ='1월'!J14 -> 1 | K13: ='1월'!K14 -> 320000 | ... S13: ='1월'!S14 -> 이예지
A14: . | B14: ='1월'!B15 -> SM-23016 | D14: ='1월'!D15 -> 45658 | E14: ='1월'!E15 -> 에실로코리아 | F14: ='1월'!F15 -> 에실로코리아 | G14: ='1월'!G15 -> MA | H14: ='1월'!H15 -> 월간 | I14: ='1월'!I15 -> 1월 유지정비료 - 1/12회 | J14: ='1월'!J15 -> 1 | K14: ='1월'!K15 -> 100000 | ... S14: ='1월'!S15 -> 이예지
A15: . | B15: ='1월'!B16 -> IK-22022 | D15: ='1월'!D16 -> 45658 | E15: ='1월'!E16 -> 로인아이티 | F15: ='1월'!F16 -> 한일전기 | G15: ='1월'!G16 -> MA | H15: ='1월'!H16 -> 월간-IBM | I15: ='1월'!I16 -> 분기(1~3월) 유지정비료 - 9/12회 | J15: ='1월'!J16 -> 1 | K15: ='1월'!K16 -> 1233000 | ... S15: ='1월'!S16 -> 천범석
A16: . | B16: ='1월'!B17 -> SB-22053 | C16: ='1월'!C17 -> ZEKV4M | D16: ='1월'!D17 -> 45658 | E16: ='1월'!E17 -> 심플키 | F16: ='1월'!F17 -> 한국산업은행 | G16: ='1월'!G17 -> MA | H16: ='1월'!H17 -> 월간-레노버 | I16: ='1월'!I17 -> 분기(1~3월) 유지정비료 - 9/12회 | ... S16: ='1월'!S17 -> 천범석
A17: . | B17: ='1월'!B18 -> SB-24042 | C17: ='1월'!C18 -> ZTME0P | D17: ='1월'!D18 -> 45658 | E17: ='1월'!E18 -> 심플키 | F17: ='1월'!F18 -> 티시스 | G17: ='1월'!G18 -> MA | H17: ='1월'!H18 -> 월간-레노버 | I17: ='1월'!I18 -> 분기(1~3월) 유지정비료 - 3/4회 | ... S17: ='1월'!S18 -> 천범석
A18: . | B18: ='1월'!B19 -> SB-24066 | C18: ='1월'!C19 -> ZDSNDX | D18: ='1월'!D19 -> 45659 | E18: ='1월'!E19 -> 이룸정보 | F18: ='1월'!F19 -> 중국광대은행 | G18: ='1월'!G19 -> MA | H18: ='1월'!H19 -> 월간-레노버 | I18: ='1월'!I19 -> 1~11월 유지정비료 | ... S18: ='1월'!S19 -> 천범석
A19: . | B19: ='1월'!B20 -> SL-24050 | C19: ='1월'!C20 -> ZXFJNS | D19: ='1월'!D20 -> 45661 | E19: ='1월'!E20 -> 스마트에프앤디 | G19: ='1월'!G20 -> MA | H19: ='1월'!H20 -> 월간-레노버 | I19: ='1월'!I20 -> 연간유지정비료(25.01.04~26.01.03) | J19: ='1월'!J20 -> 1 | K19: ='1월'!K20 -> 1320000 | L19: ='1월'!L20 -> 1320000 | M19: ='1월'!M20 -> 132000 | N19: ='1월'!N20 -> 1452000 | ... S19: ='1월'!S20 -> 천범석
A20: . | B20: ='1월'!B21 -> S | D20: ='1월'!D21 -> 45662 | E20: ='1월'!E21 -> 장형기업 | F20: ='1월'!F21 -> 검단미플존 316호 | G20: ='1월'!G21 -> 건물임대 | H20: ='1월'!H21 -> 임대료 | I20: ='1월'!I21 -> 1월 임대료 - 3/8회 | J20: ='1월'!J21 -> 1 | K20: ='1월'!K21 -> 367500 | ... S20: ='1월'!S21 -> 정지우
A21: . | B21: ='1월'!B22 -> SM-24021 | D21: ='1월'!D22 -> 45662 | E21: ='1월'!E22 -> 제이원캐피탈 | G21: ='1월'!G22 -> MA | H21: ='1월'!H22 -> 월간 | I21: ='1월'!I22 -> 12월 유지정비료 - 4/12회 | J21: ='1월'!J22 -> 1 | K21: ='1월'!K22 -> 7060000 | L21: ='1월'!L22 -> 7060000 | M21: ='1월'!M22 -> 706000 | N21: ='1월'!N22 -> 7766000 | ... S21: ='1월'!S22 -> 이예지
A22: . | B22: ='1월'!B23 -> SM-24020 | D22: ='1월'!D23 -> 45662 | E22: ='1월'!E23 -> 에이비씨한국 | G22: ='1월'!G23 -> MA | H22: ='1월'!H23 -> 월간 | I22: ='1월'!I23 -> BOARD SYSTEM Maintenance 1월분 - 4/12회 | J22: ='1월'!J23 -> 1 | K22: ='1월'!K23 -> 1100000 | L22: ='1월'!L23 -> 1100000 | M22: ='1월'!M23 -> 110000 | N22: ='1월'!N23 -> 1210000 | ... S22: ='1월'!S23 -> 이예지
B23: ='1월'!B24 -> IK-24012 | D23: ='1월'!D24 -> 45663 | E23: ='1월'!E24 -> 인정보시스템 | F23: ='1월'!F24 -> 대구텍 | G23: ='1월'!G24 -> MA | H23: ='1월'!H24 -> 월간-IBM | I23: ='1월'!I24 -> 1월 유지정비료 - 1/6회 | J23: ='1월'!J24 -> 1 | K23: ='1월'!K24 -> 1039500 | ... S23: ='1월'!S24 -> 천범석 | U23: 여신 30일견적됨, 확인필요
B24: ='1월'!B25 -> S | D24: ='1월'!D25 -> 45666 | E24: ='1월'!E25 -> 에이비씨한국 | G24: ='1월'!G25 -> 상품 | H24: ='1월'!H25 -> 노트북 | I24: ='1월'!I25 -> 엘지 노트북 납품 외 | J24: ='1월'!J25 -> 1 | K24: ='1월'!K25 -> 1520000 | L24: ='1월'!L25 -> 1520000 | M24: ='1월'!M25 -> 152000 | N24: ='1월'!N25 -> 1672000 | ... S24: ='1월'!S25 -> 이예지
A25: . | B25: ='1월'!B26 -> SM-25003 | C25: ='1월'!C26 -> ZZ6BIS | D25: ='1월'!D26 -> 45666 | E25: ='1월'!E26 -> 영화시스템 | F25: ='1월'!F26 -> CGV통합 | G25: ='1월'!G26 -> MA | H25: ='1월'!H26 -> 연간 | I25: ='1월'!I26 -> 연간유지정비료(25.01.01~25.12.31) | ... S25: ='1월'!S26 -> 천범석
A26: . | B26: ='1월'!B27 -> S | D26: ='1월'!D27 -> 45667 | E26: ='1월'!E27 -> 중소기업은행 | F26: ='1월'!F27 -> 호계214~216호 | G26: ='1월'!G27 -> 건물임대 | H26: ='1월'!H27 -> 임대료 | I26: ='1월'!I27 -> 1월 임대료 (12.13~1.12) | J26: ='1월'!J27 -> 1 | K26: ='1월'!K27 -> 6090000 | ... S26: ='1월'!S27 -> 정지우
A27: . | B27: ='1월'!B28 -> S | D27: ='1월'!D28 -> 45667 | E27: ='1월'!E28 -> 아이티앤 | F27: ='1월'!F28 -> 우물단 | G27: ='1월'!G28 -> 상품 | H27: ='1월'!H28 -> 기술지원 | I27: ='1월'!I28 -> 전산장비 이전, 시스템 마이그레이션 (1차) | J27: ='1월'!J28 -> 1 | K27: ='1월'!K28 -> 12500000 | ... P27: ='1월'!P28 -> (24/12/26) | R27: ='1월'!R28 -> 완료(25/1/31) | S27: ='1월'!S28 -> 이예지 | U27: 매출정리
A28: . | B28: ='1월'!B29 -> S | D28: ='1월'!D29 -> 45669 | E28: ='1월'!E29 -> 왕길토건 | F28: ='1월'!F29 -> 검단미플존 317호 | G28: ='1월'!G29 -> 건물임대 | H28: ='1월'!H29 -> 임대료 | I28: ='1월'!I29 -> 12월 임대료(24/12/12~25/1/10) - 3/10회 | J28: ='1월'!J29 -> 1 | K28: ='1월'!K29 -> 400000 | ... S28: ='1월'!S29 -> 정지우
B29: ='1월'!B30 -> S | D29: ='1월'!D30 -> 45671 | E29: ='1월'!E30 -> 에이비씨한국 | F29: ='1월'!F30 -> 평택 | G29: ='1월'!G30 -> 상품 | H29: ='1월'!H30 -> 노트북 | I29: ='1월'!I30 -> 엘지 노트북 납품 외 | J29: ='1월'!J30 -> 1 | K29: ='1월'!K30 -> 2273000 | ... S29: ='1월'!S30 -> 이예지
A30: . | B30: ='1월'!B31 -> S | D30: ='1월'!D31 -> 45672 | E30: ='1월'!E31 -> 순환 | F30: ='1월'!F31 -> 검단미플존 318호 | G30: ='1월'!G31 -> 건물임대 | H30: ='1월'!H31 -> 임대료 | I30: ='1월'!I31 -> 1월 임대료(24/12/20~25/1/19) - 3/9회 | J30: ='1월'!J31 -> 1 | K30: ='1월'!K31 -> 346500 | ... S30: ='1월'!S31 -> 정지우
A31: . | B31: ='1월'!B32 -> SB-24011 | C31: ='1월'!C32 -> Z5PURB | D31: ='1월'!D32 -> 45672 | E31: ='1월'!E32 -> 비온시이노베이터 | F31: ='1월'!F32 -> 국립농업과학원 | G31: ='1월'!G32 -> MA | H31: ='1월'!H32 -> 월간-레노버 | I31: ='1월'!I32 -> 12월 유지정비료 - 12/24회 | ... S31: ='1월'!S32 -> 천범석
A32: . | B32: ='1월'!B33 -> H250102-01 | D32: ='1월'!D33 -> 45672 | E32: ='1월'!E33 -> 아이엠티에스아이 | G32: ='1월'!G33 -> 상품 | H32: ='1월'!H33 -> 01AF542 | I32: ='1월'!I33 -> Processor VRM 2B4E For 8231-E1C, E1D, E2D, 8268-E1D, 8246-L1C | J32: ='1월'!J33 -> 1 | K32: ='1월'!K33 -> 430000 | L32: ='1월'!L33 -> 430000 | M32: ='1월'!M33 -> 43000 | N32: ='1월'!N33 -> 473000 | ... S32: ='1월'!S33 -> 천범석
A33: . | B33: ='1월'!B34 -> H250106-01 | D33: ='1월'!D34 -> 45672 | E33: ='1월'!E34 -> 아이엠티에스아이 | G33: ='1월'!G34 -> 상품 | H33: ='1월'!H34 -> 69Y2926 | I33: ='1월'!I34 -> Controller Battery for DS3512/DS3524 | J33: ='1월'!J34 -> 1 | K33: ='1월'!K34 -> 280000 | L33: ='1월'!L34 -> 280000 | M33: ='1월'!M34 -> 28000 | N33: ='1월'!N34 -> 308000 | ... S33: ='1월'!S34 -> 천범석
B34: ='1월'!B35 -> H250310 | D34: ='1월'!D35 -> 45673 | E34: ='1월'!E35 -> 더블포인트 | G34: ='1월'!G35 -> 상품 | H34: ='1월'!H35 -> CABLE | I34: ='1월'!I35 -> LC-LC OM3, 멀티 광점퍼코드 15M 30개 외 | J34: ='1월'!J35 -> 1 | K34: ='1월'!K35 -> 900000 | L34: ='1월'!L35 -> 900000 | M34: ='1월'!M35 -> 90000 | N34: ='1월'!N35 -> 990000 | ... S34: ='1월'!S35 -> 이예지
A35: . | B35: ='1월'!B36 -> Y241223-01 | D35: ='1월'!D36 -> 45673 | E35: ='1월'!E36 -> 라온전자 | G35: ='1월'!G36 -> 상품 | H35: ='1월'!H36 -> 맥북프로 | I35: ='1월'!I36 -> M3 Pro 11코어 / 14코어 GPU / 512GB / 18GB / 실버 | J35: ='1월'!J36 -> 1 | K35: ='1월'!K36 -> 2500000 | L35: ='1월'!L36 -> 2500000 | M35: ='1월'!M36 -> 250000 | N35: ='1월'!N36 -> 2750000 | ... S35: ='1월'!S36 -> 홍승민
A36: . | B36: ='1월'!B37 -> Y250102-01 | D36: ='1월'!D37 -> 45673 | E36: ='1월'!E37 -> 라온전자 | G36: ='1월'!G37 -> 상품 | H36: ='1월'!H37 -> 맥북프로 | I36: ='1월'!I37 -> M3 Pro 11코어 / 14코어 GPU / 512GB / 18GB / 블랙 | J36: ='1월'!J37 -> 1 | K36: ='1월'!K37 -> 2500000 | L36: ='1월'!L37 -> 2500000 | M36: ='1월'!M37 -> 250000 | N36: ='1월'!N37 -> 2750000 | ... S36: ='1월'!S37 -> 홍승민
A37: . | B37: ='1월'!B38 -> Y250107-01 | D37: ='1월'!D38 -> 45673 | E37: ='1월'!E38 -> 라온전자 | G37: ='1월'!G38 -> 상품 | H37: ='1월'!H38 -> Monitor | I37: ='1월'!I38 -> LG 27MR400 | J37: ='1월'!J38 -> 1 | K37: ='1월'!K38 -> 170000 | L37: ='1월'!L38 -> 170000 | M37: ='1월'!M38 -> 17000 | N37: ='1월'!N38 -> 187000 | ... S37: ='1월'!S38 -> 홍승민
A38: . | B38: ='1월'!B39 -> Y250113-01 | D38: ='1월'!D39 -> 45673 | E38: ='1월'!E39 -> 라온전자 | G38: ='1월'!G39 -> 상품 | H38: ='1월'!H39 -> 소모품 | I38: ='1월'!I39 -> 로지텍 K120 NEW+ 마우스 M90 세트 외 | J38: ='1월'!J39 -> 1 | K38: ='1월'!K39 -> 294000 | L38: ='1월'!L39 -> 294000 | M38: ='1월'!M39 -> 29400 | N38: ='1월'!N39 -> 323400 | ... S38: ='1월'!S39 -> 홍승민
A39: . | B39: ='1월'!B40 -> H250118-01 | D39: ='1월'!D40 -> 45675 | E39: ='1월'!E40 -> 넷매니아 | G39: ='1월'!G40 -> 상품 | H39: ='1월'!H40 -> POWER | I39: ='1월'!I40 -> POWER SUPPLY for DELL ME4024 | J39: ='1월'!J40 -> 1 | K39: ='1월'!K40 -> 1050000 | L39: ='1월'!L40 -> 1050000 | M39: ='1월'!M40 -> 105000 | N39: ='1월'!N40 -> 1155000 | ... S39: ='1월'!S40 -> 천범석
A40: . | B40: ='1월'!B41 -> Y240830-03 | D40: ='1월'!D41 -> 45676 | E40: ='1월'!E41 -> 스마트웨어 | F40: ='1월'!F41 -> 세연시스템즈 | G40: ='1월'!G41 -> 장비임대 | H40: ='1월'!H41 -> 서버임대 | I40: ='1월'!I41 -> X3650M5 임대 (Xeon E5-2640v3 2.6GHz 8C x2 / 128GB Memory / 600GB SAS x4 / Power x2)(24/12/2~25/1/1) | J40: ='1월'!J41 -> 1 | K40: ='1월'!K41 -> 200000 | ... S40: ='1월'!S41 -> 홍승민
...

Sheet 분류
A2: [월별매출] | B2: 공급가액 | C2: 부가세 | D2: 합계 | E2: 건수 | F2: GP | J2: [개인별 매출] | K2: 이예지 | L2: 홍승민 | M2: 천범석 | N2: 이지훈 | O2: 정지우 | P2: 항목별소계 | R2: 오류체크 | S2: 오류차
A3: 1월 | B3: ='1월'!L129 -> 380620734 | C3: ='1월'!M129 -> 38062074 | D3: ='1월'!N129 -> 4.1868281e+08 | E3: ='1월'!D131 -> 115 | F3: ='1월'!Q129 -> 62686433 | I3: MA | J3: MA | K3: =SUMIFS(Master!$L$2:$L$779,Master!$S$2:$S$779,분류!K$2,Master!$G$2:$G$779,분류!$J3) -> 267060602 | L3: =SUMIFS(Master!$L$2:$L$779,Master!$S$2:$S$779,분류!L$2,Master!$G$2:$G$779,분류!$J3) -> 89662002 | M3: =SUMIFS(Master!$L$2:$L$779,Master!$S$2:$S$779,분류!M$2,Master!$G$2:$G$779,분류!$J3) -> 769518660 | N3: =SUMIFS(Master!$L$2:$L$779,Master!$S$2:$S$779,분류!N$2,Master!$G$2:$G$779,분류!$J3) -> 500000 | O3: =SUMIFS(Master!$L$2:$L$779,Master!$S$2:$S$779,분류!O$2,Master!$G$2:$G$779,분류!$J3) -> 0 | P3: =SUM(K3:O3) -> 1126741264 | R3: =IF(B20=P11,"OK","F") -> OK | S3: =B20-P11 -> 0
A4: 2월 | B4: ='2월'!L134 -> 231155498 | C4: ='2월'!M134 -> 23115550 | D4: ='2월'!N134 -> 2.5427105e+08 | E4: ='2월'!D136 -> 117 | F4: ='2월'!Q134 -> 53454099 | J4: MAPAC | K4: =SUMIFS(Master!$L$2:$L$779,Master!$S$2:$S$779,분류!K$2,Master!$G$2:$G$779,분류!$J4) -> 0 | L4: =SUMIFS(Master!$L$2:$L$779,Master!$S$2:$S$779,분류!L$2,Master!$G$2:$G$779,분류!$J4) -> 0 | M4: =SUMIFS(Master!$L$2:$L$779,Master!$S$2:$S$779,분류!M$2,Master!$G$2:$G$779,분류!$J4) -> 43137000 | N4: =SUMIFS(Master!$L$2:$L$779,Master!$S$2:$S$779,분류!N$2,Master!$G$2:$G$779,분류!$J4) -> 0 | O4: =SUMIFS(Master!$L$2:$L$779,Master!$S$2:$S$779,분류!O$2,Master!$G$2:$G$779,분류!$J4) -> 0 | P4: =SUM(K4:O4) -> 43137000
A5: 3월 | B5: ='3월'!L126 -> 285300289 | C5: ='3월'!M126 -> 28530029 | D5: ='3월'!N126 -> 3.1383032e+08 | E5: ='3월'!D128 -> 115 | F5: ='3월'!Q126 -> 56080695 | G5: =SUM(B3:B5) -> 897076521 | J5: WSU | K5: =SUMIFS(Master!$L$2:$L$779,Master!$S$2:$S$779,분류!K$2,Master!$G$2:$G$779,분류!$J5) -> 0 | L5: =SUMIFS(Master!$L$2:$L$779,Master!$S$2:$S$779,분류!L$2,Master!$G$2:$G$779,분류!$J5) -> 0 | M5: =SUMIFS(Master!$L$2:$L$779,Master!$S$2:$S$779,분류!M$2,Master!$G$2:$G$779,분류!$J5) -> 13000000 | N5: =SUMIFS(Master!$L$2:$L$779,Master!$S$2:$S$779,분류!N$2,Master!$G$2:$G$779,분류!$J5) -> 0 | O5: =SUMIFS(Master!$L$2:$L$779,Master!$S$2:$S$779,분류!O$2,Master!$G$2:$G$779,분류!$J5) -> 0 | P5: =SUM(K5:O5) -> 13000000
A6: 4월 | B6: ='4월'!L142 -> 274111414 | C6: ='4월'!M142 -> 27411142 | D6: ='4월'!N142 -> 3.0152256e+08 | E6: ='4월'!D144 -> 119 | F6: ='4월'!Q142 -> 53721843 | I6: 건물임대 | J6: 건물임대 | K6: =SUMIFS(Master!$L$2:$L$779,Master!$S$2:$S$779,분류!K$2,Master!$G$2:$G$779,분류!$J6) -> 0 | L6: =SUMIFS(Master!$L$2:$L$779,Master!$S$2:$S$779,분류!L$2,Master!$G$2:$G$779,분류!$J6) -> 0 | M6: =SUMIFS(Master!$L$2:$L$779,Master!$S$2:$S$779,분류!M$2,Master!$G$2:$G$779,분류!$J6) -> 0 | N6: =SUMIFS(Master!$L$2:$L$779,Master!$S$2:$S$779,분류!N$2,Master!$G$2:$G$779,분류!$J6) -> 0 | O6: =SUMIFS(Master!$L$2:$L$779,Master!$S$2:$S$779,분류!O$2,Master!$G$2:$G$779,분류!$J6) -> 80084794 | P6: =SUM(K6:O6) -> 80084794
A7: 5월 | B7: ='5월'!L120 -> 207663334 | C7: ='5월'!M120 -> 20766334 | D7: ='5월'!N120 -> 2.2842967e+08 | E7: ='5월'!D122 -> 109 | F7: ='5월'!Q120 -> 42257024 | I7: 상품 | J7: 상품 | K7: =SUMIFS(Master!$L$2:$L$779,Master!$S$2:$S$779,분류!K$2,Master!$G$2:$G$779,분류!$J7) -> 92306000 | L7: =SUMIFS(Master!$L$2:$L$779,Master!$S$2:$S$779,분류!L$2,Master!$G$2:$G$779,분류!$J7) -> 207424000 | M7: =SUMIFS(Master!$L$2:$L$779,Master!$S$2:$S$779,분류!M$2,Master!$G$2:$G$779,분류!$J7) -> 93178000 | N7: =SUMIFS(Master!$L$2:$L$779,Master!$S$2:$S$779,분류!N$2,Master!$G$2:$G$779,분류!$J7) -> 43123000 | O7: =SUMIFS(Master!$L$2:$L$779,Master!$S$2:$S$779,분류!O$2,Master!$G$2:$G$779,분류!$J7) -> 0 | P7: =SUM(K7:O7) -> 436031000
A8: 6월 | B8: ='6월'!L149 -> 331652789 | C8: ='6월'!M149 -> 33165279 | D8: ='6월'!N149 -> 3.6481807e+08 | E8: ='6월'!D149 -> 127 | F8: ='6월'!Q147 -> 73097157 | G8: =SUM(B6:B8) -> 813427537 | J8: 장비임대 | K8: =SUMIFS(Master!$L$2:$L$779,Master!$S$2:$S$779,분류!K$2,Master!$G$2:$G$779,분류!$J8) -> 0 | L8: =SUMIFS(Master!$L$2:$L$779,Master!$S$2:$S$779,분류!L$2,Master!$G$2:$G$779,분류!$J8) -> 4210000 | M8: =SUMIFS(Master!$L$2:$L$779,Master!$S$2:$S$779,분류!M$2,Master!$G$2:$G$779,분류!$J8) -> 7100000 | N8: =SUMIFS(Master!$L$2:$L$779,Master!$S$2:$S$779,분류!N$2,Master!$G$2:$G$779,분류!$J8) -> 200000 | O8: =SUMIFS(Master!$L$2:$L$779,Master!$S$2:$S$779,분류!O$2,Master!$G$2:$G$779,분류!$J8) -> 0 | P8: =SUM(K8:O8) -> 11510000
A9: 7월 | J9: 수출 | M9: =B18 -> 0 | P9: =SUM(K9:O9) -> 0
A10: 8월 | J10: 카드/현금 | M10: =B17 -> 0 | P10: =SUM(K10:O10) -> 0
A11: 9월 | J11: 개인별 매출계 | K11: =SUM(K3:K10) -> 359366602 | L11: =SUM(L3:L10) -> 301296002 | M11: =SUM(M3:M10) -> 925933660 | N11: =SUM(N3:N10) -> 43823000 | O11: =SUM(O3:O10) -> 80084794 | P11: =ROUNDDOWN(SUM(K11:O11),0) -> 1710504058
A12: 10월
A13: 11월 | J13: [개인별 GP] | K13: 이예지 | L13: 홍승민 | M13: 천범석 | N13: 이지훈 | O13: 정지우 | P13: 항목별소계 | R13: 오류체크 | S13: 오류차
A14: 12월 | I14: MA | J14: MA | K14: =SUMIFS(Master!$Q$2:$Q$779,Master!$S$2:$S$779,분류!K$13,Master!$G$2:$G$779,분류!$J14) -> 42978704 | L14: =SUMIFS(Master!$Q$2:$Q$779,Master!$S$2:$S$779,분류!L$13,Master!$G$2:$G$779,분류!$J14) -> 37861465 | M14: =SUMIFS(Master!$Q$2:$Q$779,Master!$S$2:$S$779,분류!M$13,Master!$G$2:$G$779,분류!$J14) -> 1.0062504e+08 | N14: =SUMIFS(Master!$Q$2:$Q$779,Master!$S$2:$S$779,분류!N$13,Master!$G$2:$G$779,분류!$J14) -> 500000 | O14: =SUMIFS(Master!$Q$2:$Q$779,Master!$S$2:$S$779,분류!O$13,Master!$G$2:$G$779,분류!$J14) -> 0 | P14: =SUM(K14:O14) -> 181965214 | R14: =IF(F20=P22,"OK","F") -> OK | S14: =F20-P22 -> 0
A15: 계산서합 | B15: =SUM(B3:B14) -> 1710504058 | C15: =SUM(C3:C14) -> 1.7105041e+08 | D15: =SUM(D3:D14) -> 1.8815545e+09 | E15: =SUM(E3:E14) -> 702 | F15: =SUM(F3:F14) -> 3.4129725e+08 | J15: MAPAC | K15: =SUMIFS(Master!$Q$2:$Q$779,Master!$S$2:$S$779,분류!K$13,Master!$G$2:$G$779,분류!$J15) -> 0 | L15: =SUMIFS(Master!$Q$2:$Q$779,Master!$S$2:$S$779,분류!L$13,Master!$G$2:$G$779,분류!$J15) -> 0 | M15: =SUMIFS(Master!$Q$2:$Q$779,Master!$S$2:$S$779,분류!M$13,Master!$G$2:$G$779,분류!$J15) -> 3886847 | N15: =SUMIFS(Master!$Q$2:$Q$779,Master!$S$2:$S$779,분류!N$13,Master!$G$2:$G$779,분류!$J15) -> 0 | O15: =SUMIFS(Master!$Q$2:$Q$779,Master!$S$2:$S$779,분류!O$13,Master!$G$2:$G$779,분류!$J15) -> 0 | P15: =SUM(K15:O15) -> 3886847
J16: WSU | K16: =SUMIFS(Master!$Q$2:$Q$779,Master!$S$2:$S$779,분류!K$13,Master!$G$2:$G$779,분류!$J16) -> 0 | L16: =SUMIFS(Master!$Q$2:$Q$779,Master!$S$2:$S$779,분류!L$13,Master!$G$2:$G$779,분류!$J16) -> 0 | M16: =SUMIFS(Master!$Q$2:$Q$779,Master!$S$2:$S$779,분류!M$13,Master!$G$2:$G$779,분류!$J16) -> 6888172 | N16: =SUMIFS(Master!$Q$2:$Q$779,Master!$S$2:$S$779,분류!N$13,Master!$G$2:$G$779,분류!$J16) -> 0 | O16: =SUMIFS(Master!$Q$2:$Q$779,Master!$S$2:$S$779,분류!O$13,Master!$G$2:$G$779,분류!$J16) -> 0 | P16: =SUM(K16:O16) -> 6888172
A17: 카드/현금 | I17: 건물임대 | J17: 건물임대 | K17: =SUMIFS(Master!$Q$2:$Q$779,Master!$S$2:$S$779,분류!K$13,Master!$G$2:$G$779,분류!$J17) -> 0 | L17: =SUMIFS(Master!$Q$2:$Q$779,Master!$S$2:$S$779,분류!L$13,Master!$G$2:$G$779,분류!$J17) -> 0 | M17: =SUMIFS(Master!$Q$2:$Q$779,Master!$S$2:$S$779,분류!M$13,Master!$G$2:$G$779,분류!$J17) -> 0 | N17: =SUMIFS(Master!$Q$2:$Q$779,Master!$S$2:$S$779,분류!N$13,Master!$G$2:$G$779,분류!$J17) -> 0 | O17: =SUMIFS(Master!$Q$2:$Q$779,Master!$S$2:$S$779,분류!O$13,Master!$G$2:$G$779,분류!$J17) -> 80084794 | P17: =SUM(K17:O17) -> 80084794
A18: 수출 | I18: 상품 | J18: 상품 | K18: =SUMIFS(Master!$Q$2:$Q$779,Master!$S$2:$S$779,분류!K$13,Master!$G$2:$G$779,분류!$J18) -> 2050090.5 | L18: =SUMIFS(Master!$Q$2:$Q$779,Master!$S$2:$S$779,분류!L$13,Master!$G$2:$G$779,분류!$J18) -> 44965084 | M18: =SUMIFS(Master!$Q$2:$Q$779,Master!$S$2:$S$779,분류!M$13,Master!$G$2:$G$779,분류!$J18) -> 12592197 | N18: =SUMIFS(Master!$Q$2:$Q$779,Master!$S$2:$S$779,분류!N$13,Master!$G$2:$G$779,분류!$J18) -> 3997853 | O18: =SUMIFS(Master!$Q$2:$Q$779,Master!$S$2:$S$779,분류!O$13,Master!$G$2:$G$779,분류!$J18) -> 0 | P18: =SUM(K18:O18) -> 63605225
J19: 장비임대 | K19: =SUMIFS(Master!$Q$2:$Q$779,Master!$S$2:$S$779,분류!K$13,Master!$G$2:$G$779,분류!$J19) -> 0 | L19: =SUMIFS(Master!$Q$2:$Q$779,Master!$S$2:$S$779,분류!L$13,Master!$G$2:$G$779,분류!$J19) -> 4035000 | M19: =SUMIFS(Master!$Q$2:$Q$779,Master!$S$2:$S$779,분류!M$13,Master!$G$2:$G$779,분류!$J19) -> 632000 | N19: =SUMIFS(Master!$Q$2:$Q$779,Master!$S$2:$S$779,분류!N$13,Master!$G$2:$G$779,분류!$J19) -> 200000 | O19: =SUMIFS(Master!$Q$2:$Q$779,Master!$S$2:$S$779,분류!O$13,Master!$G$2:$G$779,분류!$J19) -> 0 | P19: =SUM(K19:O19) -> 4867000
A20: 연매출 | B20: =ROUNDDOWN(SUM(B15,B17,B18),0) -> 1710504058 | C20: =SUM(C15,C17,C18) -> 1.7105041e+08 | D20: =SUM(D15,D17,D18) -> 1.8815545e+09 | E20: =SUM(E15,E17,E18) -> 702 | F20: =ROUNDDOWN(SUM(F15,F17,F18),0) -> 341297251 | J20: 수출 | L20: 0 | M20: =F18 -> 0 | N20: 0 | O20: 0 | P20: =SUM(K20:O20) -> 0
J21: 카드/현금 | M21: =F17 -> 0 | P21: =SUM(K21:O21) -> 0
J22: 개인별 GP계 | K22: =SUM(K14:K21) -> 45028795 | L22: =SUM(L14:L21) -> 86861550 | M22: =SUM(M14:M21) -> 1.2462426e+08 | N22: =SUM(N14:N21) -> 4697853 | O22: =SUM(O14:O21) -> 80084794 | P22: =ROUNDDOWN(SUM(K22:O22),0) -> 341297251
P23: =P22/P11 -> 0.19953022
A24: Rank | B24: [업체별 매출] | C24: 합계 | D24: 상품 | E24: MA | F24: MAPAC | G24: WSU | H24: 장비임대 | I24: 건물임대 | J24: GP | K24: 수익율 | R24: 오류체크 | S24: 오류차
C25: =ROUNDDOWN(SUM(C26:C184),0) -> 1710504058 | D25: =ROUNDDOWN(SUM(D26:D184),0) -> 436031000 | E25: =ROUNDDOWN(SUM(E26:E184),0) -> 1126741264 | F25: =ROUNDDOWN(SUM(F26:F184),0) -> 43137000 | G25: =ROUNDDOWN(SUM(G26:G184),0) -> 13000000 | H25: =ROUNDDOWN(SUM(H26:H184),0) -> 11510000 | I25: =ROUNDDOWN(SUM(I26:I184),0) -> 80084794 | J25: =ROUNDDOWN(SUM(J26:J184),0) -> 341297251 | K25: =J25/C25 -> 0.19953022 | R25: =IF(B20=C25,"OK","F") -> OK | S25: =B20-C25 -> 0
A26: =RANK(C26,$C$26:$C$184,0) -> 89 | B26: 가나병원 | C26: =SUMIF(Master!$E$2:$E$779,분류!B26,Master!$L$2:$L$779) -> 1800000 | D26: =SUMIFS(Master!$L$2:$L$779,Master!$E$2:$E$779,분류!B26,Master!$G$2:$G$779,분류!$D$24) -> 0 | E26: =SUMIFS(Master!$L$2:$L$779,Master!$E$2:$E$779,분류!B26,Master!$G$2:$G$779,분류!$E$24) -> 1800000 | F26: =SUMIFS(Master!$L$2:$L$779,Master!$E$2:$E$779,분류!B26,Master!$G$2:$G$779,분류!$F$24) -> 0 | G26: =SUMIFS(Master!$L$2:$L$779,Master!$E$2:$E$779,분류!B26,Master!$G$2:$G$779,분류!$G$24) -> 0 | H26: =SUMIFS(Master!$L$2:$L$779,Master!$E$2:$E$779,분류!B26,Master!$G$2:$G$779,분류!$H$24) -> 0 | I26: =SUMIFS(Master!$L$2:$L$779,Master!$E$2:$E$779,분류!B26,Master!$G$2:$G$779,분류!$I$24) -> 0 | J26: =SUMIF(Master!$E$2:$E$779,분류!B26,Master!$Q$2:$Q$779) -> 1800000
A27: =RANK(C27,$C$26:$C$184,0) -> 72 | B27: 일원병원 | C27: =SUMIF(Master!$E$2:$E$779,분류!B27,Master!$L$2:$L$779) -> 3140000 | D27: =SUMIFS(Master!$L$2:$L$779,Master!$E$2:$E$779,분류!B27,Master!$G$2:$G$779,분류!$D$24) -> 140000 | E27: =SUMIFS(Master!$L$2:$L$779,Master!$E$2:$E$779,분류!B27,Master!$G$2:$G$779,분류!$E$24) -> 3000000 | F27: =SUMIFS(Master!$L$2:$L$779,Master!$E$2:$E$779,분류!B27,Master!$G$2:$G$779,분류!$F$24) -> 0 | G27: =SUMIFS(Master!$L$2:$L$779,Master!$E$2:$E$779,분류!B27,Master!$G$2:$G$779,분류!$G$24) -> 0 | H27: =SUMIFS(Master!$L$2:$L$779,Master!$E$2:$E$779,분류!B27,Master!$G$2:$G$779,분류!$H$24) -> 0 | I27: =SUMIFS(Master!$L$2:$L$779,Master!$E$2:$E$779,분류!B27,Master!$G$2:$G$779,분류!$I$24) -> 0 | J27: =SUMIF(Master!$E$2:$E$779,분류!B27,Master!$Q$2:$Q$779) -> 2336400
A28: =RANK(C28,$C$26:$C$184,0) -> 11 | B28: 고영 | C28: =SUMIF(Master!$E$2:$E$779,분류!B28,Master!$L$2:$L$779) -> 46063000 | D28: =SUMIFS(Master!$L$2:$L$779,Master!$E$2:$E$779,분류!B28,Master!$G$2:$G$779,분류!$D$24) -> 37663000 | E28: =SUMIFS(Master!$L$2:$L$779,Master!$E$2:$E$779,분류!B28,Master!$G$2:$G$779,분류!$E$24) -> 8400000 | F28: =SUMIFS(Master!$L$2:$L$779,Master!$E$2:$E$779,분류!B28,Master!$G$2:$G$779,분류!$F$24) -> 0 | G28: =SUMIFS(Master!$L$2:$L$779,Master!$E$2:$E$779,분류!B28,Master!$G$2:$G$779,분류!$G$24) -> 0 | H28: =SUMIFS(Master!$L$2:$L$779,Master!$E$2:$E$779,분류!B28,Master!$G$2:$G$779,분류!$H$24) -> 0 | I28: =SUMIFS(Master!$L$2:$L$779,Master!$E$2:$E$779,분류!B28,Master!$G$2:$G$779,분류!$I$24) -> 0 | J28: =SUMIF(Master!$E$2:$E$779,분류!B28,Master!$Q$2:$Q$779) -> 8597653
A29: =RANK(C29,$C$26:$C$184,0) -> 23 | B29: 서부컨테이너터미널 | C29: =SUMIF(Master!$E$2:$E$779,분류!B29,Master!$L$2:$L$779) -> 23500002 | D29: =SUMIFS(Master!$L$2:$L$779,Master!$E$2:$E$779,분류!B29,Master!$G$2:$G$779,분류!$D$24) -> 0 | E29: =SUMIFS(Master!$L$2:$L$779,Master!$E$2:$E$779,분류!B29,Master!$G$2:$G$779,분류!$E$24) -> 23500002 | F29: =SUMIFS(Master!$L$2:$L$779,Master!$E$2:$E$779,분류!B29,Master!$G$2:$G$779,분류!$F$24) -> 0 | G29: =SUMIFS(Master!$L$2:$L$779,Master!$E$2:$E$779,분류!B29,Master!$G$2:$G$779,분류!$G$24) -> 0 | H29: =SUMIFS(Master!$L$2:$L$779,Master!$E$2:$E$779,분류!B29,Master!$G$2:$G$779,분류!$H$24) -> 0 | I29: =SUMIFS(Master!$L$2:$L$779,Master!$E$2:$E$779,분류!B29,Master!$G$2:$G$779,분류!$I$24) -> 0 | J29: =SUMIF(Master!$E$2:$E$779,분류!B29,Master!$Q$2:$Q$779) -> 2685331.3
A30: =RANK(C30,$C$26:$C$184,0) -> 97 | B30: 나라정보 | C30: =SUMIF(Master!$E$2:$E$779,분류!B30,Master!$L$2:$L$779) -> 1242000 | D30: =SUMIFS(Master!$L$2:$L$779,Master!$E$2:$E$779,분류!B30,Master!$G$2:$G$779,분류!$D$24) -> 0 | E30: =SUMIFS(Master!$L$2:$L$779,Master!$E$2:$E$779,분류!B30,Master!$G$2:$G$779,분류!$E$24) -> 1242000 | F30: =SUMIFS(Master!$L$2:$L$779,Master!$E$2:$E$779,분류!B30,Master!$G$2:$G$779,분류!$F$24) -> 0 | G30: =SUMIFS(Master!$L$2:$L$779,Master!$E$2:$E$779,분류!B30,Master!$G$2:$G$779,분류!$G$24) -> 0 | H30: =SUMIFS(Master!$L$2:$L$779,Master!$E$2:$E$779,분류!B30,Master!$G$2:$G$779,분류!$H$24) -> 0 | I30: =SUMIFS(Master!$L$2:$L$779,Master!$E$2:$E$779,분류!B30,Master!$G$2:$G$779,분류!$I$24) -> 0 | J30: =SUMIF(Master!$E$2:$E$779,분류!B30,Master!$Q$2:$Q$779) -> 96906
A31: =RANK(C31,$C$26:$C$184,0) -> 71 | B31: 나우테크 | C31: =SUMIF(Master!$E$2:$E$779,분류!B31,Master!$L$2:$L$779) -> 3200000 | D31: =SUMIFS(Master!$L$2:$L$779,Master!$E$2:$E$779,분류!B31,Master!$G$2:$G$779,분류!$D$24) -> 0 | E31: =SUMIFS(Master!$L$2:$L$779,Master!$E$2:$E$779,분류!B31,Master!$G$2:$G$779,분류!$E$24) -> 0 | F31: =SUMIFS(Master!$L$2:$L$779,Master!$E$2:$E$779,분류!B31,Master!$G$2:$G$779,분류!$F$24) -> 3200000 | G31: =SUMIFS(Master!$L$2:$L$779,Master!$E$2:$E$779,분류!B31,Master!$G$2:$G$779,분류!$G$24) -> 0 | H31: =SUMIFS(Master!$L$2:$L$779,Master!$E$2:$E$779,분류!B31,Master!$G$2:$G$779,분류!$H$24) -> 0 | I31: =SUMIFS(Master!$L$2:$L$779,Master!$E$2:$E$779,분류!B31,Master!$G$2:$G$779,분류!$I$24) -> 0 | J31: =SUMIF(Master!$E$2:$E$779,분류!B31,Master!$Q$2:$Q$779) -> 575680
A32: =RANK(C32,$C$26:$C$184,0) -> 103 | B32: 넷매니아 | C32: =SUMIF(Master!$E$2:$E$779,분류!B32,Master!$L$2:$L$779) -> 1050000 | D32: =SUMIFS(Master!$L$2:$L$779,Master!$E$2:$E$779,분류!B32,Master!$G$2:$G$779,분류!$D$24) -> 1050000 | E32: =SUMIFS(Master!$L$2:$L$779,Master!$E$2:$E$779,분류!B32,Master!$G$2:$G$779,분류!$E$24) -> 0 | F32: =SUMIFS(Master!$L$2:$L$779,Master!$E$2:$E$779,분류!B32,Master!$G$2:$G$779,분류!$F$24) -> 0 | G32: =SUMIFS(Master!$L$2:$L$779,Master!$E$2:$E$779,분류!B32,Master!$G$2:$G$779,분류!$G$24) -> 0 | H32: =SUMIFS(Master!$L$2:$L$779,Master!$E$2:$E$779,분류!B32,Master!$G$2:$G$779,분류!$H$24) -> 0 | I32: =SUMIFS(Master!$L$2:$L$779,Master!$E$2:$E$779,분류!B32,Master!$G$2:$G$779,분류!$I$24) -> 0 | J32: =SUMIF(Master!$E$2:$E$779,분류!B32,Master!$Q$2:$Q$779) -> 250000
A33: =RANK(C33,$C$26:$C$184,0) -> 7 | B33: 다솜테크 | C33: =SUMIF(Master!$E$2:$E$779,분류!B33,Master!$L$2:$L$779) -> 56423350 | D33: =SUMIFS(Master!$L$2:$L$779,Master!$E$2:$E$779,분류!B33,Master!$G$2:$G$779,분류!$D$24) -> 17000000 | E33: =SUMIFS(Master!$L$2:$L$779,Master!$E$2:$E$779,분류!B33,Master!$G$2:$G$779,분류!$E$24) -> 39423350 | F33: =SUMIFS(Master!$L$2:$L$779,Master!$E$2:$E$779,분류!B33,Master!$G$2:$G$779,분류!$F$24) -> 0 | G33: =SUMIFS(Master!$L$2:$L$779,Master!$E$2:$E$779,분류!B33,Master!$G$2:$G$779,분류!$G$24) -> 0 | H33: =SUMIFS(Master!$L$2:$L$779,Master!$E$2:$E$779,분류!B33,Master!$G$2:$G$779,분류!$H$24) -> 0 | I33: =SUMIFS(Master!$L$2:$L$779,Master!$E$2:$E$779,분류!B33,Master!$G$2:$G$779,분류!$I$24) -> 0 | J33: =SUMIF(Master!$E$2:$E$779,분류!B33,Master!$Q$2:$Q$779) -> 3422690
A34: =RANK(C34,$C$26:$C$184,0) -> 70 | B34: 다올시스 | C34: =SUMIF(Master!$E$2:$E$779,분류!B34,Master!$L$2:$L$779) -> 3316000 | D34: =SUMIFS(Master!$L$2:$L$779,Master!$E$2:$E$779,분류!B34,Master!$G$2:$G$779,분류!$D$24) -> 1000000 | E34: =SUMIFS(Master!$L$2:$L$779,Master!$E$2:$E$779,분류!B34,Master!$G$2:$G$779,분류!$E$24) -> 2316000 | F34: =SUMIFS(Master!$L$2:$L$779,Master!$E$2:$E$779,분류!B34,Master!$G$2:$G$779,분류!$F$24) -> 0 | G34: =SUMIFS(Master!$L$2:$L$779,Master!$E$2:$E$779,분류!B34,Master!$G$2:$G$779,분류!$G$24) -> 0 | H34: =SUMIFS(Master!$L$2:$L$779,Master!$E$2:$E$779,분류!B34,Master!$G$2:$G$779,분류!$H$24) -> 0 | I34: =SUMIFS(Master!$L$2:$L$779,Master!$E$2:$E$779,분류!B34,Master!$G$2:$G$779,분류!$I$24) -> 0 | J34: =SUMIF(Master!$E$2:$E$779,분류!B34,Master!$Q$2:$Q$779) -> 639400
A35: =RANK(C35,$C$26:$C$184,0) -> 22 | B35: 다올앤씨 | C35: =SUMIF(Master!$E$2:$E$779,분류!B35,Master!$L$2:$L$779) -> 23600000 | D35: =SUMIFS(Master!$L$2:$L$779,Master!$E$2:$E$779,분류!B35,Master!$G$2:$G$779,분류!$D$24) -> 23600000 | E35: =SUMIFS(Master!$L$2:$L$779,Master!$E$2:$E$779,분류!B35,Master!$G$2:$G$779,분류!$E$24) -> 0 | F35: =SUMIFS(Master!$L$2:$L$779,Master!$E$2:$E$779,분류!B35,Master!$G$2:$G$779,분류!$F$24) -> 0 | G35: =SUMIFS(Master!$L$2:$L$779,Master!$E$2:$E$779,분류!B35,Master!$G$2:$G$779,분류!$G$24) -> 0 | H35: =SUMIFS(Master!$L$2:$L$779,Master!$E$2:$E$779,분류!B35,Master!$G$2:$G$779,분류!$H$24) -> 0 | I35: =SUMIFS(Master!$L$2:$L$779,Master!$E$2:$E$779,분류!B35,Master!$G$2:$G$779,분류!$I$24) -> 0 | J35: =SUMIF(Master!$E$2:$E$779,분류!B35,Master!$Q$2:$Q$779) -> 6785000
A36: =RANK(C36,$C$26:$C$184,0) -> 109 | B36: 대신네트웍스 | C36: =SUMIF(Master!$E$2:$E$779,분류!B36,Master!$L$2:$L$779) -> 835000 | D36: =SUMIFS(Master!$L$2:$L$779,Master!$E$2:$E$779,분류!B36,Master!$G$2:$G$779,분류!$D$24) -> 0 | E36: =SUMIFS(Master!$L$2:$L$779,Master!$E$2:$E$779,분류!B36,Master!$G$2:$G$779,분류!$E$24) -> 835000 | F36: =SUMIFS(Master!$L$2:$L$779,Master!$E$2:$E$779,분류!B36,Master!$G$2:$G$779,분류!$F$24) -> 0 | G36: =SUMIFS(Master!$L$2:$L$779,Master!$E$2:$E$779,분류!B36,Master!$G$2:$G$779,분류!$G$24) -> 0 | H36: =SUMIFS(Master!$L$2:$L$779,Master!$E$2:$E$779,분류!B36,Master!$G$2:$G$779,분류!$H$24) -> 0 | I36: =SUMIFS(Master!$L$2:$L$779,Master!$E$2:$E$779,분류!B36,Master!$G$2:$G$779,분류!$I$24) -> 0 | J36: =SUMIF(Master!$E$2:$E$779,분류!B36,Master!$Q$2:$Q$779) -> 140200
A37: =RANK(C37,$C$26:$C$184,0) -> 17 | B37: 파워시스 | C37: =SUMIF(Master!$E$2:$E$779,분류!B37,Master!$L$2:$L$779) -> 34888000 | D37: =SUMIFS(Master!$L$2:$L$779,Master!$E$2:$E$779,분류!B37,Master!$G$2:$G$779,분류!$D$24) -> 1450000 | E37: =SUMIFS(Master!$L$2:$L$779,Master!$E$2:$E$779,분류!B37,Master!$G$2:$G$779,분류!$E$24) -> 33438000 | F37: =SUMIFS(Master!$L$2:$L$779,Master!$E$2:$E$779,분류!B37,Master!$G$2:$G$779,분류!$F$24) -> 0 | G37: =SUMIFS(Master!$L$2:$L$779,Master!$E$2:$E$779,분류!B37,Master!$G$2:$G$779,분류!$G$24) -> 0 | H37: =SUMIFS(Master!$L$2:$L$779,Master!$E$2:$E$779,분류!B37,Master!$G$2:$G$779,분류!$H$24) -> 0 | I37: =SUMIFS(Master!$L$2:$L$779,Master!$E$2:$E$779,분류!B37,Master!$G$2:$G$779,분류!$I$24) -> 0 | J37: =SUMIF(Master!$E$2:$E$779,분류!B37,Master!$Q$2:$Q$779) -> 4198800
... A73: =RANK(C73,$C$26:$C$184,0) -> 6 | B73: 솔리드시스템 | C73: =SUMIF(Master!$E$2:$E$779,분류!B73,Master!$L$2:$L$779) -> 70578000 | D73: =SUMIFS(Master!$L$2:$L$779,Master!$E$2:$E$779,분류!B73,Master!$G$2:$G$779,분류!$D$24) -> 0 | E73: =SUMIFS(Master!$L$2:$L$779,Master!$E$2:$E$779,분류!B73,Master!$G$2:$G$779,분류!$E$24) -> 70578000 | F73: =SUMIFS(Master!$L$2:$L$779,Master!$E$2:$E$779,분류!B73,Master!$G$2:$G$779,분류!$F$24) -> 0 | G73: =SUMIFS(Master!$L$2:$L$779,Master!$E$2:$E$779,분류!B73,Master!$G$2:$G$779,분류!$G$24) -> 0 | H73: =SUMIFS(Master!$L$2:$L$779,Master!$E$2:$E$779,분류!B73,Master!$G$2:$G$779,분류!$H$24) -> 0 | I73: =SUMIFS(Master!$L$2:$L$779,Master!$E$2:$E$779,분류!B73,Master!$G$2:$G$779,분류!$I$24) -> 0 | J73: =SUMIF(Master!$E$2:$E$779,분류!B73,Master!$Q$2:$Q$779) -> 7506000
B74: 솔향 | C74: =SUMIF(Master!$E$2:$E$779,분류!B74,Master!$L$2:$L$779) -> 0 | D74: =SUMIFS(Master!$L$2:$L$779,Master!$E$2:$E$779,분류!B74,Master!$G$2:$G$779,분류!$D$24) -> 0 | E74: =SUMIFS(Master!$L$2:$L$779,Master!$E$2:$E$779,분류!B74,Master!$G$2:$G$779,분류!$E$24) -> 0 | F74: =SUMIFS(Master!$L$2:$L$779,Master!$E$2:$E$779,분류!B74,Master!$G$2:$G$779,분류!$F$24) -> 0 | G74: =SUMIFS(Master!$L$2:$L$779,Master!$E$2:$E$779,분류!B74,Master!$G$2:$G$779,분류!$G$24) -> 0 | H74: =SUMIFS(Master!$L$2:$L$779,Master!$E$2:$E$779,분류!B74,Master!$G$2:$G$779,분류!$H$24) -> 0 | I74: =SUMIFS(Master!$L$2:$L$779,Master!$E$2:$E$779,분류!B74,Master!$G$2:$G$779,분류!$I$24) -> 0 | J74: =SUMIF(Master!$E$2:$E$779,분류!B74,Master!$Q$2:$Q$779) -> 0
A75: =RANK(C75,$C$26:$C$184,0) -> 69 | B75: 순환 | C75: =SUMIF(Master!$E$2:$E$779,분류!B75,Master!$L$2:$L$779) -> 3333630 | D75: =SUMIFS(Master!$L$2:$L$779,Master!$E$2:$E$779,분류!B75,Master!$G$2:$G$779,분류!$D$24) -> 0 | E75: =SUMIFS(Master!$L$2:$L$779,Master!$E$2:$E$779,분류!B75,Master!$G$2:$G$779,분류!$E$24) -> 0 | F75: =SUMIFS(Master!$L$2:$L$779,Master!$E$2:$E$779,분류!B75,Master!$G$2:$G$779,분류!$F$24) -> 0 | G75: =SUMIFS(Master!$L$2:$L$779,Master!$E$2:$E$779,분류!B75,Master!$G$2:$G$779,분류!$G$24) -> 0 | H75: =SUMIFS(Master!$L$2:$L$779,Master!$E$2:$E$779,분류!B75,Master!$G$2:$G$779,분류!$H$24) -> 0 | I75: =SUMIFS(Master!$L$2:$L$779,Master!$E$2:$E$779,분류!B75,Master!$G$2:$G$779,분류!$I$24) -> 3333630 | J75: =SUMIF(Master!$E$2:$E$779,분류!B75,Master!$Q$2:$Q$779) -> 3333630
A76: =RANK(C76,$C$26:$C$184,0) -> 96 | B76: 스마트에프앤디 | C76: =SUMIF(Master!$E$2:$E$779,분류!B76,Master!$L$2:$L$779) -> 1320000 | D76: =SUMIFS(Master!$L$2:$L$779,Master!$E$2:$E$779,분류!B76,Master!$G$2:$G$779,분류!$D$24) -> 0 | E76: =SUMIFS(Master!$L$2:$L$779,Master!$E$2:$E$779,분류!B76,Master!$G$2:$G$779,분류!$E$24) -> 1320000 | F76: =SUMIFS(Master!$L$2:$L$779,Master!$E$2:$E$779,분류!B76,Master!$G$2:$G$779,분류!$F$24) -> 0 | G76: =SUMIFS(Master!$L$2:$L$779,Master!$E$2:$E$779,분류!B76,Master!$G$2:$G$779,분류!$G$24) -> 0 | H76: =SUMIFS(Master!$L$2:$L$779,Master!$E$2:$E$779,분류!B76,Master!$G$2:$G$779,분류!$H$24) -> 0 | I76: =SUMIFS(Master!$L$2:$L$779,Master!$E$2:$E$779,분류!B76,Master!$G$2:$G$779,분류!$I$24) -> 0 | J76: =SUMIF(Master!$E$2:$E$779,분류!B76,Master!$Q$2:$Q$779) -> 121200
...

Sheet 1월
B1: ="["&YEAR(D3)&"년 "&MONTH(D3)&"월 매출]" -> [2025년 1월 매출]
B2: 품의코드 | C2: Vendor 코드 | D2: 날짜 | E2: 매출처 | F2: END-USER | G2: 구분 | H2: MA : 청구구분 상품 : PN | I2: 거래내용 | J2: 수량 | K2: 단가 | L2: 공급가액 | M2: 부가세 | N2: 공급가합계 | O2: 매입액 | P2: 매입거래처 | Q2: GP | R2: 입금일 | S2: 영업 담당자 | T2: 비고
A3: . | B3: S | D3: 45658 | E3: 홈닥터 | F3: 광명자이 1811호 | G3: 건물임대 | H3: 임대료 | I3: 12월(12.5~25.1.4) 임대료 - 11/24회 | J3: 1 | K3: 550000 | L3: =J3*K3 -> 550000 | M3: =L3*10% -> 55000 | N3: =SUM(L3:M3) -> 605000 | O3: 0 | P3: X | Q3: =L3-O3 -> 550000 | R3: 완료(1/2) | S3: 정지우
A4: . | B4: IK-22025 | D4: 45658 | E4: 디에스피 | F4: 엘지생활건강 | G4: MA | H4: 월간-IBM | I4: 1월 유지정비료 - 12/12회 | J4: 1 | K4: 635000 | L4: =J4*K4 -> 635000 | M4: =L4*10% -> 63500 | N4: =SUM(L4:M4) -> 698500 | O4: 532212 | P4: IBM(1/2) | Q4: =L4-O4 -> 102788 | R4: 완료(1/31) | S4: 천범석
A5: . | B5: SM-23015 | D5: 45658 | E5: 동원프라스틱 | F5: 동원프라스틱 | G5: MA | H5: 월간 | I5: 1월 유지정비료 - 10/13회 | J5: 1 | K5: 1200000 | L5: =J5*K5 -> 1200000 | M5: =L5*10% -> 120000 | N5: =SUM(L5:M5) -> 1320000 | O5: =4800000/6 -> 800000 | P5: 시스나인(25/3/4) 4,800,000 1/6회 | Q5: =L5-O5 -> 400000 | R5: 완료(25/1/31) | S5: 이예지
A6: . | B6: IK-23016 | D6: 45658 | E6: 케이정보기술 | F6: 청주시청 | G6: MA | H6: 월간-IBM | I6: 1월 유지정비료 - 17/36회 | J6: 1 | K6: 1300000 | L6: =J6*K6 -> 1300000 | M6: =L6*10% -> 130000 | N6: =SUM(L6:M6) -> 1430000 | O6: =1123962+8384 -> 1132346 | P6: IBM(1/2) IBM(1/31) 8,384 | Q6: =L6-O6 -> 167654 | R6: 완료(2/28) | S6: 천범석
A7: . | B7: SM-24011 | D7: 45658 | E7: 가나병원 | G7: MA | H7: 월간 | I7: 1월 유지정비료 - 9/12회 | J7: 1 | K7: 300000 | L7: =J7*K7 -> 300000 | M7: =L7*10% -> 30000 | N7: =SUM(L7:M7) -> 330000 | O7: 0 | P7: SM | Q7: =L7-O7 -> 300000 | R7: 완료(1/9) | S7: 천범석
A8: . | B8: LI-24004 | D8: 45658 | E8: 한국메탈 | G8: MA | H8: 월간-IBM | I8: 1월 유지정비료 - 9/36회 | J8: 1 | K8: 507500 | L8: =J8*K8 -> 507500 | M8: =L8*10% -> 50750 | N8: =SUM(L8:M8) -> 558250 | O8: =316682+800000/8 -> 416682 | P8: IBM(1/2) 316,682 시스나인(1/2) 연간 1,200,000(1/12회) | Q8: =L8-O8 -> 90818 | R8: 완료(1/24) | S8: 천범석
A9: . | B9: LI-24005 | C9: Z4ACEZ | D9: 45658 | E9: 해종합건축사사무소 | G9: MA | H9: 월간-IBM | I9: 1월 유지정비료 - 8/12회 | J9: 1 | K9: 1554500 | L9: =J9*K9 -> 1554500 | M9: =L9*10% -> 155450 | N9: =SUM(L9:M9) -> 1709950 | O9: =171600+6000000/12+436400+200000 -> 1308000 | P9: 레노버(1/31) 171,600 IBM(1/1) 436,400 에스엔에이(1/15) 200,000 시스나인(25/3/4) 연간 6,000,000 8/12회 | Q9: =L9-O9 -> 246500 | R9: 완료(25/1/24) | S9: 천범석
A10: . | B10: SB-24039 | C10: ZZGBBZ | D10: 45658 | E10: 한국디지털방송 | G10: MA | H10: 월간-레노버 | I10: 1월 유지정비료 - 7/12회 | J10: 1 | K10: 1423000 | L10: =J10*K10 -> 1423000 | M10: =L10*10% -> 142300 | N10: =SUM(L10:M10) -> 1565300 | O10: 1120200 | P10: 레노버(1/31) | Q10: =L10-O10 -> 302800 | R10: 완료(1/24) | S10: 천범석
A11: . | B11: IK-24008 | D11: 45658 | E11: 서비스링크 | F11: 세원정공(폴라리스세원) | G11: MA | H11: 월간-레노버 | I11: 1월 유지정비료 - 7/12회 | J11: 1 | K11: 238000 | L11: =J11*K11 -> 238000 | M11: =L11*10% -> 23800 | N11: =SUM(L11:M11) -> 261800 | O11: 198018 | P11: IBM(1/2) | Q11: =L11-O11 -> 39982 | R11: 완료(1/31) | S11: 천범석
A12: . | B12: IK-24013 | D12: 45658 | E12: 레드텍 | F12: 대한상공회의소 | G12: MA | H12: 월간-IBM | I12: 1월 유지정비료 - 3/12회 | J12: 1 | K12: 158400 | L12: =J12*K12 -> 158400 | M12: =L12*10% -> 15840 | N12: =SUM(L12:M12) -> 174240 | O12: 94111 | P12: IBM(1/2) | Q12: =L12-O12 -> 64289 | R12: 완료(1/16) | S12: 천범석
A13: . | B13: SM-23012 | D13: 45658 | E13: 택스홈앤아웃 | F13: 본사 | G13: MA | H13: 월간 | I13: VPN 서비스 1월임대료 - 1/12회 280,000 + 보안스위치 1월 2대*120,000 | J13: 1 | K13: =280000+2*120000 -> 520000 | L13: =J13*K13 -> 520000 | M13: =L13*10% -> 52000 | N13: =SUM(L13:M13) -> 572000 | O13: =213400+155200 -> 368600 | P13: 엘림넷(1/10) 213,400 (1/10) 155,200 | Q13: =L13-O13 -> 151400 | R13: 완료(25/1/31) | S13: 이예지
A14: . | B14: SM-23013 | D14: 45658 | E14: 하이엔드택스 강남지점 | F14: 압구정 | G14: MA | H14: 월간 | I14: VPN 서비스/ 1월임대료 - 1/12회 | J14: 1 | K14: 320000 | L14: =J14*K14 -> 320000 | M14: =L14*10% -> 32000 | N14: =SUM(L14:M14) -> 352000 | O14: =145500+77600 -> 223100 | P14: 엘림넷(1/10) 145,500 (1/10) 77,600 | Q14: =L14-O14 -> 96900 | R14: 완료132,000(1/3) 220,000(2/3) | S14: 이예지
A15: . | B15: SM-23016 | D15: 45658 | E15: 에실로코리아 | F15: 에실로코리아 | G15: MA | H15: 월간 | I15: 1월 유지정비료 - 1/12회 | J15: 1 | K15: 100000 | L15: =J15*K15 -> 100000 | M15: =L15*10% -> 10000 | N15: =SUM(L15:M15) -> 110000 | O15: 0 | P15: SM | Q15: =L15-O15 -> 100000 | R15: 완료(2/14) | S15: 이예지
A16: . | B16: IK-22022 | D16: 45658 | E16: 로인아이티 | F16: 한일전기 | G16: MA | H16: 월간-IBM | I16: 분기(1~3월) 유지정비료 - 9/12회 | J16: 1 | K16: 1233000 | L16: =J16*K16 -> 1233000 | M16: =L16*10% -> 123300 | N16: =SUM(L16:M16) -> 1356300 | O16: =309047*3 -> 927141 | P16: IBM (1/1)309,047 (2/3)(3/1) | Q16: =L16-O16 -> 305859 | R16: 완료(2/25) | S16: 천범석
A17: . | B17: SB-22053 | C17: ZEKV4M | D17: 45658 | E17: 심플키 | F17: 한국산업은행 | G17: MA | H17: 월간-레노버 | I17: 분기(1~3월) 유지정비료 - 9/12회 | J17: 1 | K17: 200000 | L17: =J17*K17 -> 200000 | M17: =L17*10% -> 20000 | N17: =SUM(L17:M17) -> 220000 | O17: =58800*3 -> 176400 | P17: 레노버 월 58,800(1/31)(2/28)(3/31) | Q17: =L17-O17 -> 23600 | R17: 완료(1/31) | S17: 천범석
A18: . | B18: SB-24042 | C18: ZTME0P | D18: 45658 | E18: 심플키 | F18: 티시스 | G18: MA | H18: 월간-레노버 | I18: 분기(1~3월) 유지정비료 - 3/4회 | J18: 1 | K18: 5651400 | L18: =J18*K18 -> 5651400 | M18: =L18*10% -> 565140 | N18: =SUM(L18:M18) -> 6216540 | O18: =1706400*3+1000000/12*3 -> 5369200 | P18: 레노버 (1/31) 1,706,400 (2/28)(3/31) 시스나인(7/1) 연간 1,000,000 (8~10/12회) | Q18: =L18-O18 -> 282200 | R18: 완료(3/31) | S18: 천범석
A19: . | B19: SB-24066 | C19: ZDSNDX | D19: 45659 | E19: 이룸정보 | F19: 중국광대은행 | G19: MA | H19: 월간-레노버 | I19: 1~11월 유지정비료 | J19: 11 | K19: 108000 | L19: =J19*K19 -> 1188000 | M19: =L19*10% -> 118800 | N19: =SUM(L19:M19) -> 1306800 | O19: =98100*11 -> 1079100 | P19: 레노버 98,100(1/31)(2/28)(3/31)(4/30) (5/31)(6/30)(7/31)(8/31)(9/30)(10/31)(11/30) | Q19: =L19-O19 -> 108900 | R19: 완료(3/25) | S19: 천범석
A20: . | B20: SL-24050 | C20: ZXFJNS | D20: 45661 | E20: 스마트에프앤디 | G20: MA | H20: 월간-레노버 | I20: 연간유지정비료(25.01.04~26.01.03) | J20: 1 | K20: 1320000 | L20: =J20*K20 -> 1320000 | M20: =L20*10% -> 132000 | N20: =SUM(L20:M20) -> 1452000 | O20: 1198800 | P20: 레노버(1/31)89,910 월 99,900 (2/28)(3/31)(4/30)(5/31) (6/30)(7/31)(8/31)(9/30)(10/31)(11/30)(12/31)(26/1/ ) | Q20: =L20-O20 -> 121200 | R20: 완료(1/15) | S20: 천범석
A21: . | B21: S | D21: 45662 | E21: 장형기업 | F21: 검단미플존 316호 | G21: 건물임대 | H21: 임대료 | I21: 1월 임대료 - 3/8회 | J21: 1 | K21: 367500 | L21: =J21*K21 -> 367500 | M21: =L21*10% -> 36750 | N21: =SUM(L21:M21) -> 404250 | O21: 0 | P21: X | Q21: =L21-O21 -> 367500 | R21: 완료(25/1/31) | S21: 정지우
A22: . | B22: SM-24021 | D22: 45662 | E22: 제이원캐피탈 | G22: MA | H22: 월간 | I22: 12월 유지정비료 - 4/12회 | J22: 1 | K22: 7060000 | L22: =J22*K22 -> 7060000 | M22: =L22*10% -> 706000 | N22: =SUM(L22:M22) -> 7766000 | O22: =691781+300000+70000+1000000/12+810000+352900+5000000/3 -> 3974681 | P22: IBM(12/1) 691,781 에스엔에이(12/31) 300,000 키미데이타(12/31) 70,000 코오롱베니트(10/31) 1,000,000연간(4/12회) 더파트(12/31) 810,000 DCSS(24/12/31) 352,900 시스나인(11/1) 분기5,000 000(3/3회) | Q22: =L22-O22 -> 3085319 | R22: 완료(1/31) | S22: 이예지
A23: . | B23: SM-24020 | D23: 45662 | E23: 에이비씨한국 | G23: MA | H23: 월간 | I23: BOARD SYSTEM Maintenance 1월분 - 4/12회 | J23: 1 | K23: 1100000 | L23: =J23*K23 -> 1100000 | M23: =L23*10% -> 110000 | N23: =SUM(L23:M23) -> 1210000 | O23: 1060000 | P23: 로보츠(1/5) | Q23: =L23-O23 -> 40000 | R23: 완료(2/28) | S23: 이예지
B24: IK-24012 | D24: 45663 | E24: 인정보시스템 | F24: 대구텍 | G24: MA | H24: 월간-IBM | I24: 1월 유지정비료 - 1/6회 | J24: 1 | K24: 1039500 | L24: =J24*K24 -> 1039500 | M24: =L24*10% -> 103950 | N24: =SUM(L24:M24) -> 1143450 | O24: 862260 | P24: IBM(1/6) | Q24: =L24-O24 -> 177240 | R24: 완료(1/31) | S24: 천범석 | U24: 여신 30일견적됨, 확인필요
B25: S | D25: 45666 | E25: 에이비씨한국 | G25: 상품 | H25: 노트북 | I25: 엘지 노트북 납품 외 | J25: 1 | K25: 1520000 | L25: =J25*K25 -> 1520000 | M25: =L25*10% -> 152000 | N25: =SUM(L25:M25) -> 1672000 | O25: 1490000 | P25: 로보츠(1/9) | Q25: =L25-O25 -> 30000 | R25: 완료(2/28) | S25: 이예지
A26: . | B26: SM-25003 | C26: ZZ6BIS | D26: 45666 | E26: 영화시스템 | F26: CGV통합 | G26: MA | H26: 연간 | I26: 연간유지정비료(25.01.01~25.12.31) | J26: 1 | K26: 95680000 | L26: =J26*K26 -> 95680000 | M26: =L26*10% -> 9568000 | N26: =SUM(L26:M26) -> 105248000 | O26: =33750000+17010000+8454000+6730000+680000+18000000 -> 84624000 | P26: IBM 총 33,750,000 월 2,812,500 (1/2)(2/3)(3/4)(4/1)(5/1)(6/2)(7/1)(8/1) (9/1)(10/1)(11/1)(1/21) 레노버 17,010,000 월 1,417,500 (1/31)(2/28)(3/31)(4/30)(5/31)(6/30)(7/31)(8/31)(9/30)(10/31)(11/30)(12/31) 코오롱베니트(1/31) 680,000 에티버스(1/31) 8,454,000 에티버스(6/30) 6,730,000 시스나인(2/28) 18,000,000 | Q26: =L26-O26 -> 11056000 | R26: 완료(3/10) | S26: 천범석
A27: . | B27: S | D27: 45667 | E27: 중소기업은행 | F27: 호계214~216호 | G27: 건물임대 | H27: 임대료 | I27: 1월 임대료 (12.13~1.12) | J27: 1 | K27: 6090000 | L27: =J27*K27 -> 6090000 | M27: =L27*10% -> 609000 | N27: =SUM(L27:M27) -> 6699000 | O27: 0 | P27: X | Q27: =L27-O27 -> 6090000 | R27: 완료(1/13) | S27: 정지우
A28: . | B28: S | D28: 45667 | E28: 아이티앤 | F28: 우물단 | G28: 상품 | H28: 기술지원 | I28: 전산장비 이전, 시스템 마이그레이션 (1차) | J28: 1 | K28: 12500000 | L28: =J28*K28 -> 12500000 | M28: =L28*10% -> 1250000 | N28: =SUM(L28:M28) -> 13750000 | O28: 0 | P28: (24/12/26) | Q28: 0 | R28: 완료(25/1/31) | S28: 이예지 | U28: 매출정리
A29: . | B29: S | D29: 45669 | E29: 왕길토건 | F29: 검단미플존 317호 | G29: 건물임대 | H29: 임대료 | I29: 12월 임대료(24/12/12~25/1/10) - 3/10회 | J29: 1 | K29: 400000 | L29: =J29*K29 -> 400000 | M29: =L29*10% -> 40000 | N29: =SUM(L29:M29) -> 440000 | O29: 0 | P29: X | Q29: =L29-O29 -> 400000 | R29: 완료(25/1/31) | S29: 정지우
B30: S | D30: 45671 | E30: 에이비씨한국 | F30: 평택 | G30: 상품 | H30: 노트북 | I30: 엘지 노트북 납품 외 | J30: 1 | K30: 2273000 | L30: =J30*K30 -> 2273000 | M30: =L30*10% -> 227300 | N30: =SUM(L30:M30) -> 2500300 | O30: 2227000 | P30: 로보츠(1/14) | Q30: =L30-O30 -> 46000 | R30: 완료(2/28) | S30: 이예지
A31: . | B31: S | D31: 45672 | E31: 순환 | F31: 검단미플존 318호 | G31: 건물임대 | H31: 임대료 | I31: 1월 임대료(24/12/20~25/1/19) - 3/9회 | J31: 1 | K31: 346500 | L31: =J31*K31 -> 346500 | M31: =L31*10% -> 34650 | N31: =SUM(L31:M31) -> 381150 | O31: 0 | P31: X | Q31: =L31-O31 -> 346500 | R31: 완료(1/24) | S31: 정지우
A32: . | B32: SB-24011 | C32: Z5PURB | D32: 45672 | E32: 비온시이노베이터 | F32: 국립농업과학원 | G32: MA | H32: 월간-레노버 | I32: 12월 유지정비료 - 12/24회 | J32: 1 | K32: 875000 | L32: =J32*K32 -> 875000 | M32: =L32*10% -> 87500 | N32: =SUM(L32:M32) -> 962500 | O32: =511500+3400000/12 -> 794833.33 | P32: 레노버(12/31)511,500 시스나인(25/1/2) 연간3,400,000(12/12회) | Q32: =L32-O32 -> 80166.667 | R32: 완료(2/10) | S32: 천범석
A33: . | B33: H250102-01 | D33: 45672 | E33: 아이엠티에스아이 | G33: 상품 | H33: 01AF542 | I33: Processor VRM 2B4E For 8231-E1C, E1D, E2D, 8268-E1D, 8246-L1C | J33: 1 | K33: 430000 | L33: =J33*K33 -> 430000 | M33: =L33*10% -> 43000 | N33: =SUM(L33:M33) -> 473000 | O33: 400000 | P33: 이비웨이브(1/2) | Q33: =L33-O33 -> 30000 | R33: 완료(1/17) | S33: 천범석
A34: . | B34: H250106-01 | D34: 45672 | E34: 아이엠티에스아이 | G34: 상품 | H34: 69Y2926 | I34: Controller Battery for DS3512/DS3524 | J34: 1 | K34: 280000 | L34: =J34*K34 -> 280000 | M34: =L34*10% -> 28000 | N34: =SUM(L34:M34) -> 308000 | O34: 250000 | P34: 이비웨이브(1/6) | Q34: =L34-O34 -> 30000 | R34: 완료(1/17) | S34: 천범석
B35: H250310 | D35: 45673 | E35: 더블포인트 | G35: 상품 | H35: CABLE | I35: LC-LC OM3, 멀티 광점퍼코드 15M 30개 외 | J35: 1 | K35: 900000 | L35: =J35*K35 -> 900000 | M35: =L35*10% -> 90000 | N35: =SUM(L35:M35) -> 990000 | O35: =248000/1.1+285455 -> 510909.55 | P35: 쿠팡(3/10법카) 285,455 컴퓨존(3/14) 시스나인(3/4) 330,000 | Q35: =L35-O35 -> 389090.45 | R35: 완료(3/10) | S35: 이예지
A36: . | B36: Y241223-01 | D36: 45673 | E36: 라온전자 | G36: 상품 | H36: 맥북프로 | I36: M3 Pro 11코어 / 14코어 GPU / 512GB / 18GB / 실버 | J36: 1 | K36: 2500000 | L36: =J36*K36 -> 2500000 | M36: =L36*10% -> 250000 | N36: =SUM(L36:M36) -> 2750000 | O36: =2160909+18000 -> 2178909 | P36: 쿠팡(12/6법카) 2,160,909 우림퀵(1/31) 18,000 | Q36: =L36-O36 -> 321091 | R36: 완료(1/31) | S36: 홍승민
A37: . | B37: Y250102-01 | D37: 45673 | E37: 라온전자 | G37: 상품 | H37: 맥북프로 | I37: M3 Pro 11코어 / 14코어 GPU / 512GB / 18GB / 블랙 | J37: 1 | K37: 2500000 | L37: =J37*K37 -> 2500000 | M37: =L37*10% -> 250000 | N37: =SUM(L37:M37) -> 2750000 | O37: 2312436 | P37: 쿠팡(12/30법카) | Q37: =L37-O37 -> 187564 | R37: 완료(1/31) | S37: 홍승민
A38: . | B38: Y250107-01 | D38: 45673 | E38: 라온전자 | G38: 상품 | H38: Monitor | I38: LG 27MR400 | J38: 1 | K38: 170000 | L38: =J38*K38 -> 170000 | M38: =L38*10% -> 17000 | N38: =SUM(L38:M38) -> 187000 | O38: 150000 | P38: 컴퓨존(1/7) | Q38: =L38-O38 -> 20000 | R38: 완료(1/31) | S38: 홍승민
A39: . | B39: Y250113-01 | D39: 45673 | E39: 라온전자 | G39: 상품 | H39: 소모품 | I39: 로지텍 K120 NEW+ 마우스 M90 세트 외 | J39: 1 | K39: 294000 | L39: =J39*K39 -> 294000 | M39: =L39*10% -> 29400 | N39: =SUM(L39:M39) -> 323400 | O39: =195273+20182+23182+6000 -> 244637 | P39: 컴퓨존(1/13) 195,273 쿠팡(1/13법카)20,182 네이버(1/13법카)23,182 로젠택배(1/31) 6,000 | Q39: =L39-O39 -> 49363 | R39: 완료(1/31) | S39: 홍승민
A40: . | B40: H250118-01 | D40: 45675 | E40: 넷매니아 | G40: 상품 | H40: POWER | I40: POWER SUPPLY for DELL ME4024 | J40: 1 | K40: 1050000 | L40: =J40*K40 -> 1050000 | M40: =L40*10% -> 105000 | N40: =SUM(L40:M40) -> 1155000 | O40: 800000 | P40: 에스엔에이(1/21) | Q40: =L40-O40 -> 250000 | R40: 완료(1/18) | S40: 천범석
...

Sheet 2월
B1: ="["&YEAR(D3)&"년 "&MONTH(D3)&"월 매출]" -> [2025년 2월 매출]
B2: 품의코드 | C2: Vendor 코드 | D2: 날짜 | E2: 매출처 | F2: END-USER | G2: 구분 | H2: MA : 청구구분 상품 : PN | I2: 거래내용 | J2: 수량 | K2: 단가 | L2: 공급가액 | M2: 부가세 | N2: 공급가합계 | O2: 매입액 | P2: 매입거래처 | Q2: GP | R2: 입금일 | S2: 영업 담당자 | T2: 비고
A3: . | B3: S | D3: 45689 | E3: 홈닥터 | F3: 광명자이 1811호 | G3: 건물임대 | H3: 임대료 | I3: 1월(1.5~2.4) 임대료 - 12/24회 | J3: 1 | K3: 550000 | L3: =J3*K3 -> 550000 | M3: =L3*10% -> 55000 | N3: =SUM(L3:M3) -> 605000 | O3: 0 | P3: X | Q3: =L3-O3 -> 550000 | R3: 완료(1/24) | S3: 정지우
A4: . | B4: SM-23015 | D4: 45689 | E4: 동원프라스틱 | F4: 동원프라스틱 | G4: MA | H4: 월간 | I4: 2월 유지정비료 - 11/13회 | J4: 1 | K4: 1200000 | L4: =J4*K4 -> 1200000 | M4: =L4*10% -> 120000 | N4: =SUM(L4:M4) -> 1320000 | O4: =4800000/6 -> 800000 | P4: 시스나인(25/3/4) 4,800,000 2/6회 | Q4: =L4-O4 -> 400000 | R4: 완료(2/28) | S4: 이예지
A5: . | B5: IK-23016 | D5: 45689 | E5: 케이정보기술 | F5: 청주시청 | G5: MA | H5: 월간-IBM | I5: 2월 유지정비료 - 18/35회 | J5: 1 | K5: 1600000 | L5: =J5*K5 -> 1600000 | M5: =L5*10% -> 160000 | N5: =SUM(L5:M5) -> 1760000 | O5: =1123962+259896 -> 1383858 | P5: IBM(2/3) 1,123,962 (2/3) 259,896 | Q5: =L5-O5 -> 216142 | R5: 완료(3/31) | S5: 천범석
A6: . | B6: SM-24011 | D6: 45689 | E6: 가나병원 | G6: MA | H6: 월간 | I6: 2월 유지정비료 - 10/12회 | J6: 1 | K6: 300000 | L6: =J6*K6 -> 300000 | M6: =L6*10% -> 30000 | N6: =SUM(L6:M6) -> 330000 | O6: 0 | P6: SM | Q6: =L6-O6 -> 300000 | R6: 완료(2/10) | S6: 천범석
A7: . | B7: LI-24004 | D7: 45689 | E7: 한국메탈 | G7: MA | H7: 월간-IBM | I7: 2월 유지정비료 - 10/36회 | J7: 1 | K7: 507500 | L7: =J7*K7 -> 507500 | M7: =L7*10% -> 50750 | N7: =SUM(L7:M7) -> 558250 | O7: =316682+800000/8 -> 416682 | P7: IBM(2/3) 316,682 시스나인(1/2) 연간 1,200,000(2/12회) | Q7: =L7-O7 -> 90818 | R7: 완료(2/28) | S7: 천범석
A8: . | B8: LI-24005 | C8: Z4ACEZ | D8: 45689 | E8: 해종합건축사사무소 | G8: MA | H8: 월간-IBM | I8: 2월 유지정비료 - 9/12회 | J8: 1 | K8: 1554500 | L8: =J8*K8 -> 1554500 | M8: =L8*10% -> 155450 | N8: =SUM(L8:M8) -> 1709950 | O8: =171600+6000000/12+436400+200000 -> 1308000 | P8: 레노버(2/28) 171,600 에스엔에이(2/15) 200,000 IBM(2/3) 436,400 시스나인(25/3/4) 연간 6,000,000 9/12회 | Q8: =L8-O8 -> 246500 | R8: 완료(2/28) | S8: 천범석
A9: . | B9: SB-24039 | C9: ZZGBBZ | D9: 45689 | E9: 한국디지털방송 | G9: MA | H9: 월간-레노버 | I9: 2월 유지정비료 - 8/12회 | J9: 1 | K9: 1423000 | L9: =J9*K9 -> 1423000 | M9: =L9*10% -> 142300 | N9: =SUM(L9:M9) -> 1565300 | O9: 1120200 | P9: 레노버(2/28) | Q9: =L9-O9 -> 302800 | R9: 완료(2/24) | S9: 천범석
A10: . | B10: IK-24008 | D10: 45689 | E10: 서비스링크 | F10: 세원정공(폴라리스세원) | G10: MA | H10: 월간-레노버 | I10: 2월 유지정비료 - 8/12회 | J10: 1 | K10: 238000 | L10: =J10*K10 -> 238000 | M10: =L10*10% -> 23800 | N10: =SUM(L10:M10) -> 261800 | O10: 198018 | P10: IBM(2/3) | Q10: =L10-O10 -> 39982 | R10: 완료(2/28) | S10: 천범석
A11: . | B11: IK-24012 | D11: 45689 | E11: 인정보시스템 | F11: 대구텍 | G11: MA | H11: 월간-IBM | I11: 2월 유지정비료 - 2/6회 | J11: 1 | K11: 1039500 | L11: =J11*K11 -> 1039500 | M11: =L11*10% -> 103950 | N11: =SUM(L11:M11) -> 1143450 | O11: 990000 | P11: IBM(2/3) | Q11: =L11-O11 -> 49500 | R11: 완료(2/27) | S11: 천범석
A12: . | B12: IK-24013 | D12: 45689 | E12: 레드텍 | F12: 대한상공회의소 | G12: MA | H12: 월간-IBM | I12: 2월 유지정비료 - 4/12회 | J12: 1 | K12: 158400 | L12: =J12*K12 -> 158400 | M12: =L12*10% -> 15840 | N12: =SUM(L12:M12) -> 174240 | O12: 145780 | P12: IBM(2/3) | Q12: =L12-O12 -> 12620 | R12: 완료(2/3) | S12: 천범석
A13: . | B13: SM-23012 | D13: 45689 | E13: 택스홈앤아웃 | F13: 본사 | G13: MA | H13: 월간 | I13: VPN 서비스 2월임대료 - 2/12회 280,000 + 보안스위치 2월 2대*120,000 | J13: 1 | K13: =280000+2*120000 -> 520000 | L13: =J13*K13 -> 520000 | M13: =L13*10% -> 52000 | N13: =SUM(L13:M13) -> 572000 | O13: =213400+155200 -> 368600 | P13: 엘림넷(2/10) 213,400 (2/10) 155,200 | Q13: =L13-O13 -> 151400 | R13: 완료(2/28) | S13: 이예지
A14: . | B14: SM-23013 | D14: 45689 | E14: 하이엔드택스 강남지점 | F14: 압구정 | G14: MA | H14: 월간 | I14: VPN 서비스/ 2월임대료 - 2/12회 | J14: 1 | K14: 320000 | L14: =J14*K14 -> 320000 | M14: =L14*10% -> 32000 | N14: =SUM(L14:M14) -> 352000 | O14: =145500+77600 -> 223100 | P14: 엘림넷(2/10) 145,500 (2/10) 77,600 | Q14: =L14-O14 -> 96900 | R14: 완료(3/5) | S14: 이예지
A15: . | B15: SM-23016 | D15: 45689 | E15: 에실로코리아 | F15: 에실로코리아 | G15: MA | H15: 월간 | I15: 2월 유지정비료 - 2/12회 | J15: 1 | K15: 100000 | L15: =J15*K15 -> 100000 | M15: =L15*10% -> 10000 | N15: =SUM(L15:M15) -> 110000 | O15: 0 | P15: SM | Q15: =L15-O15 -> 100000 | R15: 완료(3/12) | S15: 이예지
A16: . | B16: IK-22025 | D16: 45689 | E16: 디에스피 | F16: 엘지생활건강 청주공장 | G16: MA | H16: 월간-IBM | I16: 2월 유지정비료 - 1/12회 | J16: 1 | K16: 635000 | L16: =J16*K16 -> 635000 | M16: =L16*10% -> 63500 | N16: =SUM(L16:M16) -> 698500 | O16: 564192 | P16: IBM(2/3) | Q16: =L16-O16 -> 70808 | R16: 완료(3/4) | S16: 천범석
A17: . | B17: S | D17: 45693 | E17: 장형기업 | F17: 검단미플존 316호 | G17: 건물임대 | H17: 임대료 | I17: 2월 임대료 - 4/8회 | J17: 1 | K17: 367500 | L17: =J17*K17 -> 367500 | M17: =L17*10% -> 36750 | N17: =SUM(L17:M17) -> 404250 | O17: 0 | P17: X | Q17: =L17-O17 -> 367500 | R17: 완료(2/28) | S17: 정지우
A18: . | B18: SM-24021 | D18: 45693 | E18: 제이원캐피탈 | G18: MA | H18: 월간 | I18: 1월 유지정비료 - 5/12회 | J18: 1 | K18: 7060000 | L18: =J18*K18 -> 7060000 | M18: =L18*10% -> 706000 | N18: =SUM(L18:M18) -> 7766000 | O18: =691781+300000+70000+1000000/12+810000+352900+5000000/3 -> 3974681 | P18: IBM(1/1) 691,781 에스엔에이(1/31) 300,000 키미데이타(1/31) 70,000 코오롱베니트(10/31) 1,000,000연간(5/12회) 더파트(1/31) 810,000 DCSS(1/31) 352,900 시스나인(4/25) 분기5,000 000(1/3회) | Q18: =L18-O18 -> 3085319 | R18: 완료(3/5) | S18: 이예지
A19: . | B19: SM-24020 | D19: 45693 | E19: 에이비씨한국 | G19: MA | H19: 월간 | I19: BOARD SYSTEM Maintenance 2월분 - 5/12회 | J19: 1 | K19: 1100000 | L19: =J19*K19 -> 1100000 | M19: =L19*10% -> 110000 | N19: =SUM(L19:M19) -> 1210000 | O19: 1060000 | P19: 로보츠(2/5) | Q19: =L19-O19 -> 40000 | R19: 완료(3/31) | S19: 이예지
A20: . | B20: S | D20: 45693 | E20: 아이티앤 | F20: 우물단 | G20: 상품 | H20: 기술지원 | I20: 전산장비 이전, 시스템 마이그레이션 (2차) | J20: 1 | K20: 12500000 | L20: =J20*K20 -> 12500000 | M20: =L20*10% -> 1250000 | N20: =SUM(L20:M20) -> 13750000 | O20: 0 | P20: (24/12/26) | Q20: 0 | R20: 완료(2/28) | S20: 이예지 | U20: 매출정리
A21: . | B21: SL-25005 | C21: TAHXA0200 | D21: 45693 | E21: 반정보시스템 | F21: 대상정보 | G21: MAPAC | H21: 연간-레노버 | I21: 연간유지정비료(24.05.25~26.03.31) | J21: 1 | K21: 15652000 | L21: =J21*K21 -> 15652000 | M21: =L21*10% -> 1565200 | N21: =SUM(L21:M21) -> 17217200 | O21: 14492160 | P21: 레노버(2/5) | Q21: =L21-O21 -> 1159840 | R21: 완료(4/2) | S21: 천범석
A22: . | B22: S | D22: 45695 | E22: 홈닥터 | F22: 광명자이 1811호 | G22: 건물임대 | H22: 임대료 | I22: 2월(2.5~2.6) 임대료 - 최종 | J22: 1 | K22: 36164 | L22: =J22*K22 -> 36164 | M22: 3616 | N22: =SUM(L22:M22) -> 39780 | O22: 0 | P22: X | Q22: =L22-O22 -> 36164 | R22: 보증금에서공제(2/7) | S22: 정지우
A23: . | B23: S | D23: 45698 | E23: 중소기업은행 | F23: 호계214~216호 | G23: 건물임대 | H23: 임대료 | I23: 2월 임대료 (1.13~2.12)-1/24회 | J23: 1 | K23: 6394500 | L23: =J23*K23 -> 6394500 | M23: =L23*10% -> 639450 | N23: =SUM(L23:M23) -> 7033950 | O23: 0 | P23: X | Q23: =L23-O23 -> 6394500 | R23: 완료(2/18) | S23: 정지우
A24: . | B24: S | D24: 45698 | E24: 에이비씨한국 | F24: 서울 | G24: 상품 | H24: 노트북 | I24: LG전자 노트북 15U50S-G.AP7TL 외 | J24: 1 | K24: 1520000 | L24: =J24*K24 -> 1520000 | M24: =L24*10% -> 152000 | N24: =SUM(L24:M24) -> 1672000 | O24: 1490000 | P24: 로보츠(2/10) | Q24: =L24-O24 -> 30000 | R24: 완료(3/31) | S24: 이예지
A25: . | B25: Y250211-01 | D25: 45699 | E25: 한국도자기협회 | G25: 상품 | H25: 탭북 | I25: 삼성전자 갤럭시탭 A9 플러스 Wifi 64GB 그라파이트 | J25: 1 | K25: 300000 | L25: 1230000 | M25: =L25*10% -> 123000 | N25: =SUM(L25:M25) -> 1353000 | O25: 1066273 | P25: 쿠팡(2/10법카) | Q25: =L25-O25 -> 163727 | R25: 완료(2/12) | S25: 홍승민
A26: . | E26: 한국도자기협회 | G26: 상품 | H26: 탭북 | I26: 아이패드 10세대 Wifi 64GB 실버 | J26: 1 | K26: 480000
A27: . | E27: 한국도자기협회 | G27: 상품 | H27: 탭북 | I27: Tab P12 QHD 8GB / 128GB 스톰그레이 | J27: 1 | K27: 290000
A28: . | E28: 한국도자기협회 | G28: 상품 | H28: 탭북 | I28: 아이뮤즈 뮤패드 K10 PLUS 태블릿PC RAM 4GB Wifi 64GB | J28: 1 | K28: 160000
A29: . | B29: 품의X | D29: 45700 | E29: 블루포트 | G29: MA | H29: 기술지원 | I29: Windows Server 2022 OS설치 및 드라이버 설치 기술지원료 | J29: 1 | K29: 500000 | L29: =J29*K29 -> 500000 | M29: =L29*10% -> 50000 | N29: =SUM(L29:M29) -> 550000 | O29: 0 | P29: SM | Q29: =L29-O29 -> 500000 | R29: 완료(4/30) | S29: 이지훈
A30: . | B30: SB-25011 | C30: ZJREZL | D30: 45700 | E30: 이룸에스앤앤 | F30: 코리아미카사 | G30: MA | H30: 월간-레노버 | I30: 연간유지정비료(24.1.20~26.1.19) | J30: 1 | K30: 1800000 | L30: =J30*K30 -> 1800000 | M30: =L30*10% -> 180000 | N30: =SUM(L30:M30) -> 1980000 | O30: =65700*24 -> 1576800 | P30: 레노버 월 65,700 24.01 (2/10) 24,090 24.2~25.1 (25/2/10) 65,700*12 (2/28)(3/31)(4/30)(5/31)(6/30)(7/31)(8/31)(9/30)(10/31)(11/30)(12/31)(26/1/ ) | Q30: =L30-O30 -> 223200 | R30: 완료(4/29) | S30: 천범석
A31: . | B31: S | D31: 45700 | E31: 왕길토건 | F31: 검단미플존 317호 | G31: 건물임대 | H31: 임대료 | I31: 1월 임대료(25/1/11~2/10) - 4/10회 | J31: 1 | K31: 400000 | L31: =J31*K31 -> 400000 | M31: =L31*10% -> 40000 | N31: =SUM(L31:M31) -> 440000 | O31: 0 | P31: X | Q31: =L31-O31 -> 400000 | R31: 완료(2/12) | S31: 정지우
A32: . | B32: H250204-01 | D32: 45700 | E32: 영화시스템 | F32: CGV계양 | G32: 상품 | H32: 기술지원 | I32: CGV계양 OS 재설치 | J32: 1 | K32: 300000 | L32: =J32*K32 -> 300000 | M32: =L32*10% -> 30000 | N32: =SUM(L32:M32) -> 330000 | O32: 0 | P32: SM | Q32: =L32-O32 -> 300000 | R32: 완료(3/14) | S32: 천범석
A33: . | B33: D250121-01 | D33: 45701 | E33: 고영 | G33: 상품 | H33: CPU | I33: E5-2470V2 10Core 2.4GHz 외 | J33: 1 | K33: 770000 | L33: =J33*K33 -> 770000 | M33: =L33*10% -> 77000 | N33: =SUM(L33:M33) -> 847000 | O33: =90000+6*40000 -> 330000 | P33: 위퍼스트(1/22) 90,000 이비웨이브(1/20) 6*40,000 SM | Q33: =L33-O33 -> 440000 | R33: 완료(3/11) | S33: 이지훈
A34: . | B34: D250121-02 | D34: 45701 | E34: 고영 | G34: 상품 | H34: 조립PC | I34: 조립PC | J34: 1 | K34: 6500000 | L34: =J34*K34 -> 6500000 | M34: =L34*10% -> 650000 | N34: =SUM(L34:M34) -> 7150000 | O34: =6212655+45000+55000+45000 -> 6357655 | P34: 컴퓨존(1/22) 우림퀵(2/28) 45,000 45,000 55,000 | Q34: =L34-O34 -> 142345 | R34: 완료(3/14) | S34: 이지훈
A35: . | B35: H250214-01 | D35: 45702 | E35: 준아이앤씨 | F35: 흥국화재 | G35: 상품 | H35: 00YK025 | I35: ThinkSystem 2.5" 1TB 7.2K SATA 6Gb Hot Swap 512n HDD | J35: 1 | K35: 510000 | L35: =J35*K35 -> 510000 | M35: =L35*10% -> 51000 | N35: =SUM(L35:M35) -> 561000 | O35: 455000 | P35: 레노버(4/4) | Q35: =L35-O35 -> 55000 | R35: 완료(2/28) | S35: 천범석
A36: . | B36: S | D36: 45703 | E36: 순환 | F36: 검단미플존 318호 | G36: 건물임대 | H36: 임대료 | I36: 2월 임대료(25/1/20~25/2/19) - 4/9회 | J36: 1 | K36: 346500 | L36: =J36*K36 -> 346500 | M36: =L36*10% -> 34650 | N36: =SUM(L36:M36) -> 381150 | O36: 0 | P36: X | Q36: =L36-O36 -> 346500 | R36: 완료(2/24) | S36: 정지우
A37: . | B37: SB-24011 | C37: Z5PURB | D37: 45703 | E37: 비온시이노베이터 | F37: 국립농업과학원 | G37: MA | H37: 월간-레노버 | I37: 1월 유지정비료 - 13/24회 | J37: 1 | K37: 875000 | L37: =J37*K37 -> 875000 | M37: =L37*10% -> 87500 | N37: =SUM(L37:M37) -> 962500 | O37: =511500+3400000/12 -> 794833.33 | P37: 레노버(1/31)511,500 시스나인(4/25) 연간3,400,000(1/12회) | Q37: =L37-O37 -> 80166.667 | R37: 완료(2/10)선입금 | S37: 천범석
A38: . | B38: SB-24009 | C38: Z0PYQC | D38: 45703 | E38: 유알피 | F38: 서울디자인재단 | G38: MA | H38: 월간-레노버 | I38: 1월 유지정비료 - 13/36회 | J38: 1 | K38: 1080000 | L38: =J38*K38 -> 1080000 | M38: =L38*10% -> 108000 | N38: =SUM(L38:M38) -> 1188000 | O38: 976200 | P38: 레노버(1/31) | Q38: =L38-O38 -> 103800 | R38: 완료(3/17) | S38: 천범석
A39: . | B39: Y240830-03 | D39: 45706 | E39: 스마트웨어 | F39: 세연시스템즈 | G39: 장비임대 | H39: 서버임대 | I39: X3650M5 임대 (Xeon E5-2640v3 2.6GHz 8C x2 / 128GB Memory / 600GB SAS x4 / Power x2)(25/1/2~25/2/1) | J39: 1 | K39: 200000 | L39: =J39*K39 -> 200000 | M39: =L39*10% -> 20000 | N39: =SUM(L39:M39) -> 220000 | O39: 0 | P39: 재고 | Q39: =L39-O39 -> 200000 | R39: 3월말 | S39: 홍승민
A40: . | B40: H250213-02 | D40: 45706 | E40: 브리토바코 | F40: BAT사천 | G40: 상품 | H40: USB Blocker | I40: [LINDY] 보안 커텍터, 추가구매용 USB 블록, LINDY-40460 10개 [레드/5 SET] / LINDY-40463 [오렌지/21 SET] | J40: 26 | K40: 33000 | L40: =J40*K40 -> 858000 | M40: =L40*10% -> 85800 | N40: =SUM(L40:M40) -> 943800 | O40: 702945 | P40: 컴퓨존(1/13) | Q40: =L40-O40 -> 155055 | R40: 완료(4/23) | S40: 천범석
...

Sheet 3월
B1: ="["&YEAR(D3)&"년 "&MONTH(D3)&"월 매출]" -> [2025년 3월 매출]
B2: 품의코드 | C2: Vendor 코드 | D2: 날짜 | E2: 매출처 | F2: END-USER | G2: 구분 | H2: MA : 청구구분 상품 : PN | I2: 거래내용 | J2: 수량 | K2: 단가 | L2: 공급가액 | M2: 부가세 | N2: 공급가합계 | O2: 매입액 | P2: 매입거래처 | Q2: GP | R2: 입금일 | S2: 영업 담당자 | T2: 비고
A3: . | B3: SM-23015 | D3: 45717 | E3: 동원프라스틱 | F3: 동원프라스틱 | G3: MA | H3: 월간 | I3: 3월 유지정비료 - 12/13회 | J3: 1 | K3: 1200000 | L3: =J3*K3 -> 1200000 | M3: =L3*10% -> 120000 | N3: =SUM(L3:M3) -> 1320000 | O3: =4800000/6 -> 800000 | P3: 시스나인(25/3/4) 4,800,000 3/6회 | Q3: =L3-O3 -> 400000 | R3: 완료(3/31) | S3: 이예지
A4: . | B4: IK-23016 | D4: 45717 | E4: 케이정보기술 | F4: 청주시청 | G4: MA | H4: 월간-IBM | I4: 3월 유지정비료 - 19/35회 | J4: 1 | K4: 1600000 | L4: =J4*K4 -> 1600000 | M4: =L4*10% -> 160000 | N4: =SUM(L4:M4) -> 1760000 | O4: =1123962+259896 -> 1383858 | P4: IBM(3/4) 1,123,962 (3/4) 259,896 | Q4: =L4-O4 -> 216142 | R4: 완료(4/30) | S4: 천범석
A5: . | B5: SM-24011 | D5: 45717 | E5: 가나병원 | G5: MA | H5: 월간 | I5: 3월 유지정비료 - 11/12회 | J5: 1 | K5: 300000 | L5: =J5*K5 -> 300000 | M5: =L5*10% -> 30000 | N5: =SUM(L5:M5) -> 330000 | O5: 0 | P5: SM | Q5: =L5-O5 -> 300000 | R5: 완료(3/13) | S5: 천범석
