Workbook

Sheet Master
B1: 품의코드 | C1: Vendor 코드 | D1: 계산서 | E1: 매입처 | F1: 매출처 | G1: 구분 | H1: MA : 청구구분 상품 : PN | I1: 품목 | J1: 수량 | K1: 단가 | L1: 공금가액 | M1: VAT | N1: 합계금액 | O1: 결제 | P1: 영업 담당자 | Q1: 매출처 세금계산서 | R1: 비고
A2: . | B2: ='1월'!B5 -> X | D2: ='1월'!D5 -> 45658 | E2: ='1월'!E5 -> 에스케이쉴더스 금천지점 | G2: ='1월'!G5 -> 일반경비 | H2: ='1월'!H5 -> 지급수수료 | I2: ='1월'!I5 -> 보안용역 월정료 1월분 | J2: ='1월'!J5 -> 1 | K2: ='1월'!K5 -> 71000 | L2: ='1월'!L5 -> 71000 | M2: ='1월'!M5 -> 7100 | N2: ='1월'!N5 -> 78100 | ... Q2: ='1월'!Q5 -> X
A3: . | B3: ='1월'!B6 -> LI-24005 | D3: ='1월'!D6 -> 45658 | E3: ='1월'!E6 -> 한국아이씨에스 | F3: ='1월'!F6 -> 해안종합건축사사무소 | G3: ='1월'!G6 -> MA | H3: ='1월'!H6 -> 월간-IBM | I3: ='1월'!I6 -> 1월 유지정비료 - 8/12회 | J3: ='1월'!J6 -> 1 | K3: ='1월'!K6 -> 436400 | ... Q3: ='1월'!Q6 -> 45658
A4: . | B4: ='1월'!B7 -> SM-24007 | D4: ='1월'!D7 -> 45658 | E4: ='1월'!E7 -> 한국아이씨에스 | F4: ='1월'!F7 -> 연세의료원 | G4: ='1월'!G7 -> MA | H4: ='1월'!H7 -> 월간-IBM | I4: ='1월'!I7 -> 1월 유지정비료 - 12/12회 | J4: ='1월'!J7 -> 1 | K4: ='1월'!K7 -> 288000 | ... Q4: ='1월'!Q7 -> 45677
A5: . | B5: ='1월'!B8 -> LI-24006 | D5: ='1월'!D8 -> 45658 | E5: ='1월'!E8 -> 한국아이씨에스 | F5: ='1월'!F8 -> 보해양조 | G5: ='1월'!G8 -> MA | H5: ='1월'!H8 -> 월간-IBM | I5: ='1월'!I8 -> 1월 유지정비료 - 6/11회 | J5: ='1월'!J8 -> 1 | K5: ='1월'!K8 -> 277600 | ... Q5: ='1월'!Q8 -> 45682
A6: . | B6: ='1월'!B9 -> IK-24006 | D6: ='1월'!D9 -> 45659 | E6: ='1월'!E9 -> 한국아이씨에스 | F6: ='1월'!F9 -> 광양항서부터미널 | G6: ='1월'!G9 -> MA | H6: ='1월'!H9 -> 월간-IBM | I6: ='1월'!I9 -> 1월 유지정비료 - 9/24회 | J6: ='1월'!J9 -> 1 | K6: ='1월'!K9 -> 3239404 | ... Q6: ='1월'!Q9 -> 45688
A7: . | B7: ='1월'!B10 -> LI-24008 | D7: ='1월'!D10 -> 45659 | E7: ='1월'!E10 -> 한국아이씨에스 | F7: ='1월'!F10 -> 쿠팡 | G7: ='1월'!G10 -> MA | H7: ='1월'!H10 -> 월간-IBM | I7: ='1월'!I10 -> 1월 유지정비료 - 6/13회 | J7: ='1월'!J10 -> 1 | K7: ='1월'!K10 -> 205780 | ... R7: ='1월'!R10 -> 매출연간
A8: . | B8: ='1월'!B11 -> LI-24003 | D8: ='1월'!D11 -> 45659 | E8: ='1월'!E11 -> 한국아이씨에스 | F8: ='1월'!F11 -> 지엔콤 | G8: ='1월'!G11 -> MA | H8: ='1월'!H11 -> 월간-IBM | I8: ='1월'!I11 -> 전주교육대학교 1월 유지정비료 - 9/12회 | J8: ='1월'!J11 -> 1 | K8: ='1월'!K11 -> 305280 | ... Q8: ='1월'!Q11 -> 45688
A9: . | B9: ='1월'!B12 -> IK-23021 | D9: ='1월'!D12 -> 45659 | E9: ='1월'!E12 -> 한국아이씨에스 | F9: ='1월'!F12 -> 투아이시스 | G9: ='1월'!G12 -> MA | H9: ='1월'!H12 -> 월간-IBM | I9: ='1월'!I12 -> 1월 유지정비료 - 11/12회 | J9: ='1월'!J12 -> 1 | K9: ='1월'!K12 -> 93445 | ... R9: ='1월'!R12 -> 매출연간
A10: . | B10: ='1월'!B13 -> SM-25003 | D10: ='1월'!D13 -> 45659 | E10: ='1월'!E13 -> 한국아이씨에스 | F10: ='1월'!F13 -> CGV 통합 | G10: ='1월'!G13 -> MA | H10: ='1월'!H13 -> 월간-IBM | I10: ='1월'!I13 -> 1월 유지정비료 - 1/12회 | J10: ='1월'!J13 -> 1 | K10: ='1월'!K13 -> 2812500 | ... R10: ='1월'!R13 -> 매출연간
A11: . | B11: ='1월'!B14 -> IK-23016 | D11: ='1월'!D14 -> 45659 | E11: ='1월'!E14 -> 한국아이씨에스 | F11: ='1월'!F14 -> 케이정보기술 | G11: ='1월'!G14 -> MA | H11: ='1월'!H14 -> 월간-IBM | I11: ='1월'!I14 -> 청주시청 1월 유지정비료 - 1/20회 추가 | J11: ='1월'!J14 -> 1 | K11: ='1월'!K14 -> 1123962 | ... Q11: ='1월'!Q14 -> 45658
A12: . | B12: ='1월'!B15 -> IK-22025 | D12: ='1월'!D15 -> 45659 | E12: ='1월'!E15 -> 한국아이씨에스 | F12: ='1월'!F15 -> 디에스피 | G12: ='1월'!G15 -> MA | H12: ='1월'!H15 -> 월간-IBM | I12: ='1월'!I15 -> 엘지생활건강 청주공장 1월 유지정비료 - 12/12회 | J12: ='1월'!J15 -> 1 | K12: ='1월'!K15 -> 532212 | ... Q12: ='1월'!Q15 -> 45658
A13: . | B13: ='1월'!B16 -> IK-23013 | D13: ='1월'!D16 -> 45659 | E13: ='1월'!E16 -> 한국아이씨에스 | F13: ='1월'!F16 -> 로보츠 | G13: ='1월'!G16 -> MA | H13: ='1월'!H16 -> 월간-IBM | I13: ='1월'!I16 -> 도시바일렉 1월 유지정비료 - 7/12회 | J13: ='1월'!J16 -> 1 | K13: ='1월'!K16 -> 66498 | ... Q13: ='1월'!Q16 -> 45688
A14: . | B14: ='1월'!B17 -> LI-24007 | D14: ='1월'!D17 -> 45659 | E14: ='1월'!E17 -> 한국아이씨에스 | F14: ='1월'!F17 -> 유더블유에스 | G14: ='1월'!G17 -> MA | H14: ='1월'!H17 -> 월간-IBM | I14: ='1월'!I17 -> 두원정공 1월 유지정비료 - 6/11회 | J14: ='1월'!J17 -> 1 | K14: ='1월'!K17 -> 80160 | ... Q14: ='1월'!Q17 -> 45688
A15: . | B15: ='1월'!B18 -> IK-23014 | D15: ='1월'!D18 -> 45659 | E15: ='1월'!E18 -> 한국아이씨에스 | F15: ='1월'!F18 -> 서비스링크 | G15: ='1월'!G18 -> MA | H15: ='1월'!H18 -> 월간-IBM | I15: ='1월'!I18 -> 세원정공 1월 유지정비료 - 7/12회 | J15: ='1월'!J18 -> 1 | K15: ='1월'!K18 -> 198018 | ... Q15: ='1월'!Q18 -> 45658
A16: . | B16: ='1월'!B19 -> SM-21021 | D16: ='1월'!D19 -> 45659 | E16: ='1월'!E19 -> 한국아이씨에스 | F16: ='1월'!F19 -> 법무법인바른 | G16: ='1월'!G19 -> MA | H16: ='1월'!H19 -> 월간-IBM | I16: ='1월'!I19 -> 1월 유지정비료 - 5/13회 | J16: ='1월'!J19 -> 1 | K16: ='1월'!K19 -> 84811 | ... Q16: ='1월'!Q19 -> 45682
A17: . | B17: ='1월'!B20 -> IK-24011 | D17: ='1월'!D20 -> 45659 | E17: ='1월'!E20 -> 한국아이씨에스 | F17: ='1월'!F20 -> 로보츠 | G17: ='1월'!G20 -> MA | H17: ='1월'!H20 -> 월간-IBM | I17: ='1월'!I20 -> 키오시아(도시바) 1월 유지정비료 - 2/12회 | J17: ='1월'!J20 -> 1 | K17: ='1월'!K20 -> 133875 | ... Q17: ='1월'!Q20 -> 45688
A18: . | B18: ='1월'!B21 -> SM-25011 | D18: ='1월'!D21 -> 45659 | E18: ='1월'!E21 -> 한국아이씨에스 | F18: ='1월'!F21 -> 유니포인트 | G18: ='1월'!G21 -> MA | H18: ='1월'!H21 -> 월간-IBM | I18: ='1월'!I21 -> 한미약품/한미사이언스 1월 유지정비료 - 1/12회 | J18: ='1월'!J21 -> 1 | K18: ='1월'!K21 -> 11623397 | ... Q18: ='1월'!Q21 -> 45681
A19: . | B19: ='1월'!B22 -> IK-24002 | D19: ='1월'!D22 -> 45659 | E19: ='1월'!E22 -> 한국아이씨에스 | F19: ='1월'!F22 -> 리온아이티 | G19: ='1월'!G22 -> MA | H19: ='1월'!H22 -> 월간-IBM | I19: ='1월'!I22 -> 교세라 1월 유지정비료 - 12/36회 | J19: ='1월'!J22 -> 1 | K19: ='1월'!K22 -> 70422 | ... Q19: ='1월'!Q22 -> 45688
A20: . | B20: ='1월'!B23 -> SM-24021 | D20: ='1월'!D23 -> 45659 | E20: ='1월'!E23 -> 한국아이씨에스 | F20: ='1월'!F23 -> 에이캐피탈 | G20: ='1월'!G23 -> MA | H20: ='1월'!H23 -> 월간-IBM | I20: ='1월'!I23 -> 1월 유지정비료 - 5/12회 | J20: ='1월'!J23 -> 1 | K20: ='1월'!K23 -> 691782 | ... Q20: ='1월'!Q23 -> 45693
A21: . | B21: ='1월'!B24 -> LI-24004 | D21: ='1월'!D24 -> 45659 | E21: ='1월'!E24 -> 한국아이씨에스 | F21: ='1월'!F24 -> 한국메탈 | G21: ='1월'!G24 -> MA | H21: ='1월'!H24 -> 월간-IBM | I21: ='1월'!I24 -> 1월유지정비료 - 9/32회 | J21: ='1월'!J24 -> 1 | K21: ='1월'!K24 -> 316682 | ... Q21: ='1월'!Q24 -> 45658
A22: . | B22: ='1월'!B25 -> SB-24036 | D22: ='1월'!D25 -> 45659 | E22: ='1월'!E25 -> 한국아이씨에스 | F22: ='1월'!F25 -> 나라정보 | G22: ='1월'!G25 -> MA | H22: ='1월'!H25 -> 월간-IBM | I22: ='1월'!I25 -> 부국철강 1월 유지정비료 - 9/32 회 | J22: ='1월'!J25 -> 1 | K22: ='1월'!K25 -> 190849 | ... Q22: ='1월'!Q25 -> 45688
A23: . | B23: ='1월'!B26 -> LI-24009 | D23: ='1월'!D26 -> 45659 | E23: ='1월'!E26 -> 한국아이씨에스 | F23: ='1월'!F26 -> 아이리스인포테크 | G23: ='1월'!G26 -> MA | H23: ='1월'!H26 -> 월간-IBM | I23: ='1월'!I26 -> 프레이저플레이스 1월 유지정비료 - 6/12회 | J23: ='1월'!J26 -> 1 | K23: ='1월'!K26 -> 95200 | ... R23: ='1월'!R26 -> 매출분기
A24: . | B24: ='1월'!B27 -> IK-24014 | D24: ='1월'!D27 -> 45659 | E24: ='1월'!E27 -> 한국아이씨에스 | F24: ='1월'!F27 -> 로보츠 | G24: ='1월'!G27 -> MA | H24: ='1월'!H27 -> 월간-IBM | I24: ='1월'!I27 -> 와이케이케이 1월 유지정비료 - 1/12회 | J24: ='1월'!J27 -> 1 | K24: ='1월'!K27 -> 79496 | ... Q24: ='1월'!Q27 -> 45682
A25: . | B25: ='1월'!B28 -> IK-22023 | D25: ='1월'!D28 -> 45659 | E25: ='1월'!E28 -> 한국아이씨에스 | F25: ='1월'!F28 -> 리온아이티 | G25: ='1월'!G28 -> MA | H25: ='1월'!H28 -> 월간-IBM | I25: ='1월'!I28 -> 성원제강 1월 유지정비료 - 22/36회 | J25: ='1월'!J28 -> 1 | K25: ='1월'!K28 -> 159761 | ... Q25: ='1월'!Q28 -> 45688
A26: . | B26: ='1월'!B29 -> LI-24006 | D26: ='1월'!D29 -> 45659 | E26: ='1월'!E29 -> 한국아이씨에스 | F26: ='1월'!F29 -> 보해양조 | G26: ='1월'!G29 -> MA | H26: ='1월'!H29 -> 월간-IBM | I26: ='1월'!I29 -> 1월 유지정비료 - 7/12회 | J26: ='1월'!J29 -> 1 | K26: ='1월'!K29 -> 142800 | ... Q26: ='1월'!Q29 -> 45682
A27: . | B27: ='1월'!B30 -> IK-24005 | D27: ='1월'!D30 -> 45659 | E27: ='1월'!E30 -> 한국아이씨에스 | F27: ='1월'!F30 -> 엔콤 | G27: ='1월'!G30 -> MA | H27: ='1월'!H30 -> 월간-IBM | I27: ='1월'!I30 -> 전북도시가스 1월 유지정비료 - 10/12회 | J27: ='1월'!J30 -> 1 | K27: ='1월'!K30 -> 1263250 | ... Q27: ='1월'!Q30 -> 45688
A28: . | B28: ='1월'!B31 -> IK-22022 | D28: ='1월'!D31 -> 45659 | E28: ='1월'!E31 -> 한국아이씨에스 | F28: ='1월'!F31 -> 리온아이티 | G28: ='1월'!G31 -> MA | H28: ='1월'!H31 -> 월간-IBM | I28: ='1월'!I31 -> 한일전기 1월 유지정비료 - 25/36회 | J28: ='1월'!J31 -> 1 | K28: ='1월'!K31 -> 309047 | ... R28: ='1월'!R31 -> 매출분기
A29: . | B29: ='1월'!B32 -> IK-24013 | D29: ='1월'!D32 -> 45659 | E29: ='1월'!E32 -> 한국아이씨에스 | F29: ='1월'!F32 -> 레드텍 | G29: ='1월'!G32 -> MA | H29: ='1월'!H32 -> 월간-IBM | I29: ='1월'!I32 -> 대한상공회의소 1월 유지정비료 - 3/12회 | J29: ='1월'!J32 -> 1 | K29: ='1월'!K32 -> 94111 | ... Q29: ='1월'!Q32 -> 45658
A30: . | B30: ='1월'!B33 -> IK-22021 | D30: ='1월'!D33 -> 45659 | E30: ='1월'!E33 -> 한국아이씨에스 | F30: ='1월'!F33 -> 리온아이티 | G30: ='1월'!G33 -> MA | H30: ='1월'!H33 -> 월간-IBM | I30: ='1월'!I33 -> 문배철강 1월 유지정비료 - 22/36회 | J30: ='1월'!J33 -> 1 | K30: ='1월'!K33 -> 212293 | ... Q30: ='1월'!Q33 -> 45688
A31: . | B31: ='1월'!B34 -> Y241205-01 | D31: ='1월'!D34 -> 45659 | E31: ='1월'!E34 -> 컴퓨존 | F31: ='1월'!F34 -> 삼표피앤씨 | G31: ='1월'!G34 -> 상품 | H31: ='1월'!H34 -> 랜카드 | I31: ='1월'!I34 -> ipTIME U1000 PLUS 유선랜카드 | J31: ='1월'!J34 -> 1 | K31: ='1월'!K34 -> 13545 | ... Q31: ='1월'!Q34 -> 45649
A32: . | B32: ='1월'!B35 -> SM-25010 | D32: ='1월'!D35 -> 45659 | E32: ='1월'!E35 -> 프로미스 | F32: ='1월'!F35 -> 유니포인트 | G32: ='1월'!G35 -> MA | H32: ='1월'!H35 -> 분기 | I32: ='1월'!I35 -> 한미약품, 한미사이언스 유지보수 25년 1Q | J32: ='1월'!J35 -> 1 | K32: ='1월'!K35 -> 8000000 | ... Q32: ='1월'!Q35 -> 45688
A33: . | B33: ='1월'!B36 -> Y241209-03 | D33: ='1월'!D36 -> 45659 | E33: ='1월'!E36 -> 프로미스 | F33: ='1월'!F36 -> 더힘 | G33: ='1월'!G36 -> 상품 | H33: ='1월'!H36 -> 기술지원 | I33: ='1월'!I36 -> 우물단 TR630 설치지원 | J33: ='1월'!J36 -> 1 | K33: ='1월'!K36 -> 3000000 | ... Q33: ='1월'!Q36 -> 45645
A34: . | B34: ='1월'!B37 -> S | D34: ='1월'!D37 -> 45659 | E34: ='1월'!E37 -> 프로미스 | F34: ='1월'!F37 -> 티엔플러스 | G34: ='1월'!G37 -> 상품 | H34: ='1월'!H37 -> 기술지원 | I34: ='1월'!I37 -> 계양 복지센터 케이코 설치지원 | J34: ='1월'!J37 -> 1 | K34: ='1월'!K37 -> 800000 | ... Q34: ='1월'!Q37 -> 45650
A35: . | B35: ='1월'!B38 -> S241223 | D35: ='1월'!D38 -> 45659 | E35: ='1월'!E38 -> 프로미스 | F35: ='1월'!F38 -> 다솜테크 | G35: ='1월'!G38 -> 상품 | H35: ='1월'!H38 -> 기술지원 | I35: ='1월'!I38 -> SSD 설치지원 | J35: ='1월'!J38 -> 1 | K35: ='1월'!K38 -> 1700000 | ... Q35: ='1월'!Q38 -> 45657
A36: . | B36: ='1월'!B39 -> SB-24011 | D36: ='1월'!D39 -> 45659 | E36: ='1월'!E39 -> 프로미스 | F36: ='1월'!F39 -> 비온시 | G36: ='1월'!G39 -> MA | H36: ='1월'!H39 -> 연간 | I36: ='1월'!I39 -> 24년 국립농업과학원 기술지원 | J36: ='1월'!J39 -> 1 | K36: ='1월'!K39 -> 3400000 | ... Q36: ='1월'!Q39 -> 24/2/15~25/1/15
A37: . | B37: ='1월'!B40 -> SB-24063 | D37: ='1월'!D40 -> 45659 | E37: ='1월'!E40 -> 프로미스 | F37: ='1월'!F40 -> 다솜테크 | G37: ='1월'!G40 -> MA | H37: ='1월'!H40 -> 연간 | I37: ='1월'!I40 -> E1컨테이너터미널 기술지원비 | J37: ='1월'!J40 -> 1 | K37: ='1월'!K40 -> 1000000 | ... Q37: ='1월'!Q40 -> 1/31~12/31
A38: . | B38: ='1월'!B41 -> SM-25001 | D38: ='1월'!D41 -> 45659 | E38: ='1월'!E41 -> 프로미스 | F38: ='1월'!F41 -> 로스만스/브리티쉬 | G38: ='1월'!G41 -> MA | H38: ='1월'!H41 -> 연간 | I38: ='1월'!I41 -> BAT 서울 사천 연간 기술지원 | J38: ='1월'!J41 -> 1 | K38: ='1월'!K41 -> 2500000 | ... Q38: ='1월'!Q41 -> 1/31~12/31
A39: . | B39: ='1월'!B42 -> S | D39: ='1월'!D42 -> 45659 | E39: ='1월'!E42 -> 프로미스 | F39: ='1월'!F42 -> 매사 | G39: ='1월'!G42 -> 상품 | H39: ='1월'!H42 -> Battery | I39: ='1월'!I42 -> FS8600 CTRL Battery | J39: ='1월'!J42 -> 1 | K39: ='1월'!K42 -> 550000 | ... Q39: ='1월'!Q42 -> 45596
A40: . | B40: ='1월'!B43 -> H240426-02 | D40: ='1월'!D43 -> 45659 | E40: ='1월'!E43 -> 프로미스 | F40: ='1월'!F43 -> 에스엔정보 | G40: ='1월'!G43 -> 상품 | H40: ='1월'!H43 -> 9RZ268-150 | I40: ='1월'!I43 -> 1TB 7.2K 6G SFF SAS | J40: ='1월'!J43 -> 1 | K40: ='1월'!K43 -> 130000 | ... Q40: ='1월'!Q43 -> 45408
...

Sheet 분류
A2: [월별매입] | B2: 공급가액 | C2: 부가세 | D2: 합계 | E2: 건수
A3: 1월 | B3: ='1월'!L207 -> 2.4799697e+08 | C3: ='1월'!M207 -> 24614207 | D3: ='1월'!N207 -> 2.7261117e+08 | E3: ='1월'!D208 -> 197
A4: 2월 | B4: ='2월'!L230 -> 258840954 | C4: ='2월'!M230 -> 25695538 | D4: ='2월'!N230 -> 2.8453649e+08 | E4: ='2월'!D231 -> 212
A5: 3월 | B5: ='3월'!L210 -> 3.6678925e+08 | C5: ='3월'!M210 -> 36493122 | D5: ='3월'!N210 -> 4.0328237e+08 | E5: ='3월'!D211 -> 194
A6: 4월 | B6: ='4월'!L212 -> 2.641991e+08 | C6: ='4월'!M212 -> 26235927 | D6: ='4월'!N212 -> 2.9043502e+08 | E6: ='4월'!D213 -> 192
A7: 5월 | B7: ='5월'!L213 -> 198025977 | C7: ='5월'!M213 -> 19776997 | D7: ='5월'!N213 -> 2.1780297e+08 | E7: ='5월'!D214 -> 192
A8: 6월 | B8: ='6월'!L215 -> 2.438904e+08 | C8: ='6월'!M215 -> 24372496 | D8: ='6월'!N215 -> 2.682629e+08 | E8: ='6월'!D216 -> 188
A9: 7월
A10: 8월
A11: 9월
A12: 10월
A13: 11월
A14: 12월
A15: 계산서합 | B15: =SUM(B3:B14) -> 1.5797426e+09 | C15: =SUM(C3:C14) -> 1.5718829e+08 | D15: =SUM(D3:D14) -> 1.7369309e+09 | E15: =SUM(E3:E14) -> 1175
A16: 카드/현금 | B16: ='현금,법인카드'!L50 -> 5387063.8 | C16: ='현금,법인카드'!M50 -> 538706.68 | D16: ='현금,법인카드'!N50 -> 5925770.5 | E16: ='현금,법인카드'!D50 -> 15
A17: 수입 | B17: =수입!I11 -> 0 | C17: 0 | D17: =수입!I11 -> 0 | E17: =수입!B11 -> 0
A18: 연간매입 | B18: =SUM(B15,B16,B17) -> 1.5851297e+09 | C18: =SUM(C15,C16,C17) -> 1.5772699e+08 | D18: =SUM(D15,D16,D17) -> 1.7428567e+09 | E18: =SUM(E15,E16,E17) -> 1190
A21: Rank | B21: [업체별 매입] | C21: 합계 | D21: 상품 | E21: MA | F21: MAPAC | G21: WSU | H21: 장비임대 | I21: 일반경비 | J21: 수입부가세 | K21: 건물매매 | L21: 건물관리 | N21: 오류체크 | O21: 오류차
C22: =SUM(C23:C117) -> 1.5851297e+09 | D22: =SUM(D23:D117) -> 3.5458721e+08 | E22: =SUM(E23:E117) -> 9.2926106e+08 | F22: =SUM(F23:F117) -> 119391693 | G22: =SUM(G23:G117) -> 36546921 | H22: =SUM(H23:H117) -> 930000 | I22: =SUM(I23:I117) -> 144412828 | J22: =SUM(J23:J117) -> 0 | ... L22: =SUM(L23:L117) -> 0 | N22: =IF(B18=C22,"OK","F") -> OK | O22: =B18-C22 -> 0
A23: =RANK(C23,$C$23:$C$115,0) -> 65 | B23: 가양역더리브아너비즈타워 | C23: =SUM(D23:L23) -> 0 | D23: =SUMIFS(Master!$L$2:$L$1254,Master!$G$2:$G$1254,분류!D$21,Master!$E$2:$E$1254,분류!$B23) -> 0 | E23: =SUMIFS(Master!$L$2:$L$1254,Master!$G$2:$G$1254,분류!E$21,Master!$E$2:$E$1254,분류!$B23) -> 0 | F23: =SUMIFS(Master!$L$2:$L$1254,Master!$G$2:$G$1254,분류!F$21,Master!$E$2:$E$1254,분류!$B23) -> 0 | G23: =SUMIFS(Master!$L$2:$L$1254,Master!$G$2:$G$1254,분류!G$21,Master!$E$2:$E$1254,분류!$B23) -> 0 | H23: =SUMIFS(Master!$L$2:$L$1254,Master!$G$2:$G$1254,분류!H$21,Master!$E$2:$E$1254,분류!$B23) -> 0 | I23: =SUMIFS(Master!$L$2:$L$1254,Master!$G$2:$G$1254,분류!I$21,Master!$E$2:$E$1254,분류!$B23) -> 0 | J23: =SUMIFS(Master!$L$2:$L$1254,Master!$G$2:$G$1254,분류!J$21,Master!$E$2:$E$1254,분류!$B23) -> 0 | K23: =SUMIFS(Master!$L$2:$L$1254,Master!$G$2:$G$1254,분류!K$21,Master!$E$2:$E$1254,분류!$B23) -> 0 | L23: =SUMIFS(Master!$L$2:$L$1254,Master!$G$2:$G$1254,분류!L$21,Master!$E$2:$E$1254,분류!$B23) -> 0
A24: =RANK(C24,$C$23:$C$115,0) -> 57 | B24: 광명역자이타워관리단 | C24: =SUM(D24:L24) -> 260610 | D24: =SUMIFS(Master!$L$2:$L$1254,Master!$G$2:$G$1254,분류!D$21,Master!$E$2:$E$1254,분류!$B24) -> 0 | E24: =SUMIFS(Master!$L$2:$L$1254,Master!$G$2:$G$1254,분류!E$21,Master!$E$2:$E$1254,분류!$B24) -> 0 | F24: =SUMIFS(Master!$L$2:$L$1254,Master!$G$2:$G$1254,분류!F$21,Master!$E$2:$E$1254,분류!$B24) -> 0 | G24: =SUMIFS(Master!$L$2:$L$1254,Master!$G$2:$G$1254,분류!G$21,Master!$E$2:$E$1254,분류!$B24) -> 0 | H24: =SUMIFS(Master!$L$2:$L$1254,Master!$G$2:$G$1254,분류!H$21,Master!$E$2:$E$1254,분류!$B24) -> 0 | I24: =SUMIFS(Master!$L$2:$L$1254,Master!$G$2:$G$1254,분류!I$21,Master!$E$2:$E$1254,분류!$B24) -> 260610 | J24: =SUMIFS(Master!$L$2:$L$1254,Master!$G$2:$G$1254,분류!J$21,Master!$E$2:$E$1254,분류!$B24) -> 0 | K24: =SUMIFS(Master!$L$2:$L$1254,Master!$G$2:$G$1254,분류!K$21,Master!$E$2:$E$1254,분류!$B24) -> 0 | L24: =SUMIFS(Master!$L$2:$L$1254,Master!$G$2:$G$1254,분류!L$21,Master!$E$2:$E$1254,분류!$B24) -> 0
A25: =RANK(C25,$C$23:$C$115,0) -> 58 | B25: 금오이노베이션 | C25: =SUM(D25:L25) -> 240000 | D25: =SUMIFS(Master!$L$2:$L$1254,Master!$G$2:$G$1254,분류!D$21,Master!$E$2:$E$1254,분류!$B25) -> 0 | E25: =SUMIFS(Master!$L$2:$L$1254,Master!$G$2:$G$1254,분류!E$21,Master!$E$2:$E$1254,분류!$B25) -> 0 | F25: =SUMIFS(Master!$L$2:$L$1254,Master!$G$2:$G$1254,분류!F$21,Master!$E$2:$E$1254,분류!$B25) -> 0 | G25: =SUMIFS(Master!$L$2:$L$1254,Master!$G$2:$G$1254,분류!G$21,Master!$E$2:$E$1254,분류!$B25) -> 0 | H25: =SUMIFS(Master!$L$2:$L$1254,Master!$G$2:$G$1254,분류!H$21,Master!$E$2:$E$1254,분류!$B25) -> 0 | I25: =SUMIFS(Master!$L$2:$L$1254,Master!$G$2:$G$1254,분류!I$21,Master!$E$2:$E$1254,분류!$B25) -> 240000 | J25: =SUMIFS(Master!$L$2:$L$1254,Master!$G$2:$G$1254,분류!J$21,Master!$E$2:$E$1254,분류!$B25) -> 0 | K25: =SUMIFS(Master!$L$2:$L$1254,Master!$G$2:$G$1254,분류!K$21,Master!$E$2:$E$1254,분류!$B25) -> 0 | L25: =SUMIFS(Master!$L$2:$L$1254,Master!$G$2:$G$1254,분류!L$21,Master!$E$2:$E$1254,분류!$B25) -> 0
A26: =RANK(C26,$C$23:$C$115,0) -> 65 | B26: 네오프랜드 | C26: =SUM(D26:L26) -> 0 | D26: =SUMIFS(Master!$L$2:$L$1254,Master!$G$2:$G$1254,분류!D$21,Master!$E$2:$E$1254,분류!$B26) -> 0 | E26: =SUMIFS(Master!$L$2:$L$1254,Master!$G$2:$G$1254,분류!E$21,Master!$E$2:$E$1254,분류!$B26) -> 0 | F26: =SUMIFS(Master!$L$2:$L$1254,Master!$G$2:$G$1254,분류!F$21,Master!$E$2:$E$1254,분류!$B26) -> 0 | G26: =SUMIFS(Master!$L$2:$L$1254,Master!$G$2:$G$1254,분류!G$21,Master!$E$2:$E$1254,분류!$B26) -> 0 | H26: =SUMIFS(Master!$L$2:$L$1254,Master!$G$2:$G$1254,분류!H$21,Master!$E$2:$E$1254,분류!$B26) -> 0 | I26: =SUMIFS(Master!$L$2:$L$1254,Master!$G$2:$G$1254,분류!I$21,Master!$E$2:$E$1254,분류!$B26) -> 0 | J26: =SUMIFS(Master!$L$2:$L$1254,Master!$G$2:$G$1254,분류!J$21,Master!$E$2:$E$1254,분류!$B26) -> 0 | K26: =SUMIFS(Master!$L$2:$L$1254,Master!$G$2:$G$1254,분류!K$21,Master!$E$2:$E$1254,분류!$B26) -> 0 | L26: =SUMIFS(Master!$L$2:$L$1254,Master!$G$2:$G$1254,분류!L$21,Master!$E$2:$E$1254,분류!$B26) -> 0
A27: =RANK(C27,$C$23:$C$115,0) -> 8 | B27: 다솜테크 | C27: =SUM(D27:L27) -> 40065000 | D27: =SUMIFS(Master!$L$2:$L$1254,Master!$G$2:$G$1254,분류!D$21,Master!$E$2:$E$1254,분류!$B27) -> 36675000 | E27: =SUMIFS(Master!$L$2:$L$1254,Master!$G$2:$G$1254,분류!E$21,Master!$E$2:$E$1254,분류!$B27) -> 3390000 | F27: =SUMIFS(Master!$L$2:$L$1254,Master!$G$2:$G$1254,분류!F$21,Master!$E$2:$E$1254,분류!$B27) -> 0 | G27: =SUMIFS(Master!$L$2:$L$1254,Master!$G$2:$G$1254,분류!G$21,Master!$E$2:$E$1254,분류!$B27) -> 0 | H27: =SUMIFS(Master!$L$2:$L$1254,Master!$G$2:$G$1254,분류!H$21,Master!$E$2:$E$1254,분류!$B27) -> 0 | I27: =SUMIFS(Master!$L$2:$L$1254,Master!$G$2:$G$1254,분류!I$21,Master!$E$2:$E$1254,분류!$B27) -> 0 | J27: =SUMIFS(Master!$L$2:$L$1254,Master!$G$2:$G$1254,분류!J$21,Master!$E$2:$E$1254,분류!$B27) -> 0 | K27: =SUMIFS(Master!$L$2:$L$1254,Master!$G$2:$G$1254,분류!K$21,Master!$E$2:$E$1254,분류!$B27) -> 0 | L27: =SUMIFS(Master!$L$2:$L$1254,Master!$G$2:$G$1254,분류!L$21,Master!$E$2:$E$1254,분류!$B27) -> 0
A28: =RANK(C28,$C$23:$C$115,0) -> 43 | B28: 다원씨앤에스 | C28: =SUM(D28:L28) -> 1200000 | D28: =SUMIFS(Master!$L$2:$L$1254,Master!$G$2:$G$1254,분류!D$21,Master!$E$2:$E$1254,분류!$B28) -> 0 | E28: =SUMIFS(Master!$L$2:$L$1254,Master!$G$2:$G$1254,분류!E$21,Master!$E$2:$E$1254,분류!$B28) -> 1200000 | F28: =SUMIFS(Master!$L$2:$L$1254,Master!$G$2:$G$1254,분류!F$21,Master!$E$2:$E$1254,분류!$B28) -> 0 | G28: =SUMIFS(Master!$L$2:$L$1254,Master!$G$2:$G$1254,분류!G$21,Master!$E$2:$E$1254,분류!$B28) -> 0 | H28: =SUMIFS(Master!$L$2:$L$1254,Master!$G$2:$G$1254,분류!H$21,Master!$E$2:$E$1254,분류!$B28) -> 0 | I28: =SUMIFS(Master!$L$2:$L$1254,Master!$G$2:$G$1254,분류!I$21,Master!$E$2:$E$1254,분류!$B28) -> 0 | J28: =SUMIFS(Master!$L$2:$L$1254,Master!$G$2:$G$1254,분류!J$21,Master!$E$2:$E$1254,분류!$B28) -> 0 | K28: =SUMIFS(Master!$L$2:$L$1254,Master!$G$2:$G$1254,분류!K$21,Master!$E$2:$E$1254,분류!$B28) -> 0 | L28: =SUMIFS(Master!$L$2:$L$1254,Master!$G$2:$G$1254,분류!L$21,Master!$E$2:$E$1254,분류!$B28) -> 0
A29: =RANK(C29,$C$23:$C$115,0) -> 65 | B29: 단군소프트 | C29: =SUM(D29:L29) -> 0 | D29: =SUMIFS(Master!$L$2:$L$1254,Master!$G$2:$G$1254,분류!D$21,Master!$E$2:$E$1254,분류!$B29) -> 0 | E29: =SUMIFS(Master!$L$2:$L$1254,Master!$G$2:$G$1254,분류!E$21,Master!$E$2:$E$1254,분류!$B29) -> 0 | F29: =SUMIFS(Master!$L$2:$L$1254,Master!$G$2:$G$1254,분류!F$21,Master!$E$2:$E$1254,분류!$B29) -> 0 | G29: =SUMIFS(Master!$L$2:$L$1254,Master!$G$2:$G$1254,분류!G$21,Master!$E$2:$E$1254,분류!$B29) -> 0 | H29: =SUMIFS(Master!$L$2:$L$1254,Master!$G$2:$G$1254,분류!H$21,Master!$E$2:$E$1254,분류!$B29) -> 0 | I29: =SUMIFS(Master!$L$2:$L$1254,Master!$G$2:$G$1254,분류!I$21,Master!$E$2:$E$1254,분류!$B29) -> 0 | J29: =SUMIFS(Master!$L$2:$L$1254,Master!$G$2:$G$1254,분류!J$21,Master!$E$2:$E$1254,분류!$B29) -> 0 | K29: =SUMIFS(Master!$L$2:$L$1254,Master!$G$2:$G$1254,분류!K$21,Master!$E$2:$E$1254,분류!$B29) -> 0 | L29: =SUMIFS(Master!$L$2:$L$1254,Master!$G$2:$G$1254,분류!L$21,Master!$E$2:$E$1254,분류!$B29) -> 0
A30: =RANK(C30,$C$23:$C$115,0) -> 60 | B30: 더좋은샘물 | C30: =SUM(D30:L30) -> 120000 | D30: =SUMIFS(Master!$L$2:$L$1254,Master!$G$2:$G$1254,분류!D$21,Master!$E$2:$E$1254,분류!$B30) -> 0 | E30: =SUMIFS(Master!$L$2:$L$1254,Master!$G$2:$G$1254,분류!E$21,Master!$E$2:$E$1254,분류!$B30) -> 0 | F30: =SUMIFS(Master!$L$2:$L$1254,Master!$G$2:$G$1254,분류!F$21,Master!$E$2:$E$1254,분류!$B30) -> 0 | G30: =SUMIFS(Master!$L$2:$L$1254,Master!$G$2:$G$1254,분류!G$21,Master!$E$2:$E$1254,분류!$B30) -> 0 | H30: =SUMIFS(Master!$L$2:$L$1254,Master!$G$2:$G$1254,분류!H$21,Master!$E$2:$E$1254,분류!$B30) -> 0 | I30: =SUMIFS(Master!$L$2:$L$1254,Master!$G$2:$G$1254,분류!I$21,Master!$E$2:$E$1254,분류!$B30) -> 120000 | J30: =SUMIFS(Master!$L$2:$L$1254,Master!$G$2:$G$1254,분류!J$21,Master!$E$2:$E$1254,분류!$B30) -> 0 | K30: =SUMIFS(Master!$L$2:$L$1254,Master!$G$2:$G$1254,분류!K$21,Master!$E$2:$E$1254,분류!$B30) -> 0 | L30: =SUMIFS(Master!$L$2:$L$1254,Master!$G$2:$G$1254,분류!L$21,Master!$E$2:$E$1254,분류!$B30) -> 0
A31: =RANK(C31,$C$23:$C$115,0) -> 22 | B31: 더파트 | C31: =SUM(D31:L31) -> 4860000 | D31: =SUMIFS(Master!$L$2:$L$1254,Master!$G$2:$G$1254,분류!D$21,Master!$E$2:$E$1254,분류!$B31) -> 0 | E31: =SUMIFS(Master!$L$2:$L$1254,Master!$G$2:$G$1254,분류!E$21,Master!$E$2:$E$1254,분류!$B31) -> 4860000 | F31: =SUMIFS(Master!$L$2:$L$1254,Master!$G$2:$G$1254,분류!F$21,Master!$E$2:$E$1254,분류!$B31) -> 0 | G31: =SUMIFS(Master!$L$2:$L$1254,Master!$G$2:$G$1254,분류!G$21,Master!$E$2:$E$1254,분류!$B31) -> 0 | H31: =SUMIFS(Master!$L$2:$L$1254,Master!$G$2:$G$1254,분류!H$21,Master!$E$2:$E$1254,분류!$B31) -> 0 | I31: =SUMIFS(Master!$L$2:$L$1254,Master!$G$2:$G$1254,분류!I$21,Master!$E$2:$E$1254,분류!$B31) -> 0 | J31: =SUMIFS(Master!$L$2:$L$1254,Master!$G$2:$G$1254,분류!J$21,Master!$E$2:$E$1254,분류!$B31) -> 0 | K31: =SUMIFS(Master!$L$2:$L$1254,Master!$G$2:$G$1254,분류!K$21,Master!$E$2:$E$1254,분류!$B31) -> 0 | L31: =SUMIFS(Master!$L$2:$L$1254,Master!$G$2:$G$1254,분류!L$21,Master!$E$2:$E$1254,분류!$B31) -> 0
A32: =RANK(C32,$C$23:$C$115,0) -> 17 | B32: 디씨에스에스테크놀러지코리아 | C32: =SUM(D32:L32) -> 9020080 | D32: =SUMIFS(Master!$L$2:$L$1254,Master!$G$2:$G$1254,분류!D$21,Master!$E$2:$E$1254,분류!$B32) -> 200000 | E32: =SUMIFS(Master!$L$2:$L$1254,Master!$G$2:$G$1254,분류!E$21,Master!$E$2:$E$1254,분류!$B32) -> 8820080 | F32: =SUMIFS(Master!$L$2:$L$1254,Master!$G$2:$G$1254,분류!F$21,Master!$E$2:$E$1254,분류!$B32) -> 0 | G32: =SUMIFS(Master!$L$2:$L$1254,Master!$G$2:$G$1254,분류!G$21,Master!$E$2:$E$1254,분류!$B32) -> 0 | H32: =SUMIFS(Master!$L$2:$L$1254,Master!$G$2:$G$1254,분류!H$21,Master!$E$2:$E$1254,분류!$B32) -> 0 | I32: =SUMIFS(Master!$L$2:$L$1254,Master!$G$2:$G$1254,분류!I$21,Master!$E$2:$E$1254,분류!$B32) -> 0 | J32: =SUMIFS(Master!$L$2:$L$1254,Master!$G$2:$G$1254,분류!J$21,Master!$E$2:$E$1254,분류!$B32) -> 0 | K32: =SUMIFS(Master!$L$2:$L$1254,Master!$G$2:$G$1254,분류!K$21,Master!$E$2:$E$1254,분류!$B32) -> 0 | L32: =SUMIFS(Master!$L$2:$L$1254,Master!$G$2:$G$1254,분류!L$21,Master!$E$2:$E$1254,분류!$B32) -> 0
A33: =RANK(C33,$C$23:$C$115,0) -> 59 | B33: 디에스티인터내셔널 | C33: =SUM(D33:L33) -> 200000 | D33: =SUMIFS(Master!$L$2:$L$1254,Master!$G$2:$G$1254,분류!D$21,Master!$E$2:$E$1254,분류!$B33) -> 0 | E33: =SUMIFS(Master!$L$2:$L$1254,Master!$G$2:$G$1254,분류!E$21,Master!$E$2:$E$1254,분류!$B33) -> 200000 | F33: =SUMIFS(Master!$L$2:$L$1254,Master!$G$2:$G$1254,분류!F$21,Master!$E$2:$E$1254,분류!$B33) -> 0 | G33: =SUMIFS(Master!$L$2:$L$1254,Master!$G$2:$G$1254,분류!G$21,Master!$E$2:$E$1254,분류!$B33) -> 0 | H33: =SUMIFS(Master!$L$2:$L$1254,Master!$G$2:$G$1254,분류!H$21,Master!$E$2:$E$1254,분류!$B33) -> 0 | I33: =SUMIFS(Master!$L$2:$L$1254,Master!$G$2:$G$1254,분류!I$21,Master!$E$2:$E$1254,분류!$B33) -> 0 | J33: =SUMIFS(Master!$L$2:$L$1254,Master!$G$2:$G$1254,분류!J$21,Master!$E$2:$E$1254,분류!$B33) -> 0 | K33: =SUMIFS(Master!$L$2:$L$1254,Master!$G$2:$G$1254,분류!K$21,Master!$E$2:$E$1254,분류!$B33) -> 0 | L33: =SUMIFS(Master!$L$2:$L$1254,Master!$G$2:$G$1254,분류!L$21,Master!$E$2:$E$1254,분류!$B33) -> 0
A34: =RANK(C34,$C$23:$C$115,0) -> 53 | B34: 디지알코리아 | C34: =SUM(D34:L34) -> 310000 | D34: =SUMIFS(Master!$L$2:$L$1254,Master!$G$2:$G$1254,분류!D$21,Master!$E$2:$E$1254,분류!$B34) -> 310000 | E34: =SUMIFS(Master!$L$2:$L$1254,Master!$G$2:$G$1254,분류!E$21,Master!$E$2:$E$1254,분류!$B34) -> 0 | F34: =SUMIFS(Master!$L$2:$L$1254,Master!$G$2:$G$1254,분류!F$21,Master!$E$2:$E$1254,분류!$B34) -> 0 | G34: =SUMIFS(Master!$L$2:$L$1254,Master!$G$2:$G$1254,분류!G$21,Master!$E$2:$E$1254,분류!$B34) -> 0 | H34: =SUMIFS(Master!$L$2:$L$1254,Master!$G$2:$G$1254,분류!H$21,Master!$E$2:$E$1254,분류!$B34) -> 0 | I34: =SUMIFS(Master!$L$2:$L$1254,Master!$G$2:$G$1254,분류!I$21,Master!$E$2:$E$1254,분류!$B34) -> 0 | J34: =SUMIFS(Master!$L$2:$L$1254,Master!$G$2:$G$1254,분류!J$21,Master!$E$2:$E$1254,분류!$B34) -> 0 | K34: =SUMIFS(Master!$L$2:$L$1254,Master!$G$2:$G$1254,분류!K$21,Master!$E$2:$E$1254,분류!$B34) -> 0 | L34: =SUMIFS(Master!$L$2:$L$1254,Master!$G$2:$G$1254,분류!L$21,Master!$E$2:$E$1254,분류!$B34) -> 0
... A115: =RANK(C115,$C$23:$C$115,0) -> 65 | B115: 휴넷 | C115: =SUM(D115:L115) -> 0 | D115: =SUMIFS(Master!$L$2:$L$1254,Master!$G$2:$G$1254,분류!D$21,Master!$E$2:$E$1254,분류!$B115) -> 0 | E115: =SUMIFS(Master!$L$2:$L$1254,Master!$G$2:$G$1254,분류!E$21,Master!$E$2:$E$1254,분류!$B115) -> 0 | F115: =SUMIFS(Master!$L$2:$L$1254,Master!$G$2:$G$1254,분류!F$21,Master!$E$2:$E$1254,분류!$B115) -> 0 | G115: =SUMIFS(Master!$L$2:$L$1254,Master!$G$2:$G$1254,분류!G$21,Master!$E$2:$E$1254,분류!$B115) -> 0 | H115: =SUMIFS(Master!$L$2:$L$1254,Master!$G$2:$G$1254,분류!H$21,Master!$E$2:$E$1254,분류!$B115) -> 0 | I115: =SUMIFS(Master!$L$2:$L$1254,Master!$G$2:$G$1254,분류!I$21,Master!$E$2:$E$1254,분류!$B115) -> 0 | J115: =SUMIFS(Master!$L$2:$L$1254,Master!$G$2:$G$1254,분류!J$21,Master!$E$2:$E$1254,분류!$B115) -> 0 | K115: =SUMIFS(Master!$L$2:$L$1254,Master!$G$2:$G$1254,분류!K$21,Master!$E$2:$E$1254,분류!$B115) -> 0 | L115: =SUMIFS(Master!$L$2:$L$1254,Master!$G$2:$G$1254,분류!L$21,Master!$E$2:$E$1254,분류!$B115) -> 0
B116: 법인카드 | C116: =SUM(D116:L116) -> 5387063.8 | D116: ='현금,법인카드'!L45 -> 5387063.8
B117: 현금 | C117: =SUM(D117:L117) -> 0 | D117: ='현금,법인카드'!L10 -> 0
A145: =RANK(C145,$C$23:$C$115,0) -> 65 | B145: 금성스펀지 | C145: =SUM(D145:L145) -> 0 | D145: =SUMIFS(Master!$L$2:$L$1254,Master!$G$2:$G$1254,분류!D$21,Master!$E$2:$E$1254,분류!$B145) -> 0 | E145: =SUMIFS(Master!$L$2:$L$1254,Master!$G$2:$G$1254,분류!E$21,Master!$E$2:$E$1254,분류!$B145) -> 0 | F145: =SUMIFS(Master!$L$2:$L$1254,Master!$G$2:$G$1254,분류!F$21,Master!$E$2:$E$1254,분류!$B145) -> 0 | G145: =SUMIFS(Master!$L$2:$L$1254,Master!$G$2:$G$1254,분류!G$21,Master!$E$2:$E$1254,분류!$B145) -> 0 | H145: =SUMIFS(Master!$L$2:$L$1254,Master!$G$2:$G$1254,분류!H$21,Master!$E$2:$E$1254,분류!$B145) -> 0 | I145: =SUMIFS(Master!$L$2:$L$1254,Master!$G$2:$G$1254,분류!I$21,Master!$E$2:$E$1254,분류!$B145) -> 0 | J145: =SUMIFS(Master!$L$2:$L$1254,Master!$G$2:$G$1254,분류!J$21,Master!$E$2:$E$1254,분류!$B145) -> 0 | K145: =SUMIFS(Master!$L$2:$L$1254,Master!$G$2:$G$1254,분류!K$21,Master!$E$2:$E$1254,분류!$B145) -> 0 | L145: =SUMIFS(Master!$L$2:$L$1254,Master!$G$2:$G$1254,분류!L$21,Master!$E$2:$E$1254,분류!$B145) -> 0
A146: =RANK(C146,$C$23:$C$115,0) -> 65 | B146: 나로아이엔씨 | C146: =SUM(D146:L146) -> 0 | D146: =SUMIFS(Master!$L$2:$L$1254,Master!$G$2:$G$1254,분류!D$21,Master!$E$2:$E$1254,분류!$B146) -> 0 | E146: =SUMIFS(Master!$L$2:$L$1254,Master!$G$2:$G$1254,분류!E$21,Master!$E$2:$E$1254,분류!$B146) -> 0 | F146: =SUMIFS(Master!$L$2:$L$1254,Master!$G$2:$G$1254,분류!F$21,Master!$E$2:$E$1254,분류!$B146) -> 0 | G146: =SUMIFS(Master!$L$2:$L$1254,Master!$G$2:$G$1254,분류!G$21,Master!$E$2:$E$1254,분류!$B146) -> 0 | H146: =SUMIFS(Master!$L$2:$L$1254,Master!$G$2:$G$1254,분류!H$21,Master!$E$2:$E$1254,분류!$B146) -> 0 | I146: =SUMIFS(Master!$L$2:$L$1254,Master!$G$2:$G$1254,분류!I$21,Master!$E$2:$E$1254,분류!$B146) -> 0 | J146: =SUMIFS(Master!$L$2:$L$1254,Master!$G$2:$G$1254,분류!J$21,Master!$E$2:$E$1254,분류!$B146) -> 0 | K146: =SUMIFS(Master!$L$2:$L$1254,Master!$G$2:$G$1254,분류!K$21,Master!$E$2:$E$1254,분류!$B146) -> 0 | L146: =SUMIFS(Master!$L$2:$L$1254,Master!$G$2:$G$1254,분류!L$21,Master!$E$2:$E$1254,분류!$B146) -> 0
A147: =RANK(C147,$C$23:$C$115,0) -> 65 | B147: 닷넷소프트 | C147: =SUM(D147:L147) -> 0 | D147: =SUMIFS(Master!$L$2:$L$1254,Master!$G$2:$G$1254,분류!D$21,Master!$E$2:$E$1254,분류!$B147) -> 0 | E147: =SUMIFS(Master!$L$2:$L$1254,Master!$G$2:$G$1254,분류!E$21,Master!$E$2:$E$1254,분류!$B147) -> 0 | F147: =SUMIFS(Master!$L$2:$L$1254,Master!$G$2:$G$1254,분류!F$21,Master!$E$2:$E$1254,분류!$B147) -> 0 | G147: =SUMIFS(Master!$L$2:$L$1254,Master!$G$2:$G$1254,분류!G$21,Master!$E$2:$E$1254,분류!$B147) -> 0 | H147: =SUMIFS(Master!$L$2:$L$1254,Master!$G$2:$G$1254,분류!H$21,Master!$E$2:$E$1254,분류!$B147) -> 0 | I147: =SUMIFS(Master!$L$2:$L$1254,Master!$G$2:$G$1254,분류!I$21,Master!$E$2:$E$1254,분류!$B147) -> 0 | J147: =SUMIFS(Master!$L$2:$L$1254,Master!$G$2:$G$1254,분류!J$21,Master!$E$2:$E$1254,분류!$B147) -> 0 | K147: =SUMIFS(Master!$L$2:$L$1254,Master!$G$2:$G$1254,분류!K$21,Master!$E$2:$E$1254,분류!$B147) -> 0 | L147: =SUMIFS(Master!$L$2:$L$1254,Master!$G$2:$G$1254,분류!L$21,Master!$E$2:$E$1254,분류!$B147) -> 0
A148: =RANK(C148,$C$23:$C$115,0) -> 65 | B148: 대원씨티에스 | C148: =SUM(D148:L148) -> 0 | D148: =SUMIFS(Master!$L$2:$L$1254,Master!$G$2:$G$1254,분류!D$21,Master!$E$2:$E$1254,분류!$B148) -> 0 | E148: =SUMIFS(Master!$L$2:$L$1254,Master!$G$2:$G$1254,분류!E$21,Master!$E$2:$E$1254,분류!$B148) -> 0 | F148: =SUMIFS(Master!$L$2:$L$1254,Master!$G$2:$G$1254,분류!F$21,Master!$E$2:$E$1254,분류!$B148) -> 0 | G148: =SUMIFS(Master!$L$2:$L$1254,Master!$G$2:$G$1254,분류!G$21,Master!$E$2:$E$1254,분류!$B148) -> 0 | H148: =SUMIFS(Master!$L$2:$L$1254,Master!$G$2:$G$1254,분류!H$21,Master!$E$2:$E$1254,분류!$B148) -> 0 | I148: =SUMIFS(Master!$L$2:$L$1254,Master!$G$2:$G$1254,분류!I$21,Master!$E$2:$E$1254,분류!$B148) -> 0 | J148: =SUMIFS(Master!$L$2:$L$1254,Master!$G$2:$G$1254,분류!J$21,Master!$E$2:$E$1254,분류!$B148) -> 0 | K148: =SUMIFS(Master!$L$2:$L$1254,Master!$G$2:$G$1254,분류!K$21,Master!$E$2:$E$1254,분류!$B148) -> 0 | L148: =SUMIFS(Master!$L$2:$L$1254,Master!$G$2:$G$1254,분류!L$21,Master!$E$2:$E$1254,분류!$B148) -> 0
A149: =RANK(C149,$C$23:$C$115,0) -> 65 | B149: 도우정보 | C149: =SUM(D149:L149) -> 0 | D149: =SUMIFS(Master!$L$2:$L$1254,Master!$G$2:$G$1254,분류!D$21,Master!$E$2:$E$1254,분류!$B149) -> 0 | E149: =SUMIFS(Master!$L$2:$L$1254,Master!$G$2:$G$1254,분류!E$21,Master!$E$2:$E$1254,분류!$B149) -> 0 | F149: =SUMIFS(Master!$L$2:$L$1254,Master!$G$2:$G$1254,분류!F$21,Master!$E$2:$E$1254,분류!$B149) -> 0 | G149: =SUMIFS(Master!$L$2:$L$1254,Master!$G$2:$G$1254,분류!G$21,Master!$E$2:$E$1254,분류!$B149) -> 0 | H149: =SUMIFS(Master!$L$2:$L$1254,Master!$G$2:$G$1254,분류!H$21,Master!$E$2:$E$1254,분류!$B149) -> 0 | I149: =SUMIFS(Master!$L$2:$L$1254,Master!$G$2:$G$1254,분류!I$21,Master!$E$2:$E$1254,분류!$B149) -> 0 | J149: =SUMIFS(Master!$L$2:$L$1254,Master!$G$2:$G$1254,분류!J$21,Master!$E$2:$E$1254,분류!$B149) -> 0 | K149: =SUMIFS(Master!$L$2:$L$1254,Master!$G$2:$G$1254,분류!K$21,Master!$E$2:$E$1254,분류!$B149) -> 0 | L149: =SUMIFS(Master!$L$2:$L$1254,Master!$G$2:$G$1254,분류!L$21,Master!$E$2:$E$1254,분류!$B149) -> 0
A150: =RANK(C150,$C$23:$C$115,0) -> 65 | B150: 디앤디컴 | C150: =SUM(D150:L150) -> 0 | D150: =SUMIFS(Master!$L$2:$L$1254,Master!$G$2:$G$1254,분류!D$21,Master!$E$2:$E$1254,분류!$B150) -> 0 | E150: =SUMIFS(Master!$L$2:$L$1254,Master!$G$2:$G$1254,분류!E$21,Master!$E$2:$E$1254,분류!$B150) -> 0 | F150: =SUMIFS(Master!$L$2:$L$1254,Master!$G$2:$G$1254,분류!F$21,Master!$E$2:$E$1254,분류!$B150) -> 0 | G150: =SUMIFS(Master!$L$2:$L$1254,Master!$G$2:$G$1254,분류!G$21,Master!$E$2:$E$1254,분류!$B150) -> 0 | H150: =SUMIFS(Master!$L$2:$L$1254,Master!$G$2:$G$1254,분류!H$21,Master!$E$2:$E$1254,분류!$B150) -> 0 | I150: =SUMIFS(Master!$L$2:$L$1254,Master!$G$2:$G$1254,분류!I$21,Master!$E$2:$E$1254,분류!$B150) -> 0 | J150: =SUMIFS(Master!$L$2:$L$1254,Master!$G$2:$G$1254,분류!J$21,Master!$E$2:$E$1254,분류!$B150) -> 0 | K150: =SUMIFS(Master!$L$2:$L$1254,Master!$G$2:$G$1254,분류!K$21,Master!$E$2:$E$1254,분류!$B150) -> 0 | L150: =SUMIFS(Master!$L$2:$L$1254,Master!$G$2:$G$1254,분류!L$21,Master!$E$2:$E$1254,분류!$B150) -> 0
...

Sheet 1월
B1: ="["&YEAR(D5)&"년 "&MONTH(D5)&"월 매입]" -> [2025년 1월 매입]
M2: x 비과세 0 영세 | O2: 완료 | Q2: 트루스케일
B3: 품의코드 | C3: Vendor 코드 | D3: 계산서 | E3: 매입처 | F3: 매출처 | G3: 구분 | H3: MA : 청구구분 상품 : PN | I3: 품목 | J3: 수량 | K3: 매입 | O3: 결제 | P3: 영업 담당자 | Q3: 매출처 세금계산서 | R3: 비고
K4: 단가 | L4: 공금가액 | M4: VAT | N4: 합계금액
A5: . | B5: X | D5: 45658 | E5: 에스케이쉴더스 금천지점 | G5: 일반경비 | H5: 지급수수료 | I5: 보안용역 월정료 1월분 | J5: 1 | K5: 71000 | L5: =J5*K5 -> 71000 | M5: =L5*10% -> 7100 | N5: =SUM(L5:M5) -> 78100 | O5: 자동이체(1/11) | P5: 정지우 | Q5: X
A6: . | B6: LI-24005 | D6: 45658 | E6: 한국아이씨에스 | F6: 해안종합건축사사무소 | G6: MA | H6: 월간-IBM | I6: 1월 유지정비료 - 8/12회 | J6: 1 | K6: 436400 | L6: =J6*K6 -> 436400 | M6: 43640 | N6: =SUM(L6:M6) -> 480040 | O6: 완료(25/1/24) | P6: 천범석 | Q6: 45658
A7: . | B7: SM-24007 | D7: 45658 | E7: 한국아이씨에스 | F7: 연세의료원 | G7: MA | H7: 월간-IBM | I7: 1월 유지정비료 - 12/12회 | J7: 1 | K7: 288000 | L7: =J7*K7 -> 288000 | M7: 28800 | N7: =SUM(L7:M7) -> 316800 | O7: 완료(25/1/24) | P7: 이예지 | Q7: 45677
A8: . | B8: LI-24006 | D8: 45658 | E8: 한국아이씨에스 | F8: 보해양조 | G8: MA | H8: 월간-IBM | I8: 1월 유지정비료 - 6/11회 | J8: 1 | K8: 277600 | L8: =J8*K8 -> 277600 | M8: 27760 | N8: =SUM(L8:M8) -> 305360 | O8: 완료(25/1/24) | P8: 천범석 | Q8: 45682
A9: . | B9: IK-24006 | D9: 45659 | E9: 한국아이씨에스 | F9: 광양항서부터미널 | G9: MA | H9: 월간-IBM | I9: 1월 유지정비료 - 9/24회 | J9: 1 | K9: 3239404 | L9: =J9*K9 -> 3239404 | M9: 323940 | N9: =SUM(L9:M9) -> 3563344 | O9: 완료(2/28) | P9: 홍승민 | Q9: 45688
A10: . | B10: LI-24008 | D10: 45659 | E10: 한국아이씨에스 | F10: 쿠팡 | G10: MA | H10: 월간-IBM | I10: 1월 유지정비료 - 6/13회 | J10: 1 | K10: 205780 | L10: 205780 | M10: 20578 | N10: =SUM(L10:M10) -> 226358 | O10: 완료(2/28) | P10: 천범석 | Q10: 45491 | R10: 매출연간
A11: . | B11: LI-24003 | D11: 45659 | E11: 한국아이씨에스 | F11: 지엔콤 | G11: MA | H11: 월간-IBM | I11: 전주교육대학교 1월 유지정비료 - 9/12회 | J11: 1 | K11: 305280 | L11: =J11*K11 -> 305280 | M11: 30528 | N11: =SUM(L11:M11) -> 335808 | O11: 완료(2/28) | P11: 천범석 | Q11: 45688
A12: . | B12: IK-23021 | D12: 45659 | E12: 한국아이씨에스 | F12: 투아이시스 | G12: MA | H12: 월간-IBM | I12: 1월 유지정비료 - 11/12회 | J12: 1 | K12: 93445 | L12: =J12*K12 -> 93445 | M12: 9344 | N12: =SUM(L12:M12) -> 102789 | O12: 완료(2/28) | P12: 천범석 | Q12: 45380 | R12: 매출연간
A13: . | B13: SM-25003 | D13: 45659 | E13: 한국아이씨에스 | F13: CGV 통합 | G13: MA | H13: 월간-IBM | I13: 1월 유지정비료 - 1/12회 | J13: 1 | K13: 2812500 | L13: =J13*K13 -> 2812500 | M13: 281250 | N13: =SUM(L13:M13) -> 3093750 | O13: 완료(2/28) | P13: 이예지 | Q13: 45666 | R13: 매출연간
A14: . | B14: IK-23016 | D14: 45659 | E14: 한국아이씨에스 | F14: 케이정보기술 | G14: MA | H14: 월간-IBM | I14: 청주시청 1월 유지정비료 - 1/20회 추가 | J14: 1 | K14: 1123962 | L14: =J14*K14 -> 1123962 | M14: 112396 | N14: =SUM(L14:M14) -> 1236358 | O14: 완료(2/28) | P14: 천범석 | Q14: 45658
A15: . | B15: IK-22025 | D15: 45659 | E15: 한국아이씨에스 | F15: 디에스피 | G15: MA | H15: 월간-IBM | I15: 엘지생활건강 청주공장 1월 유지정비료 - 12/12회 | J15: 1 | K15: 532212 | L15: =J15*K15 -> 532212 | M15: 53221 | N15: =SUM(L15:M15) -> 585433 | O15: 완료(2/28) | P15: 천범석 | Q15: 45658
A16: . | B16: IK-23013 | D16: 45659 | E16: 한국아이씨에스 | F16: 로보츠 | G16: MA | H16: 월간-IBM | I16: 도시바일렉 1월 유지정비료 - 7/12회 | J16: 1 | K16: 66498 | L16: =J16*K16 -> 66498 | M16: 6649 | N16: =SUM(L16:M16) -> 73147 | O16: 완료(2/28) | P16: 천범석 | Q16: 45688
A17: . | B17: LI-24007 | D17: 45659 | E17: 한국아이씨에스 | F17: 유더블유에스 | G17: MA | H17: 월간-IBM | I17: 두원정공 1월 유지정비료 - 6/11회 | J17: 1 | K17: 80160 | L17: 80160 | M17: 8016 | N17: =SUM(L17:M17) -> 88176 | O17: 완료(2/28) | P17: 천범석 | Q17: 45688
A18: . | B18: IK-23014 | D18: 45659 | E18: 한국아이씨에스 | F18: 서비스링크 | G18: MA | H18: 월간-IBM | I18: 세원정공 1월 유지정비료 - 7/12회 | J18: 1 | K18: 198018 | L18: =J18*K18 -> 198018 | M18: 19801 | N18: =SUM(L18:M18) -> 217819 | O18: 완료(2/28) | P18: 천범석 | Q18: 45658
A19: . | B19: SM-21021 | D19: 45659 | E19: 한국아이씨에스 | F19: 법무법인바른 | G19: MA | H19: 월간-IBM | I19: 1월 유지정비료 - 5/13회 | J19: 1 | K19: 84811 | L19: =J19*K19 -> 84811 | M19: 8481 | N19: =SUM(L19:M19) -> 93292 | O19: 완료(2/28) | P19: 천범석 | Q19: 45682
A20: . | B20: IK-24011 | D20: 45659 | E20: 한국아이씨에스 | F20: 로보츠 | G20: MA | H20: 월간-IBM | I20: 키오시아(도시바) 1월 유지정비료 - 2/12회 | J20: 1 | K20: 133875 | L20: =J20*K20 -> 133875 | M20: 13387 | N20: =SUM(L20:M20) -> 147262 | O20: 완료(2/28) | P20: 천범석 | Q20: 45688
A21: . | B21: SM-25011 | D21: 45659 | E21: 한국아이씨에스 | F21: 유니포인트 | G21: MA | H21: 월간-IBM | I21: 한미약품/한미사이언스 1월 유지정비료 - 1/12회 | J21: 1 | K21: 11623397 | L21: =J21*K21 -> 11623397 | M21: 1162339 | N21: =SUM(L21:M21) -> 12785736 | O21: 완료(2/28) | P21: 천범석 | Q21: 45681
A22: . | B22: IK-24002 | D22: 45659 | E22: 한국아이씨에스 | F22: 리온아이티 | G22: MA | H22: 월간-IBM | I22: 교세라 1월 유지정비료 - 12/36회 | J22: 1 | K22: 70422 | L22: =J22*K22 -> 70422 | M22: 7042 | N22: =SUM(L22:M22) -> 77464 | O22: 완료(2/28) | P22: 천범석 | Q22: 45688
A23: . | B23: SM-24021 | D23: 45659 | E23: 한국아이씨에스 | F23: 에이캐피탈 | G23: MA | H23: 월간-IBM | I23: 1월 유지정비료 - 5/12회 | J23: 1 | K23: 691782 | L23: =J23*K23 -> 691782 | M23: 69178 | N23: =SUM(L23:M23) -> 760960 | O23: 완료(2/28) | P23: 천범석 | Q23: 45693
A24: . | B24: LI-24004 | D24: 45659 | E24: 한국아이씨에스 | F24: 한국메탈 | G24: MA | H24: 월간-IBM | I24: 1월유지정비료 - 9/32회 | J24: 1 | K24: 316682 | L24: =J24*K24 -> 316682 | M24: 31668 | N24: =SUM(L24:M24) -> 348350 | O24: 완료(2/28) | P24: 천범석 | Q24: 45658
A25: . | B25: SB-24036 | D25: 45659 | E25: 한국아이씨에스 | F25: 나라정보 | G25: MA | H25: 월간-IBM | I25: 부국철강 1월 유지정비료 - 9/32 회 | J25: 1 | K25: 190849 | L25: =J25*K25 -> 190849 | M25: 19084 | N25: =SUM(L25:M25) -> 209933 | O25: 완료(2/28) | P25: 천범석 | Q25: 45688
A26: . | B26: LI-24009 | D26: 45659 | E26: 한국아이씨에스 | F26: 아이리스인포테크 | G26: MA | H26: 월간-IBM | I26: 프레이저플레이스 1월 유지정비료 - 6/12회 | J26: 1 | K26: 95200 | L26: =J26*K26 -> 95200 | M26: 9520 | N26: =SUM(L26:M26) -> 104720 | O26: 완료(2/28) | P26: 천범석 | Q26: 45625 | R26: 매출분기
A27: . | B27: IK-24014 | D27: 45659 | E27: 한국아이씨에스 | F27: 로보츠 | G27: MA | H27: 월간-IBM | I27: 와이케이케이 1월 유지정비료 - 1/12회 | J27: 1 | K27: 79496 | L27: =J27*K27 -> 79496 | M27: 7949 | N27: =SUM(L27:M27) -> 87445 | O27: 완료(2/28) | P27: 천범석 | Q27: 45682
A28: . | B28: IK-22023 | D28: 45659 | E28: 한국아이씨에스 | F28: 리온아이티 | G28: MA | H28: 월간-IBM | I28: 성원제강 1월 유지정비료 - 22/36회 | J28: 1 | K28: 159761 | L28: =J28*K28 -> 159761 | M28: 15976 | N28: =SUM(L28:M28) -> 175737 | O28: 완료(2/28) | P28: 천범석 | Q28: 45688
A29: . | B29: LI-24006 | D29: 45659 | E29: 한국아이씨에스 | F29: 보해양조 | G29: MA | H29: 월간-IBM | I29: 1월 유지정비료 - 7/12회 | J29: 1 | K29: 142800 | L29: =J29*K29 -> 142800 | M29: 14280 | N29: =SUM(L29:M29) -> 157080 | O29: 완료(2/28) | P29: 천범석 | Q29: 45682
A30: . | B30: IK-24005 | D30: 45659 | E30: 한국아이씨에스 | F30: 엔콤 | G30: MA | H30: 월간-IBM | I30: 전북도시가스 1월 유지정비료 - 10/12회 | J30: 1 | K30: 1263250 | L30: =J30*K30 -> 1263250 | M30: 126325 | N30: =SUM(L30:M30) -> 1389575 | O30: 완료(2/28) | P30: 천범석 | Q30: 45688
A31: . | B31: IK-22022 | D31: 45659 | E31: 한국아이씨에스 | F31: 리온아이티 | G31: MA | H31: 월간-IBM | I31: 한일전기 1월 유지정비료 - 25/36회 | J31: 1 | K31: 309047 | L31: =J31*K31 -> 309047 | M31: 30904 | N31: =SUM(L31:M31) -> 339951 | O31: 완료(2/28) | P31: 천범석 | Q31: 45658 | R31: 매출분기
A32: . | B32: IK-24013 | D32: 45659 | E32: 한국아이씨에스 | F32: 레드텍 | G32: MA | H32: 월간-IBM | I32: 대한상공회의소 1월 유지정비료 - 3/12회 | J32: 1 | K32: 94111 | L32: =J32*K32 -> 94111 | M32: 9411 | N32: =SUM(L32:M32) -> 103522 | O32: 완료(2/28) | P32: 천범석 | Q32: 45658
A33: . | B33: IK-22021 | D33: 45659 | E33: 한국아이씨에스 | F33: 리온아이티 | G33: MA | H33: 월간-IBM | I33: 문배철강 1월 유지정비료 - 22/36회 | J33: 1 | K33: 212293 | L33: =J33*K33 -> 212293 | M33: 21229 | N33: =SUM(L33:M33) -> 233522 | O33: 완료(2/28) | P33: 천범석 | Q33: 45688
A34: . | B34: Y241205-01 | D34: 45659 | E34: 컴퓨존 | F34: 삼표피앤씨 | G34: 상품 | H34: 랜카드 | I34: ipTIME U1000 PLUS 유선랜카드 | J34: 1 | K34: 13545 | L34: =J34*K34 -> 13545 | M34: 1355 | N34: =SUM(L34:M34) -> 14900 | O34: 완료(1/2) | P34: 홍승민 | Q34: 45649
A35: . | B35: SM-25010 | D35: 45659 | E35: 프로미스 | F35: 유니포인트 | G35: MA | H35: 분기 | I35: 한미약품, 한미사이언스 유지보수 25년 1Q | J35: 1 | K35: 8000000 | L35: =J35*K35 -> 8000000 | M35: =L35*10% -> 800000 | N35: =SUM(L35:M35) -> 8800000 | O35: 완료(1/15) | P35: 이예지 | Q35: 45688
A36: . | B36: Y241209-03 | D36: 45659 | E36: 프로미스 | F36: 더힘 | G36: 상품 | H36: 기술지원 | I36: 우물단 TR630 설치지원 | J36: 1 | K36: 3000000 | L36: =J36*K36 -> 3000000 | M36: =L36*10% -> 300000 | N36: =SUM(L36:M36) -> 3300000 | O36: 완료(1/15) | P36: 홍승민 | Q36: 45645
A37: . | B37: S | D37: 45659 | E37: 프로미스 | F37: 티엔플러스 | G37: 상품 | H37: 기술지원 | I37: 계양 복지센터 케이코 설치지원 | J37: 1 | K37: 800000 | L37: =J37*K37 -> 800000 | M37: =L37*10% -> 80000 | N37: =SUM(L37:M37) -> 880000 | O37: 완료(1/15) | P37: 이예지 | Q37: 45650
A38: . | B38: S241223 | D38: 45659 | E38: 프로미스 | F38: 다솜테크 | G38: 상품 | H38: 기술지원 | I38: SSD 설치지원 | J38: 1 | K38: 1700000 | L38: =J38*K38 -> 1700000 | M38: =L38*10% -> 170000 | N38: =SUM(L38:M38) -> 1870000 | O38: 완료(1/15) | P38: 이예지 | Q38: 45657
A39: . | B39: SB-24011 | D39: 45659 | E39: 프로미스 | F39: 비온시 | G39: MA | H39: 연간 | I39: 24년 국립농업과학원 기술지원 | J39: 1 | K39: 3400000 | L39: =J39*K39 -> 3400000 | M39: =L39*10% -> 340000 | N39: =SUM(L39:M39) -> 3740000 | O39: 완료(1/15) | P39: 천범석 | Q39: 24/2/15~25/1/15
A40: . | B40: SB-24063 | D40: 45659 | E40: 프로미스 | F40: 다솜테크 | G40: MA | H40: 연간 | I40: E1컨테이너터미널 기술지원비 | J40: 1 | K40: 1000000 | L40: =J40*K40 -> 1000000 | M40: =L40*10% -> 100000 | N40: =SUM(L40:M40) -> 1100000 | O40: 완료(1/15) | P40: 천범석 | Q40: 1/31~12/31
...

Sheet 2월
B1: ="["&YEAR(D5)&"년 "&MONTH(D5)&"월 매입]" -> [2025년 2월 매입]
M2: x 비과세 0 영세 | O2: 완료 | Q2: 트루스케일
B3: 품의코드 | C3: Vendor 코드 | D3: 계산서 | E3: 매입처 | F3: 매출처 | G3: 구분 | H3: MA : 청구구분 상품 : PN | I3: 품목 | J3: 수량 | K3: 매입 | O3: 결제 | P3: 영업 담당자 | Q3: 매출처 세금계산서 | R3: 비고
K4: 단가 | L4: 공금가액 | M4: VAT | N4: 합계금액
A5: . | B5: X | D5: 45689 | E5: 에스케이쉴더스 금천지점 | G5: 일반경비 | H5: 지급수수료 | I5: 보안용역 월정료 2월분 | J5: 1 | K5: 71000 | L5: =J5*K5 -> 71000 | M5: =L5*10% -> 7100 | N5: =SUM(L5:M5) -> 78100 | O5: 자동이체(2/11) | P5: 정지우 | Q5: X
A6: . | B6: LI-24005 | D6: 45689 | E6: 한국아이씨에스 | F6: 해안종합건축사사무소 | G6: MA | H6: 월간-IBM | I6: 2월 유지정비료 - 9/12회 | J6: 1 | K6: 436400 | L6: =J6*K6 -> 436400 | M6: =L6*10% -> 43640 | N6: =SUM(L6:M6) -> 480040 | O6: 완료(3/31) | P6: 천범석 | Q6: 45689
A7: . | B7: LI-24006 | D7: 45689 | E7: 한국아이씨에스 | F7: 보해양조 | G7: MA | H7: 월간-IBM | I7: 2월 유지정비료 - 7/11회 | J7: 1 | K7: 277600 | L7: =J7*K7 -> 277600 | M7: =L7*10% -> 27760 | N7: =SUM(L7:M7) -> 305360 | O7: 완료(3/31) | P7: 천범석 | Q7: 45713
A8: . | B8: Y250203-01 | D8: 45691 | E8: 컴퓨존 | F8: 에스엠티정보기술 | G8: 상품 | H8: OS | I8: Windows Server 2022 Standard (DSP/16core/64bit/CAL미포함16 core) | J8: 1 | K8: 1096609 | L8: =J8*K8 -> 1096609 | M8: 109661 | N8: =SUM(L8:M8) -> 1206270 | O8: 완료(2/3) | P8: 홍승민 | Q8: 45715
A9: . | B9: IK-23021 | D9: 45691 | E9: 한국아이씨에스 | F9: 투아이시스 | G9: MA | H9: 월간-IBM | I9: 2월 유지정비료 - 12/12회 | J9: 1 | K9: 93456 | L9: =J9*K9 -> 93456 | M9: 9345 | N9: =SUM(L9:M9) -> 102801 | O9: 완료(3/31) | P9: 천범석 | Q9: 45380 | R9: 매출연간
A10: . | B10: IK-24006 | D10: 45691 | E10: 한국아이씨에스 | F10: 광양항서부터미널 | G10: MA | H10: 월간-IBM | I10: 2월 유지정비료 - 10/24회 | J10: 1 | K10: 3239404 | L10: =J10*K10 -> 3239404 | M10: 323940 | N10: =SUM(L10:M10) -> 3563344 | O10: 완료(3/31) | P10: 홍승민 | Q10: 45716
A11: . | B11: LI-24008 | D11: 45691 | E11: 한국아이씨에스 | F11: 쿠팡 | G11: MA | H11: 월간-IBM | I11: 2월 유지정비료 - 7/13회 | J11: 1 | K11: 205780 | L11: 205780 | M11: 20578 | N11: =SUM(L11:M11) -> 226358 | O11: 완료(3/31) | P11: 천범석 | Q11: 45491 | R11: 매출연간
A12: . | B12: IK-24012 | D12: 45691 | E12: 한국아이씨에스 | F12: 인정보 | G12: MA | H12: 월간-IBM | I12: 대구텍 2월 유지정비료 - 2/6회 | J12: 1 | K12: 990000 | L12: =J12*K12 -> 990000 | M12: =L12*10% -> 99000 | N12: =SUM(L12:M12) -> 1089000 | O12: 완료(3/31) | P12: 천범석 | Q12: 45689
A13: . | B13: LI-24003 | D13: 45691 | E13: 한국아이씨에스 | F13: 지엔콤 | G13: MA | H13: 월간-IBM | I13: 전주교육대학교 2월 유지정비료 - 10/12회 | J13: 1 | K13: 305280 | L13: =J13*K13 -> 305280 | M13: 30528 | N13: =SUM(L13:M13) -> 335808 | O13: 완료(3/31) | P13: 천범석 | Q13: 45716
A14: . | B14: IK-23016 | D14: 45691 | E14: 한국아이씨에스 | F14: 케이정보기술 | G14: MA | H14: 월간-IBM | I14: 청주시청 2월 유지정비료 - 18/36회 | J14: 1 | K14: 259896 | L14: =J14*K14 -> 259896 | M14: 25989 | N14: =SUM(L14:M14) -> 285885 | O14: 완료(3/31) | P14: 천범석 | Q14: 45689
A15: . | B15: IK-23013 | D15: 45691 | E15: 한국아이씨에스 | F15: 로보츠 | G15: MA | H15: 월간-IBM | I15: 도시바일렉 2월 유지정비료 - 8/12회 | J15: 1 | K15: 66498 | L15: =J15*K15 -> 66498 | M15: 6649 | N15: =SUM(L15:M15) -> 73147 | O15: 완료(3/31) | P15: 천범석 | Q15: 45716
A16: . | B16: LI-24007 | D16: 45691 | E16: 한국아이씨에스 | F16: 유더블유에스 | G16: MA | H16: 월간-IBM | I16: 두원정공 2월 유지정비료 - 7/11회 | J16: 1 | K16: 80160 | L16: 80160 | M16: 8016 | N16: =SUM(L16:M16) -> 88176 | O16: 완료(3/31) | P16: 천범석 | Q16: 45716
A17: . | B17: IK-23014 | D17: 45691 | E17: 한국아이씨에스 | F17: 서비스링크 | G17: MA | H17: 월간-IBM | I17: 세원정공 2월 유지정비료 - 8/12회 | J17: 1 | K17: 198018 | L17: =J17*K17 -> 198018 | M17: 19801 | N17: =SUM(L17:M17) -> 217819 | O17: 완료(3/31) | P17: 천범석 | Q17: 45689
A18: . | B18: SM-21021 | D18: 45691 | E18: 한국아이씨에스 | F18: 법무법인바른 | G18: MA | H18: 월간-IBM | I18: 2월 유지정비료 - 6/13회 | J18: 1 | K18: 84811 | L18: =J18*K18 -> 84811 | M18: 8481 | N18: =SUM(L18:M18) -> 93292 | O18: 완료(3/31) | P18: 천범석 | Q18: 45713
A19: . | B19: IK-24011 | D19: 45691 | E19: 한국아이씨에스 | F19: 로보츠 | G19: MA | H19: 월간-IBM | I19: 키오시아(도시바) 2월 유지정비료 - 3/12회 | J19: 1 | K19: 133875 | L19: =J19*K19 -> 133875 | M19: 13387 | N19: =SUM(L19:M19) -> 147262 | O19: 완료(3/31) | P19: 천범석 | Q19: 45716
A20: . | B20: SM-25011 | D20: 45691 | E20: 한국아이씨에스 | F20: 유니포인트 | G20: MA | H20: 월간-IBM | I20: 한미약품/한미사이언스 2월 유지정비료 - 2/12회 | J20: 1 | K20: 11623397 | L20: =J20*K20 -> 11623397 | M20: 1162339 | N20: =SUM(L20:M20) -> 12785736 | O20: 완료(3/31) | P20: 천범석 | Q20: 45713
A21: . | B21: IK-22025 | D21: 45691 | E21: 한국아이씨에스 | F21: 디에스피 | G21: MA | H21: 월간-IBM | I21: 엘지생활건강 청주공장 2월 유지정비료 - 1/12회 | J21: 1 | K21: 564192 | L21: =J21*K21 -> 564192 | M21: 56419 | N21: =SUM(L21:M21) -> 620611 | O21: 완료(3/31) | P21: 천범석 | Q21: 45689
A22: . | B22: SM-25003 | D22: 45691 | E22: 한국아이씨에스 | F22: CGV 통합 | G22: MA | H22: 월간-IBM | I22: 2월 유지정비료 - 2/12회 | J22: 1 | K22: 2812500 | L22: =J22*K22 -> 2812500 | M22: 281250 | N22: =SUM(L22:M22) -> 3093750 | O22: 완료(3/31) | P22: 이예지 | Q22: 45666 | R22: 매출연간
A23: . | B23: IK-23016 | D23: 45691 | E23: 한국아이씨에스 | F23: 케이정보기술 | G23: MA | H23: 월간-IBM | I23: 청주시청 2월 유지정비료 - 2/20회 추가 | J23: 1 | K23: 1123962 | L23: =J23*K23 -> 1123962 | M23: 112396 | N23: =SUM(L23:M23) -> 1236358 | O23: 완료(3/31) | P23: 천범석 | Q23: 45689
A24: . | B24: SM-24021 | D24: 45691 | E24: 한국아이씨에스 | F24: 에이캐피탈 | G24: MA | H24: 월간-IBM | I24: 2월 유지정비료 - 6/12회 | J24: 1 | K24: 691782 | L24: =J24*K24 -> 691782 | M24: 69178 | N24: =SUM(L24:M24) -> 760960 | O24: 완료(3/31) | P24: 천범석 | Q24: 45721
A25: . | B25: IK-24014 | D25: 45691 | E25: 한국아이씨에스 | F25: 로보츠 | G25: MA | H25: 월간-IBM | I25: 와이케이케이 2월 유지정비료 - 2/12회 | J25: 1 | K25: 79496 | L25: =J25*K25 -> 79496 | M25: 7949 | N25: =SUM(L25:M25) -> 87445 | O25: 완료(3/31) | P25: 천범석 | Q25: 45713
A26: . | B26: IK-22023 | D26: 45691 | E26: 한국아이씨에스 | F26: 리온아이티 | G26: MA | H26: 월간-IBM | I26: 성원제강 2월 유지정비료 - 23/36회 | J26: 1 | K26: 159761 | L26: =J26*K26 -> 159761 | M26: 15976 | N26: =SUM(L26:M26) -> 175737 | O26: 완료(3/31) | P26: 천범석 | Q26: 45716
A27: . | B27: IK-24002 | D27: 45691 | E27: 한국아이씨에스 | F27: 리온아이티 | G27: MA | H27: 월간-IBM | I27: 교세라 2월 유지정비료 - 13/36회 | J27: 1 | K27: 70422 | L27: =J27*K27 -> 70422 | M27: 7042 | N27: =SUM(L27:M27) -> 77464 | O27: 완료(3/31) | P27: 천범석 | Q27: 45716 | R27: 매출연간
A28: . | B28: LI-24009 | D28: 45691 | E28: 한국아이씨에스 | F28: 아이리스인포테크 | G28: MA | H28: 월간-IBM | I28: 프레이저플레이스 2월 유지정비료 - 7/12회 | J28: 1 | K28: 95200 | L28: =J28*K28 -> 95200 | M28: =L28*10% -> 9520 | N28: =SUM(L28:M28) -> 104720 | O28: 완료(3/31) | P28: 천범석 | Q28: 45716 | R28: 매출분기
A29: . | B29: LI-24006 | D29: 45691 | E29: 한국아이씨에스 | F29: 보해양조 | G29: MA | H29: 월간-IBM | I29: 2월 유지정비료 - 8/12회 | J29: 1 | K29: 142800 | L29: =J29*K29 -> 142800 | M29: =L29*10% -> 14280 | N29: =SUM(L29:M29) -> 157080 | O29: 완료(3/31) | P29: 천범석 | Q29: 45713
A30: . | B30: IK-24005 | D30: 45691 | E30: 한국아이씨에스 | F30: 엔콤 | G30: MA | H30: 월간-IBM | I30: 전북도시가스 2월 유지정비료 - 11/12회 | J30: 1 | K30: 1263250 | L30: =J30*K30 -> 1263250 | M30: 126325 | N30: =SUM(L30:M30) -> 1389575 | O30: 완료(3/31) | P30: 천범석 | Q30: 45716
A31: . | B31: IK-22022 | D31: 45691 | E31: 한국아이씨에스 | F31: 리온아이티 | G31: MA | H31: 월간-IBM | I31: 한일전기 2월 유지정비료 - 26/36회 | J31: 1 | K31: 309047 | L31: =J31*K31 -> 309047 | M31: 30904 | N31: =SUM(L31:M31) -> 339951 | O31: 완료(3/31) | P31: 천범석 | Q31: 45658 | R31: 매출분기
A32: . | B32: IK-22021 | D32: 45691 | E32: 한국아이씨에스 | F32: 리온아이티 | G32: MA | H32: 월간-IBM | I32: 문배철강 2월 유지정비료 - 23/36회 | J32: 1 | K32: 212293 | L32: =J32*K32 -> 212293 | M32: 21229 | N32: =SUM(L32:M32) -> 233522 | O32: 완료(3/31) | P32: 천범석 | Q32: 45716
A33: . | B33: IK-24013 | D33: 45691 | E33: 한국아이씨에스 | F33: 레드텍 | G33: MA | H33: 월간-IBM | I33: 대한상공회의소 2월 유지정비료 - 4/12회 | J33: 1 | K33: 145780 | L33: =J33*K33 -> 145780 | M33: 14578 | N33: =SUM(L33:M33) -> 160358 | O33: 완료(3/31) | P33: 천범석 | Q33: 45689
A34: . | B34: LI-24004 | D34: 45691 | E34: 한국아이씨에스 | F34: 한국메탈 | G34: MA | H34: 월간-IBM | I34: 2월유지정비료 - 10/32회 | J34: 1 | K34: 316682 | L34: =J34*K34 -> 316682 | M34: 31668 | N34: =SUM(L34:M34) -> 348350 | O34: 완료(3/31) | P34: 천범석 | Q34: 45689
A35: . | B35: SB-24036 | D35: 45691 | E35: 한국아이씨에스 | F35: 나라정보 | G35: MA | H35: 월간-IBM | I35: 부국철강 2월 유지정비료 - 10/32 회 | J35: 1 | K35: 190849 | L35: =J35*K35 -> 190849 | M35: 19084 | N35: =SUM(L35:M35) -> 209933 | O35: 완료(3/31) | P35: 천범석 | Q35: 45716
A36: . | B36: S | D36: 45691 | E36: 프로미스 | G36: 상품 | H36: 기술지원 | I36: 보안취약 작업(LENOVO) #2 | J36: 1 | K36: 15000000 | L36: =J36*K36 -> 15000000 | M36: =L36*10% -> 1500000 | N36: =SUM(L36:M36) -> 16500000 | O36: 완료(2/28) | P36: 이예지 | Q36: 45643 | S36: 정리
A37: . | B37: S241223 | D37: 45691 | E37: 프로미스 | F37: 다솜테크 | G37: 상품 | H37: 기술지원 | I37: dell 서버 기술지원 | J37: 1 | K37: 600000 | L37: =J37*K37 -> 600000 | M37: =L37*10% -> 60000 | N37: =SUM(L37:M37) -> 660000 | O37: 완료(2/28) | P37: 이예지 | Q37: 45657
A38: . | B38: H250203-01 | D38: 45691 | E38: 이비웨이브 | F38: 티에스씨인포 | G38: 상품 | H38: 80P3162 | I38: 73GB U320 15K 80Pin SCSI Hard Drive | J38: 1 | K38: 120000 | L38: =J38*K38 -> 120000 | M38: =L38*10% -> 12000 | N38: =SUM(L38:M38) -> 132000 | O38: 완료(4/30) | P38: 천범석 | Q38: 45716
A39: . | B39: X | D39: 45691 | E39: 에스케이브로드밴드 | G39: 일반경비 | H39: 통신비 | I39: 통신료 | J39: 1 | K39: 12956 | L39: =J39*K39 -> 12956 | M39: 1295 | N39: =SUM(L39:M39) -> 14251 | O39: 자동이체(2/28) | P39: 정지우 | Q39: X
A40: . | B40: S | D40: 45693 | E40: 로보츠 | G40: MA | H40: 기술지원 | I40: 보안취약점 2차 기술지원 | J40: 1 | K40: 10000000 | L40: =J40*K40 -> 10000000 | M40: =L40*10% -> 1000000 | N40: =SUM(L40:M40) -> 11000000 | O40: 완료(3/25) | P40: 이예지 | Q40: 45657 | S40: 정리
...

Sheet 3월
B1: ="["&YEAR(D5)&"년 "&MONTH(D5)&"월 매입]" -> [2025년 3월 매입]
M2: x 비과세 0 영세 | O2: 완료 | Q2: 트루스케일
B3: 품의코드 | C3: Vendor 코드 | D3: 계산서 | E3: 매입처 | F3: 매출처 | G3: 구분 | H3: MA : 청구구분 상품 : PN | I3: 품목 | J3: 수량 | K3: 매입 | O3: 결제 | P3: 영업 담당자 | Q3: 매출처 세금계산서 | R3: 비고
K4: 단가 | L4: 공금가액 | M4: VAT | N4: 합계금액
A5: . | B5: X | D5: 45717 | E5: 에스케이쉴더스 금천지점 | G5: 일반경비 | H5: 지급수수료 | I5: 보안용역 월정료 3월분 | J5: 1 | K5: 71000 | L5: =J5*K5 -> 71000 | M5: =L5*10% -> 7100 | N5: =SUM(L5:M5) -> 78100 | O5: 자동이체(3/11) | P5: 정지우 | Q5: X
A6: . | B6: LI-24005 | D6: 45717 | E6: 한국아이씨에스 | F6: 해안종합건축사사무소 | G6: MA | H6: 월간-IBM | I6: 3월 유지정비료 - 10/12회 | J6: 1 | K6: 436400 | L6: =J6*K6 -> 436400 | M6: =L6*10% -> 43640 | N6: =SUM(L6:M6) -> 480040 | O6: 완료(3/31) | P6: 천범석 | Q6: 45717
A7: . | B7: LI-24006 | D7: 45717 | E7: 한국아이씨에스 | F7: 보해양조 | G7: MA | H7: 월간-IBM | I7: 3월 유지정비료 - 8/11회 | J7: 1 | K7: 277600 | L7: =J7*K7 -> 277600 | M7: =L7*10% -> 27760 | N7: =SUM(L7:M7) -> 305360 | O7: 완료(3/31) | P7: 천범석 | Q7: 45741
A8: . | B8: H250218-01 | D8: 45717 | E8: 이비웨이브 | F8: 우리에스아이티 | G8: 상품 | H8: 00AJ122 | I8: 500GB 7.2K 6G NL SAS 2.5inch Hard Drive | J8: 1 | K8: 150000 | L8: =J8*K8 -> 150000 | M8: =L8*10% -> 15000 | N8: =SUM(L8:M8) -> 165000 | O8: 완료(5/30) | P8: 천범석 | Q8: 45713
A9: . | B9: LI-24004 | D9: 45719 | E9: 한국아이씨에스 | F9: 한국메탈 | G9: MA | H9: 월간-IBM | I9: 3월유지정비료 - 11/32회 | J9: 1 | K9: 316682 | L9: =J9*K9 -> 316682 | M9: 31668 | N9: =SUM(L9:M9) -> 348350 | O9: 완료(4/30) | P9: 천범석 | Q9: 45717
A10: . | B10: SB-24036 | D10: 45719 | E10: 한국아이씨에스 | F10: 나라정보 | G10: MA | H10: 월간-IBM | I10: 부국철강 3월 유지정비료 - 11/32 회 | J10: 1 | K10: 190849 | L10: =J10*K10 -> 190849 | M10: 19084 | N10: =SUM(L10:M10) -> 209933 | O10: 완료(4/30) | P10: 천범석 | Q10: 45747
A11: . | B11: IK-22025 | D11: 45719 | E11: 한국아이씨에스 | F11: 디에스피 | G11: MA | H11: 월간-IBM | I11: 엘지생활건강 청주공장 3월 유지정비료 - 2/12회 | J11: 1 | K11: 564192 | L11: =J11*K11 -> 564192 | M11: 56419 | N11: =SUM(L11:M11) -> 620611 | O11: 완료(4/30) | P11: 천범석 | Q11: 45717
A12: . | B12: IK-25001 | D12: 45719 | E12: 한국아이씨에스 | F12: 투아이시스 | G12: MA | H12: 월간-IBM | I12: 3월 유지정비료 - 1/12회 | J12: 1 | K12: 93445 | L12: =J12*K12 -> 93445 | M12: 9344 | N12: =SUM(L12:M12) -> 102789 | O12: 완료(4/30) | P12: 천범석 | Q12: 45747 | R12: 매출연간
A13: . | B13: SM-24021 | D13: 45719 | E13: 한국아이씨에스 | F13: 에이캐피탈 | G13: MA | H13: 월간-IBM | I13: 3월 유지정비료 - 7/12회 | J13: 1 | K13: 691782 | L13: =J13*K13 -> 691782 | M13: 69178 | N13: =SUM(L13:M13) -> 760960 | O13: 완료(4/30) | P13: 천범석 | Q13: 45752
A14: . | B14: X | D14: 45719 | E14: 에스케이브로드밴드 | G14: 일반경비 | H14: 통신비 | I14: 통신료 | J14: 1 | K14: 14676 | L14: =J14*K14 -> 14676 | M14: 1467 | N14: =SUM(L14:M14) -> 16143 | O14: 자동이체(3/31) | P14: 정지우 | Q14: X
A15: . | B15: IK-24006 | D15: 45720 | E15: 한국아이씨에스 | F15: 광양항서부터미널 | G15: MA | H15: 월간-IBM | I15: 3월 유지정비료 - 11/24회 | J15: 1 | K15: 3239404 | L15: =J15*K15 -> 3239404 | M15: 323940 | N15: =SUM(L15:M15) -> 3563344 | O15: 완료(4/30) | P15: 홍승민 | Q15: 45747
A16: . | B16: LI-24008 | D16: 45720 | E16: 한국아이씨에스 | F16: 쿠팡 | G16: MA | H16: 월간-IBM | I16: 3월 유지정비료 - 8/13회 | J16: 1 | K16: 205780 | L16: =J16*K16 -> 205780 | M16: 20578 | N16: =SUM(L16:M16) -> 226358 | O16: 완료(4/30) | P16: 천범석 | Q16: 45491 | R16: 매출연간
A17: . | B17: SM-25008 | D17: 45720 | E17: 한국아이씨에스 | F17: 유니포인트 | G17: MA | H17: 월간-IBM | I17: 스마트로 3월 유지정비료 - 3/12회 | J17: 1 | K17: 1210534 | L17: =J17*K17 -> 1210534 | M17: 121053 | N17: =SUM(L17:M17) -> 1331587 | O17: 완료(4/30) | P17: 천범석 | Q17: 45747
A18: . | B18: SM-25003 | D18: 45720 | E18: 한국아이씨에스 | F18: CGV 통합 | G18: MA | H18: 월간-IBM | I18: 3월 유지정비료 - 3/12회 | J18: 1 | K18: 2812500 | L18: =J18*K18 -> 2812500 | M18: 281250 | N18: =SUM(L18:M18) -> 3093750 | O18: 완료(4/30) | P18: 이예지 | Q18: 45666 | R18: 매출연간
A19: . | B19: IK-23016 | D19: 45720 | E19: 한국아이씨에스 | F19: 케이정보기술 | G19: MA | H19: 월간-IBM | I19: 청주시청 3월 유지정비료 - 3/20회 추가 | J19: 1 | K19: 1123962 | L19: =J19*K19 -> 1123962 | M19: 112396 | N19: =SUM(L19:M19) -> 1236358 | O19: 완료(4/30) | P19: 천범석 | Q19: 45717
A20: . | B20: LI-24003 | D20: 45720 | E20: 한국아이씨에스 | F20: 지엔콤 | G20: MA | H20: 월간-IBM | I20: 전주교육대학교 3월 유지정비료 - 11/12회 | J20: 1 | K20: 305280 | L20: =J20*K20 -> 305280 | M20: 30528 | N20: =SUM(L20:M20) -> 335808 | O20: 완료(4/30) | P20: 천범석 | Q20: 45747
A21: . | B21: IK-23016 | D21: 45720 | E21: 한국아이씨에스 | F21: 케이정보기술 | G21: MA | H21: 월간-IBM | I21: 청주시청 3월 유지정비료 - 19/36회 | J21: 1 | K21: 259896 | L21: =J21*K21 -> 259896 | M21: 25989 | N21: =SUM(L21:M21) -> 285885 | O21: 완료(4/30) | P21: 천범석 | Q21: 45717
A22: . | B22: IK-23013 | D22: 45720 | E22: 한국아이씨에스 | F22: 로보츠 | G22: MA | H22: 월간-IBM | I22: 도시바일렉 3월 유지정비료 - 9/12회 | J22: 1 | K22: 66498 | L22: =J22*K22 -> 66498 | M22: 6649 | N22: =SUM(L22:M22) -> 73147 | O22: 완료(4/30) | P22: 천범석 | Q22: 45747
A23: . | B23: LI-24007 | D23: 45720 | E23: 한국아이씨에스 | F23: 유더블유에스 | G23: MA | H23: 월간-IBM | I23: 두원정공 3월 유지정비료 - 8/11회 | J23: 1 | K23: 80160 | L23: =J23*K23 -> 80160 | M23: 8016 | N23: =SUM(L23:M23) -> 88176 | O23: 완료(4/30) | P23: 천범석 | Q23: 45747
A24: . | B24: IK-23014 | D24: 45720 | E24: 한국아이씨에스 | F24: 서비스링크 | G24: MA | H24: 월간-IBM | I24: 세원정공 3월 유지정비료 - 9/12회 | J24: 1 | K24: 198018 | L24: =J24*K24 -> 198018 | M24: 19801 | N24: =SUM(L24:M24) -> 217819 | O24: 완료(4/30) | P24: 천범석 | Q24: 45717
A25: . | B25: SM-21021 | D25: 45720 | E25: 한국아이씨에스 | F25: 법무법인바른 | G25: MA | H25: 월간-IBM | I25: 3월 유지정비료 - 7/13회 | J25: 1 | K25: 84811 | L25: =J25*K25 -> 84811 | M25: 8481 | N25: =SUM(L25:M25) -> 93292 | O25: 완료(4/30) | P25: 천범석 | Q25: 45741
A26: . | B26: IK-24011 | D26: 45720 | E26: 한국아이씨에스 | F26: 로보츠 | G26: MA | H26: 월간-IBM | I26: 키오시아(도시바) 3월 유지정비료 - 4/12회 | J26: 1 | K26: 133875 | L26: =J26*K26 -> 133875 | M26: 13387 | N26: =SUM(L26:M26) -> 147262 | O26: 완료(4/30) | P26: 천범석 | Q26: 45747
A27: . | B27: SM-25011 | D27: 45720 | E27: 한국아이씨에스 | F27: 유니포인트 | G27: MA | H27: 월간-IBM | I27: 한미약품/한미사이언스 3월 유지정비료 - 3/12회 | J27: 1 | K27: 11623397 | L27: =J27*K27 -> 11623397 | M27: 1162339 | N27: =SUM(L27:M27) -> 12785736 | O27: 완료(4/30) | P27: 천범석 | Q27: 45741
A28: . | B28: IK-24012 | D28: 45720 | E28: 한국아이씨에스 | F28: 인정보 | G28: MA | H28: 월간-IBM | I28: 대구텍 3월 유지정비료 - 3/6회 | J28: 1 | K28: 990000 | L28: =J28*K28 -> 990000 | M28: =L28*10% -> 99000 | N28: =SUM(L28:M28) -> 1089000 | O28: 완료(4/30) | P28: 천범석 | Q28: 45717
A29: . | B29: IK-24005 | D29: 45720 | E29: 한국아이씨에스 | F29: 엔콤 | G29: MA | H29: 월간-IBM | I29: 전북도시가스 3월 유지정비료 - 12/12회 | J29: 1 | K29: 1263248 | L29: =J29*K29 -> 1263248 | M29: 126324 | N29: =SUM(L29:M29) -> 1389572 | O29: 완료(4/30) | P29: 천범석 | Q29: 45747
A30: . | B30: IK-22021 | D30: 45720 | E30: 한국아이씨에스 | F30: 리온아이티 | G30: MA | H30: 월간-IBM | I30: 문배철강 3월 유지정비료 - 24/36회 | J30: 1 | K30: 212293 | L30: =J30*K30 -> 212293 | M30: 21229 | N30: =SUM(L30:M30) -> 233522 | O30: 완료(4/30) | P30: 천범석 | Q30: 45747
A31: . | B31: IK-24013 | D31: 45720 | E31: 한국아이씨에스 | F31: 레드텍 | G31: MA | H31: 월간-IBM | I31: 대한상공회의소 3월 유지정비료 - 5/12회 | J31: 1 | K31: 145780 | L31: =J31*K31 -> 145780 | M31: 14578 | N31: =SUM(L31:M31) -> 160358 | O31: 완료(4/30) | P31: 천범석 | Q31: 45717
A32: . | B32: IK-22022 | D32: 45720 | E32: 한국아이씨에스 | F32: 리온아이티 | G32: MA | H32: 월간-IBM | I32: 한일전기 3월 유지정비료 - 27/36회 | J32: 1 | K32: 309047 | L32: =J32*K32 -> 309047 | M32: 30904 | N32: =SUM(L32:M32) -> 339951 | O32: 완료(4/30) | P32: 천범석 | Q32: 45658 | R32: 매출분기
A33: . | B33: LI-24006 | D33: 45720 | E33: 한국아이씨에스 | F33: 보해양조 | G33: MA | H33: 월간-IBM | I33: 3월 유지정비료 - 9/12회 | J33: 1 | K33: 142800 | L33: =J33*K33 -> 142800 | M33: =L33*10% -> 14280 | N33: =SUM(L33:M33) -> 157080 | O33: 완료(4/30) | P33: 천범석 | Q33: 45741
A34: . | B34: IK-24002 | D34: 45720 | E34: 한국아이씨에스 | F34: 리온아이티 | G34: MA | H34: 월간-IBM | I34: 교세라 3월 유지정비료 - 14/36회 | J34: 1 | K34: 70422 | L34: =J34*K34 -> 70422 | M34: 7042 | N34: =SUM(L34:M34) -> 77464 | O34: 완료(4/30) | P34: 천범석 | Q34: 45716 | R34: 매출연간
A35: . | B35: IK-22023 | D35: 45720 | E35: 한국아이씨에스 | F35: 리온아이티 | G35: MA | H35: 월간-IBM | I35: 성원제강 3월 유지정비료 - 24/36회 | J35: 1 | K35: 159761 | L35: =J35*K35 -> 159761 | M35: 15976 | N35: =SUM(L35:M35) -> 175737 | O35: 완료(4/30) | P35: 천범석 | Q35: 45747
A36: . | B36: IK-24014 | D36: 45720 | E36: 한국아이씨에스 | F36: 로보츠 | G36: MA | H36: 월간-IBM | I36: 와이케이케이 3월 유지정비료 - 3/12회 | J36: 1 | K36: 79496 | L36: =J36*K36 -> 79496 | M36: 7949 | N36: =SUM(L36:M36) -> 87445 | O36: 완료(4/30) | P36: 천범석 | Q36: 45741
A37: . | B37: LI-24009 | D37: 45720 | E37: 한국아이씨에스 | F37: 아이리스인포테크 | G37: MA | H37: 월간-IBM | I37: 프레이저플레이스 3월 유지정비료 - 8/12회 | J37: 1 | K37: 95200 | L37: =J37*K37 -> 95200 | M37: =L37*10% -> 9520 | N37: =SUM(L37:M37) -> 104720 | O37: 완료(4/30) | P37: 천범석 | Q37: 45716 | R37: 매출분기
A38: . | B38: SM-25008 SM-25009 | D38: 45720 | E38: 프로미스 | F38: 유니포인트 | G38: MA | H38: 분기 | I38: 스마트로 유지보수 25년 1Q | J38: 1 | K38: 14000000 | L38: =J38*K38 -> 14000000 | M38: =L38*10% -> 1400000 | N38: =SUM(L38:M38) -> 15400000 | O38: 완료(3/24) | P38: 이예지 | Q38: 1/24,2/28/,3/31
A39: . | B39: SM-23033 | D39: 45720 | E39: 프로미스 | F39: 강북21세기병원 | G39: MA | H39: 연간 | I39: 연간 24년(23.12~24.11) | J39: 1 | K39: 1200000 | L39: =J39*K39 -> 1200000 | M39: =L39*10% -> 120000 | N39: =SUM(L39:M39) -> 1320000 | O39: 완료(3/24) | P39: 천범석 | Q39: 23/12/25~ | R39: 매출월간
A40: . | B40: SB-24031 | D40: 45720 | E40: 프로미스 | F40: 데이타메트렉스 | G40: MA | H40: 반기 | I40: 하이마트 MA (24.12~25.5) - 반기 | J40: 1 | K40: 2160000 | L40: =J40*K40 -> 2160000 | M40: =L40*10% -> 216000 | N40: =SUM(L40:M40) -> 2376000 | O40: 완료(3/24) | P40: 천범석 | Q40: 12/27~ | R40: 매출월간
...

Sheet 4월
B1: ="["&YEAR(D5)&"년 "&MONTH(D5)&"월 매입]" -> [2025년 4월 매입]
M2: x 비과세 0 영세 | O2: 완료 | Q2: 트루스케일
B3: 품의코드 | C3: Vendor 코드 | D3: 계산서 | E3: 매입처 | F3: 매출처 | G3: 구분 | H3: MA : 청구구분 상품 : PN | I3: 품목 | J3: 수량 | K3: 매입 | O3: 결제 | P3: 영업 담당자 | Q3: 매출처 세금계산서 | R3: 비고
K4: 단가 | L4: 공금가액 | M4: VAT | N4: 합계금액
